Workbook

Sheet BaselineMesh
A1: Test Configuration | C1: Field Notes
A2: Field | B2: Value
A3: Experiment | B3: Enabled | C3: {=_xlfn.SWITCH(experiment0[[#This Row],[Value]],"Disabled","Experiment disabled will not run", " Experiment recipe enabled")} -> Experiment recipe enabled
A4: Test Name | B4: Baseline | C4: Name of Test to be executed
A5: Test Mode | B5: Mesh | C5: Test Mode: Slice or Mesh
A6: Test Type | B6: Loops | C6: Type of test: Loops, Sweep or Shmoo
A7: Visual ID | B7: TestUnitData | C7: Unit Visual ID
A8: Bucket | B8: IDIPAR | C8: Unit Assigned Bucket
A9: COM Port | B9: 11 | C9: Serial Port to communicate to MB
A10: IP Address | B10: 10.250.0.2 | C10: IP Address to communicate to MB
A11: TTL Folder | B11: S:\GNR\RVP\TTLs\TTL_DragonMesh | C11: Teraterm TTL Macros Folder Location with Commands.ttl and Connect.ttl files
A12: Scripts File | C12: Script File to be loaded before Test Execution
A13: Post Process | C13: Script File to be loaded after Test Execution
A14: Pass String | B14: Test Complete | C14: Lookup String for a Pass Condition of the Test
A15: Fail String | B15: Test Failed | C15: Lookup String for a Fail Condition of the Test
A16: Content | B16: Dragon | C16: Select your content: Linux | Dragon | PYSConsole (Custom Python Script)
A17: Test Number | B17: 11 | C17: First Number to be assigned to your test iteration
A18: Test Time | B18: 30 | C18: Wait time to be used for watchdog monitoring of console, in case unit is hang or failed during execution
A19: Reset | B19: TRUE | C19: Reset Unit before Starting first experiment
A20: Reset on PASS | B20: TRUE | C20: Reset Unit after each PASS
A21: FastBoot | B21: TRUE | C21: if Mesh Masking is selected, set this to False
A22: Core License | C22: Leave Blank if not used
A23: 600W Unit | B23: FALSE | C23: True or False
A24: Pseudo Config | B24: FALSE | C24: {=IF(MiscData!C1="AtomCore",MiscData!U14,_xlfn.SWITCH($B$5,"Slice",MiscData!U14,MiscData!U16))} -> Set if using Pseudo Mesh Content, to disable HT
A25: Configuration (Mask) | C25: =_xlfn.XLOOKUP(B5,MiscData!K3:K5,MiscData!L3:L5) -> Mesh Options: RowPass1, RowPass2, RowPass3, FirstPass, SecondPass, ThirdPass || Leave Blank if Full Chip
A26: Boot Breakpoint | C26: {=_xlfn.SWITCH(B16,"PYSVConsole",MiscData!U18,MiscData!U14)} -> Not used
A27: Disable 2 Cores | C27: =IF(MiscData!C1="AtomCore",MiscData!U17,MiscData!U14) -> Not used
A28: Check Core | B28: 36 | C28: Used in Mesh Mode to check an specific core data, such as voltage, frequency, license, dcf… If slice, this is set to the tested core. | D28: Limits
A29: Voltage Type | B29: vbump | C29: vbump or fixed | D29: MAX | E29: MIN
A30: Voltage IA | C30: {=_xlfn.SWITCH(B29,"vbump",_xlfn.SWITCH(TRUE,experiment0[[#This Row],[Value]]="",MiscData!U15,experiment0[[#This Row],[Value]]>MiscData!N3,MiscData!U4,experiment0[[#This Row],[Value]]<MiscData!O3,MiscData!U5,MiscData!U3),"fixed",_xlfn.SWITCH(TRUE,experiment0[[#This Row],[Value]]="",MiscData!U15,experiment0[[#This Row],[Value]]>MiscData!N7,MiscData!U4,experiment0[[#This Row],[Value]]<MiscData!O7,MiscData!U5,MiscData!U3),"")} -> Not Configured | D30: {=_xlfn.SWITCH(B$29,"vbump",MiscData!N3,"fixed",MiscData!N7,"")} -> 0.2 | E30: {=_xlfn.SWITCH(B$29,"vbump",MiscData!O3,"fixed",MiscData!O7,"")} -> -0.2
A31: Voltage CFC | C31: {=_xlfn.SWITCH(B29,"vbump",_xlfn.SWITCH(TRUE,experiment0[[#This Row],[Value]]="",MiscData!U15,experiment0[[#This Row],[Value]]>MiscData!N4,MiscData!U4,experiment0[[#This Row],[Value]]<MiscData!O4,MiscData!U5,MiscData!U3),"fixed",_xlfn.SWITCH(TRUE,experiment0[[#This Row],[Value]]="",MiscData!U15,experiment0[[#This Row],[Value]]>MiscData!N8,MiscData!U4,experiment0[[#This Row],[Value]]<MiscData!O8,MiscData!U5,MiscData!U3),"")} -> Not Configured | D31: {=_xlfn.SWITCH(B$29,"vbump",MiscData!N4,"fixed",MiscData!N8,"")} -> 0.2 | E31: {=_xlfn.SWITCH(B$29,"vbump",MiscData!O4,"fixed",MiscData!O8,"")} -> -0.2
A32: Frequency IA | C32: {=_xlfn.SWITCH(TRUE,experiment0[[#This Row],[Value]]="",MiscData!U15,experiment0[[#This Row],[Value]]>MiscData!Q3,MiscData!U4,experiment0[[#This Row],[Value]]<MiscData!R3,MiscData!U5,MiscData!U3)} -> Not Configured | D32: =MiscData!Q3 -> 44 | E32: =MiscData!R3 -> 5
A33: Frequency CFC | C33: {=_xlfn.SWITCH(TRUE,experiment0[[#This Row],[Value]]="",MiscData!U15,experiment0[[#This Row],[Value]]>MiscData!Q4,MiscData!U4,experiment0[[#This Row],[Value]]<MiscData!R4,MiscData!U5,MiscData!U3)} -> Not Configured | D33: =MiscData!Q4 -> 22 | E33: =MiscData!R4 -> 8
A34: Loops | B34: 5 | C34: {=_xlfn.SWITCH(B6,"Loops",MiscData!U6,MiscData!U14)} -> Number of Loops to run
A35: Type | B35: Voltage | C35: {=_xlfn.SWITCH($B$6,"Sweep",MiscData!U7,MiscData!$U$14)} -> Not used
A36: Domain | B36: IA | C36: {=_xlfn.SWITCH($B$6,"Sweep",MiscData!U8,MiscData!$U$14)} -> Not used
A37: Start | B37: -0.03 | C37: {=_xlfn.SWITCH($B$6,"Sweep",MiscData!U9,MiscData!$U$14)} -> Not used
A38: End | B38: 0.06 | C38: {=_xlfn.SWITCH($B$6,"Sweep",MiscData!U10,MiscData!$U$14)} -> Not used
A39: Steps | B39: 0.03 | C39: {=_xlfn.SWITCH($B$6,"Sweep",MiscData!U11,MiscData!$U$14)} -> Not used
A40: ShmooFile | B40: C:\SystemDebug\Shmoos\RVPShmooConfig.json | C40: {=_xlfn.SWITCH($B$6,"Shmoo",MiscData!U12,MiscData!$U$14)} -> Not used
...

Sheet BaselinePPVC
A1: Test Configuration | C1: Field Notes
A2: Field | B2: Value
A3: Experiment | B3: Enabled | C3: {=_xlfn.SWITCH(experiment016[[#This Row],[Value]],"Disabled","Experiment disabled will not run", " Experiment recipe enabled")} -> Experiment recipe enabled
A4: Test Name | B4: BaselinePPVC | C4: Name of Test to be executed
A5: Test Mode | B5: Mesh | C5: Test Mode: Slice or Mesh
A6: Test Type | B6: Loops | C6: Type of test: Loops, Sweep or Shmoo
A7: Visual ID | B7: TestUnitData | C7: Unit Visual ID
A8: Bucket | B8: IDIPAR | C8: Unit Assigned Bucket
A9: COM Port | B9: 11 | C9: Serial Port to communicate to MB
A10: IP Address | B10: 10.250.0.2 | C10: IP Address to communicate to MB
A11: TTL Folder | B11: S:\GNR\RVP\TTLs\TTL_DragonMesh | C11: Teraterm TTL Macros Folder Location with Commands.ttl and Connect.ttl files
A12: Scripts File | C12: Script File to be loaded before Test Execution
A13: Post Process | C13: Script File to be loaded after Test Execution
A14: Pass String | B14: Test Complete | C14: Lookup String for a Pass Condition of the Test
A15: Fail String | B15: Test Failed | C15: Lookup String for a Fail Condition of the Test
A16: Content | B16: Dragon | C16: Select your content: Linux | Dragon | PYSConsole (Custom Python Script)
A17: Test Number | B17: 11 | C17: First Number to be assigned to your test iteration
A18: Test Time | B18: 30 | C18: Wait time to be used for watchdog monitoring of console, in case unit is hang or failed during execution
A19: Reset | B19: TRUE | C19: Reset Unit before Starting first experiment
A20: Reset on PASS | B20: TRUE | C20: Reset Unit after each PASS
A21: FastBoot | B21: TRUE | C21: if Mesh Masking is selected, set this to False
A22: Core License | C22: Leave Blank if not used
A23: 600W Unit | B23: FALSE | C23: True or False
A24: Pseudo Config | B24: FALSE | C24: {=IF(MiscData!C1="AtomCore",MiscData!U14,_xlfn.SWITCH($B$5,"Slice",MiscData!U14,MiscData!U16))} -> Set if using Pseudo Mesh Content, to disable HT
A25: Configuration (Mask) | C25: =_xlfn.XLOOKUP(B5,MiscData!K3:K5,MiscData!L3:L5) -> Mesh Options: RowPass1, RowPass2, RowPass3, FirstPass, SecondPass, ThirdPass || Leave Blank if Full Chip
A26: Boot Breakpoint | C26: {=_xlfn.SWITCH(B16,"PYSVConsole",MiscData!U18,MiscData!U14)} -> Not used
A27: Disable 2 Cores | C27: =IF(MiscData!C1="AtomCore",MiscData!U17,MiscData!U14) -> Not used
A28: Check Core | B28: 36 | C28: Used in Mesh Mode to check an specific core data, such as voltage, frequency, license, dcf… If slice, this is set to the tested core. | D28: Limits
A29: Voltage Type | B29: ppvc | C29: vbump or fixed | D29: MAX | E29: MIN
A30: Voltage IA | C30: {=_xlfn.SWITCH(B29,"vbump",_xlfn.SWITCH(TRUE,experiment016[[#This Row],[Value]]="",MiscData!U15,experiment016[[#This Row],[Value]]>MiscData!N3,MiscData!U4,experiment016[[#This Row],[Value]]<MiscData!O3,MiscData!U5,MiscData!U3),"fixed",_xlfn.SWITCH(TRUE,experiment016[[#This Row],[Value]]="",MiscData!U15,experiment016[[#This Row],[Value]]>MiscData!N7,MiscData!U4,experiment016[[#This Row],[Value]]<MiscData!O7,MiscData!U5,MiscData!U3),"")} | D30: {=_xlfn.SWITCH(B$29,"vbump",MiscData!N3,"fixed",MiscData!N7,"")} | E30: {=_xlfn.SWITCH(B$29,"vbump",MiscData!O3,"fixed",MiscData!O7,"")}
A31: Voltage CFC | C31: {=_xlfn.SWITCH(B29,"vbump",_xlfn.SWITCH(TRUE,experiment016[[#This Row],[Value]]="",MiscData!U15,experiment016[[#This Row],[Value]]>MiscData!N4,MiscData!U4,experiment016[[#This Row],[Value]]<MiscData!O4,MiscData!U5,MiscData!U3),"fixed",_xlfn.SWITCH(TRUE,experiment016[[#This Row],[Value]]="",MiscData!U15,experiment016[[#This Row],[Value]]>MiscData!N8,MiscData!U4,experiment016[[#This Row],[Value]]<MiscData!O8,MiscData!U5,MiscData!U3),"")} | D31: {=_xlfn.SWITCH(B$29,"vbump",MiscData!N4,"fixed",MiscData!N8,"")} | E31: {=_xlfn.SWITCH(B$29,"vbump",MiscData!O4,"fixed",MiscData!O8,"")}
A32: Frequency IA | C32: {=_xlfn.SWITCH(TRUE,experiment016[[#This Row],[Value]]="",MiscData!U15,experiment016[[#This Row],[Value]]>MiscData!Q3,MiscData!U4,experiment016[[#This Row],[Value]]<MiscData!R3,MiscData!U5,MiscData!U3)} -> Not Configured | D32: =MiscData!Q3 -> 44 | E32: =MiscData!R3 -> 5
A33: Frequency CFC | C33: {=_xlfn.SWITCH(TRUE,experiment016[[#This Row],[Value]]="",MiscData!U15,experiment016[[#This Row],[Value]]>MiscData!Q4,MiscData!U4,experiment016[[#This Row],[Value]]<MiscData!R4,MiscData!U5,MiscData!U3)} -> Not Configured | D33: =MiscData!Q4 -> 22 | E33: =MiscData!R4 -> 8
A34: Loops | B34: 5 | C34: {=_xlfn.SWITCH(B6,"Loops",MiscData!U6,MiscData!U14)} -> Number of Loops to run
A35: Type | B35: Voltage | C35: {=_xlfn.SWITCH($B$6,"Sweep",MiscData!U7,MiscData!$U$14)} -> Not used
A36: Domain | B36: IA | C36: {=_xlfn.SWITCH($B$6,"Sweep",MiscData!U8,MiscData!$U$14)} -> Not used
A37: Start | B37: -0.03 | C37: {=_xlfn.SWITCH($B$6,"Sweep",MiscData!U9,MiscData!$U$14)} -> Not used
A38: End | B38: 0.06 | C38: {=_xlfn.SWITCH($B$6,"Sweep",MiscData!U10,MiscData!$U$14)} -> Not used
A39: Steps | B39: 0.03 | C39: {=_xlfn.SWITCH($B$6,"Sweep",MiscData!U11,MiscData!$U$14)} -> Not used
A40: ShmooFile | B40: C:\SystemDebug\Shmoos\RVPShmooConfig.json | C40: {=_xlfn.SWITCH($B$6,"Shmoo",MiscData!U12,MiscData!$U$14)} -> Not used
...

Sheet BaselineXtended
A1: Test Configuration | C1: Field Notes
A2: Field | B2: Value
A3: Experiment | B3: Enabled | C3: {=_xlfn.SWITCH(experiment01617[[#This Row],[Value]],"Disabled","Experiment disabled will not run", " Experiment recipe enabled")} -> Experiment recipe enabled
A4: Test Name | B4: BaselineXtended | C4: Name of Test to be executed
A5: Test Mode | B5: Mesh | C5: Test Mode: Slice or Mesh
A6: Test Type | B6: Loops | C6: Type of test: Loops, Sweep or Shmoo
A7: Visual ID | B7: TestUnitData | C7: Unit Visual ID
A8: Bucket | B8: IDIPAR | C8: Unit Assigned Bucket
A9: COM Port | B9: 11 | C9: Serial Port to communicate to MB
A10: IP Address | B10: 10.250.0.2 | C10: IP Address to communicate to MB
A11: TTL Folder | B11: S:\GNR\RVP\TTLs\TTL_DragonMesh | C11: Teraterm TTL Macros Folder Location with Commands.ttl and Connect.ttl files
A12: Scripts File | C12: Script File to be loaded before Test Execution
A13: Post Process | C13: Script File to be loaded after Test Execution
A14: Pass String | B14: Test Complete | C14: Lookup String for a Pass Condition of the Test
A15: Fail String | B15: Test Failed | C15: Lookup String for a Fail Condition of the Test
A16: Content | B16: Dragon | C16: Select your content: Linux | Dragon | PYSConsole (Custom Python Script)
A17: Test Number | B17: 11 | C17: First Number to be assigned to your test iteration
A18: Test Time | B18: 30 | C18: Wait time to be used for watchdog monitoring of console, in case unit is hang or failed during execution
A19: Reset | B19: TRUE | C19: Reset Unit before Starting first experiment
A20: Reset on PASS | B20: TRUE | C20: Reset Unit after each PASS
A21: FastBoot | B21: TRUE | C21: if Mesh Masking is selected, set this to False
A22: Core License | C22: Leave Blank if not used
A23: 600W Unit | B23: FALSE | C23: True or False
A24: Pseudo Config | B24: FALSE | C24: {=IF(MiscData!C1="AtomCore",MiscData!U14,_xlfn.SWITCH($B$5,"Slice",MiscData!U14,MiscData!U16))} -> Set if using Pseudo Mesh Content, to disable HT
A25: Configuration (Mask) | C25: =_xlfn.XLOOKUP(B5,MiscData!K3:K5,MiscData!L3:L5) -> Mesh Options: RowPass1, RowPass2, RowPass3, FirstPass, SecondPass, ThirdPass || Leave Blank if Full Chip
A26: Boot Breakpoint | C26: {=_xlfn.SWITCH(B16,"PYSVConsole",MiscData!U18,MiscData!U14)} -> Not used
A27: Disable 2 Cores | C27: =IF(MiscData!C1="AtomCore",MiscData!U17,MiscData!U14) -> Not used
A28: Check Core | B28: 36 | C28: Used in Mesh Mode to check an specific core data, such as voltage, frequency, license, dcf… If slice, this is set to the tested core. | D28: Limits
A29: Voltage Type | B29: ppvc | C29: vbump or fixed | D29: MAX | E29: MIN
A30: Voltage IA | C30: {=_xlfn.SWITCH(B29,"vbump",_xlfn.SWITCH(TRUE,experiment01617[[#This Row],[Value]]="",MiscData!U15,experiment01617[[#This Row],[Value]]>MiscData!N3,MiscData!U4,experiment01617[[#This Row],[Value]]<MiscData!O3,MiscData!U5,MiscData!U3),"fixed",_xlfn.SWITCH(TRUE,experiment01617[[#This Row],[Value]]="",MiscData!U15,experiment01617[[#This Row],[Value]]>MiscData!N7,MiscData!U4,experiment01617[[#This Row],[Value]]<MiscData!O7,MiscData!U5,MiscData!U3),"")} | D30: {=_xlfn.SWITCH(B$29,"vbump",MiscData!N3,"fixed",MiscData!N7,"")} | E30: {=_xlfn.SWITCH(B$29,"vbump",MiscData!O3,"fixed",MiscData!O7,"")}
A31: Voltage CFC | C31: {=_xlfn.SWITCH(B29,"vbump",_xlfn.SWITCH(TRUE,experiment01617[[#This Row],[Value]]="",MiscData!U15,experiment01617[[#This Row],[Value]]>MiscData!N4,MiscData!U4,experiment01617[[#This Row],[Value]]<MiscData!O4,MiscData!U5,MiscData!U3),"fixed",_xlfn.SWITCH(TRUE,experiment01617[[#This Row],[Value]]="",MiscData!U15,experiment01617[[#This Row],[Value]]>MiscData!N8,MiscData!U4,experiment01617[[#This Row],[Value]]<MiscData!O8,MiscData!U5,MiscData!U3),"")} | D31: {=_xlfn.SWITCH(B$29,"vbump",MiscData!N4,"fixed",MiscData!N8,"")} | E31: {=_xlfn.SWITCH(B$29,"vbump",MiscData!O4,"fixed",MiscData!O8,"")}
A32: Frequency IA | C32: {=_xlfn.SWITCH(TRUE,experiment01617[[#This Row],[Value]]="",MiscData!U15,experiment01617[[#This Row],[Value]]>MiscData!Q3,MiscData!U4,experiment01617[[#This Row],[Value]]<MiscData!R3,MiscData!U5,MiscData!U3)} -> Not Configured | D32: =MiscData!Q3 -> 44 | E32: =MiscData!R3 -> 5
A33: Frequency CFC | C33: {=_xlfn.SWITCH(TRUE,experiment01617[[#This Row],[Value]]="",MiscData!U15,experiment01617[[#This Row],[Value]]>MiscData!Q4,MiscData!U4,experiment01617[[#This Row],[Value]]<MiscData!R4,MiscData!U5,MiscData!U3)} -> Not Configured | D33: =MiscData!Q4 -> 22 | E33: =MiscData!R4 -> 8
A34: Loops | B34: 5 | C34: {=_xlfn.SWITCH(B6,"Loops",MiscData!U6,MiscData!U14)} -> Number of Loops to run
A35: Type | B35: Voltage | C35: {=_xlfn.SWITCH($B$6,"Sweep",MiscData!U7,MiscData!$U$14)} -> Not used
A36: Domain | B36: IA | C36: {=_xlfn.SWITCH($B$6,"Sweep",MiscData!U8,MiscData!$U$14)} -> Not used
A37: Start | B37: -0.03 | C37: {=_xlfn.SWITCH($B$6,"Sweep",MiscData!U9,MiscData!$U$14)} -> Not used
A38: End | B38: 0.06 | C38: {=_xlfn.SWITCH($B$6,"Sweep",MiscData!U10,MiscData!$U$14)} -> Not used
A39: Steps | B39: 0.03 | C39: {=_xlfn.SWITCH($B$6,"Sweep",MiscData!U11,MiscData!$U$14)} -> Not used
A40: ShmooFile | B40: C:\SystemDebug\Shmoos\RVPShmooConfig.json | C40: {=_xlfn.SWITCH($B$6,"Shmoo",MiscData!U12,MiscData!$U$14)} -> Not used
...

Sheet BaselineSlice
A1: Test Configuration | C1: Field Notes
A2: Field | B2: Value
A3: Experiment | B3: Enabled | C3: {=_xlfn.SWITCH(experiment01314[[#This Row],[Value]],"Disabled","Experiment disabled will not run", " Experiment recipe enabled")} -> Experiment recipe enabled
A4: Test Name | B4: Slice_TSL_mini | C4: Name of Test to be executed
A5: Test Mode | B5: Slice | C5: Test Mode: Slice or Mesh
A6: Test Type | B6: Loops | C6: Type of test: Loops, Sweep or Shmoo
A7: Visual ID | B7: 759Q17J500189 | C7: Unit Visual ID
A8: Bucket | B8: 3strike | C8: Unit Assigned Bucket
A9: COM Port | B9: 8 | C9: Serial Port to communicate to MB
A10: IP Address | B10: 10.250.0.2 | C10: IP Address to communicate to MB
A11: TTL Folder | B11: S:\GNR\\RVP\TTLs\TTL_DragonSlice | C11: Teraterm TTL Macros Folder Location with Commands.ttl and Connect.ttl files
A12: Scripts File | C12: Script File to be loaded before Test Execution
A13: Post Process | C13: Script File to be loaded after Test Execution
A14: Pass String | B14: Test Complete | C14: Lookup String for a Pass Condition of the Test
A15: Fail String | B15: Test Failed | C15: Lookup String for a Fail Condition of the Test
A16: Content | B16: Dragon | C16: Select your content: Linux | Dragon | PYSConsole (Custom Python Script)
A17: Test Number | B17: 1 | C17: First Number to be assigned to your test iteration
A18: Test Time | B18: 40 | C18: Wait time to be used for watchdog monitoring of console, in case unit is hang or failed during execution
A19: Reset | B19: TRUE | C19: Reset Unit before Starting first experiment
A20: Reset on PASS | B20: TRUE | C20: Reset Unit after each PASS
A21: FastBoot | B21: TRUE | C21: if Mesh Masking is selected, set this to False
A22: Core License | C22: Leave Blank if not used
A23: 600W Unit | B23: TRUE | C23: True or False
A24: Pseudo Config | B24: FALSE | C24: {=IF(MiscData!C1="AtomCore",MiscData!U14,_xlfn.SWITCH($B$5,"Slice",MiscData!U14,MiscData!U16))} -> Not used
A25: Configuration (Mask) | B25: 36 | C25: =_xlfn.XLOOKUP(B5,MiscData!K3:K5,MiscData!L3:L5) -> Use Physical Core Number
A26: Boot Breakpoint | C26: {=_xlfn.SWITCH(B16,"PYSVConsole",MiscData!U18,MiscData!U14)} -> Not used
A27: Disable 2 Cores | C27: =IF(MiscData!C1="AtomCore",MiscData!U17,MiscData!U14) -> Not used
A28: Check Core | B28: 36 | C28: Used in Mesh Mode to check an specific core data, such as voltage, frequency, license, dcf… If slice, this is set to the tested core. | D28: Limits
A29: Voltage Type | B29: vbump | C29: vbump or fixed | D29: MAX | E29: MIN
A30: Voltage IA | C30: {=_xlfn.SWITCH(B29,"vbump",_xlfn.SWITCH(TRUE,experiment01314[[#This Row],[Value]]="",MiscData!U15,experiment01314[[#This Row],[Value]]>MiscData!N3,MiscData!U4,experiment01314[[#This Row],[Value]]<MiscData!O3,MiscData!U5,MiscData!U3),"fixed",_xlfn.SWITCH(TRUE,experiment01314[[#This Row],[Value]]="",MiscData!U15,experiment01314[[#This Row],[Value]]>MiscData!N7,MiscData!U4,experiment01314[[#This Row],[Value]]<MiscData!O7,MiscData!U5,MiscData!U3),"")} -> Not Configured | D30: {=_xlfn.SWITCH(B$29,"vbump",MiscData!N3,"fixed",MiscData!N7,"")} -> 0.2 | E30: {=_xlfn.SWITCH(B$29,"vbump",MiscData!O3,"fixed",MiscData!O7,"")} -> -0.2
A31: Voltage CFC | C31: {=_xlfn.SWITCH(B29,"vbump",_xlfn.SWITCH(TRUE,experiment01314[[#This Row],[Value]]="",MiscData!U15,experiment01314[[#This Row],[Value]]>MiscData!N4,MiscData!U4,experiment01314[[#This Row],[Value]]<MiscData!O4,MiscData!U5,MiscData!U3),"fixed",_xlfn.SWITCH(TRUE,experiment01314[[#This Row],[Value]]="",MiscData!U15,experiment01314[[#This Row],[Value]]>MiscData!N8,MiscData!U4,experiment01314[[#This Row],[Value]]<MiscData!O8,MiscData!U5,MiscData!U3),"")} -> Not Configured | D31: {=_xlfn.SWITCH(B$29,"vbump",MiscData!N4,"fixed",MiscData!N8,"")} -> 0.2 | E31: {=_xlfn.SWITCH(B$29,"vbump",MiscData!O4,"fixed",MiscData!O8,"")} -> -0.2
A32: Frequency IA | C32: {=_xlfn.SWITCH(TRUE,experiment01314[[#This Row],[Value]]="",MiscData!U15,experiment01314[[#This Row],[Value]]>MiscData!Q3,MiscData!U4,experiment01314[[#This Row],[Value]]<MiscData!R3,MiscData!U5,MiscData!U3)} -> Not Configured | D32: =MiscData!Q3 -> 44 | E32: =MiscData!R3 -> 5
A33: Frequency CFC | C33: {=_xlfn.SWITCH(TRUE,experiment01314[[#This Row],[Value]]="",MiscData!U15,experiment01314[[#This Row],[Value]]>MiscData!Q4,MiscData!U4,experiment01314[[#This Row],[Value]]<MiscData!R4,MiscData!U5,MiscData!U3)} -> Not Configured | D33: =MiscData!Q4 -> 22 | E33: =MiscData!R4 -> 8
A34: Loops | B34: 5 | C34: {=_xlfn.SWITCH(B6,"Loops",MiscData!U6,MiscData!U14)} -> Number of Loops to run
A35: Type | B35: Voltage | C35: {=_xlfn.SWITCH($B$6,"Sweep",MiscData!U7,MiscData!$U$14)} -> Not used
A36: Domain | B36: IA | C36: {=_xlfn.SWITCH($B$6,"Sweep",MiscData!U8,MiscData!$U$14)} -> Not used
A37: Start | B37: -0.03 | C37: {=_xlfn.SWITCH($B$6,"Sweep",MiscData!U9,MiscData!$U$14)} -> Not used
A38: End | B38: 0.06 | C38: {=_xlfn.SWITCH($B$6,"Sweep",MiscData!U10,MiscData!$U$14)} -> Not used
A39: Steps | B39: 0.03 | C39: {=_xlfn.SWITCH($B$6,"Sweep",MiscData!U11,MiscData!$U$14)} -> Not used
A40: ShmooFile | B40: C:\SystemDebug\Shmoos\RVPShmooConfig.json | C40: {=_xlfn.SWITCH($B$6,"Shmoo",MiscData!U12,MiscData!$U$14)} -> Not used
...

Sheet CFC_Voltage
A1: Test Configuration | C1: Field Notes
A2: Field | B2: Value
A3: Experiment | B3: Enabled | C3: {=_xlfn.SWITCH(experiment07[[#This Row],[Value]],"Disabled","Experiment disabled will not run", " Experiment recipe enabled")} -> Experiment recipe enabled
A4: Test Name | B4: CFCVoltage | C4: Name of Test to be executed
A5: Test Mode | B5: Mesh | C5: Test Mode: Slice or Mesh
A6: Test Type | B6: Sweep | C6: Type of test: Loops, Sweep or Shmoo
A7: Visual ID | B7: TestUnitData | C7: Unit Visual ID
A8: Bucket | B8: IDIPAR | C8: Unit Assigned Bucket
A9: COM Port | B9: 11 | C9: Serial Port to communicate to MB
A10: IP Address | B10: 10.250.0.2 | C10: IP Address to communicate to MB
A11: TTL Folder | B11: S:\GNR\RVP\TTLs\TTL_DragonMesh | C11: Teraterm TTL Macros Folder Location with Commands.ttl and Connect.ttl files
A12: Scripts File | C12: Script File to be loaded before Test Execution
A13: Post Process | C13: Script File to be loaded after Test Execution
A14: Pass String | B14: Test Complete | C14: Lookup String for a Pass Condition of the Test
A15: Fail String | B15: Test Failed | C15: Lookup String for a Fail Condition of the Test
A16: Content | B16: Dragon | C16: Select your content: Linux | Dragon | PYSConsole (Custom Python Script)
A17: Test Number | B17: 11 | C17: First Number to be assigned to your test iteration
A18: Test Time | B18: 30 | C18: Wait time to be used for watchdog monitoring of console, in case unit is hang or failed during execution
A19: Reset | B19: TRUE | C19: Reset Unit before Starting first experiment
A20: Reset on PASS | B20: TRUE | C20: Reset Unit after each PASS
A21: FastBoot | B21: TRUE | C21: if Mesh Masking is selected, set this to False
A22: Core License | C22: Leave Blank if not used
A23: 600W Unit | B23: FALSE | C23: True or False
A24: Pseudo Config | B24: FALSE | C24: {=IF(MiscData!C1="AtomCore",MiscData!U14,_xlfn.SWITCH($B$5,"Slice",MiscData!U14,MiscData!U16))} -> Set if using Pseudo Mesh Content, to disable HT
A25: Configuration (Mask) | C25: =_xlfn.XLOOKUP(B5,MiscData!K3:K5,MiscData!L3:L5) -> Mesh Options: RowPass1, RowPass2, RowPass3, FirstPass, SecondPass, ThirdPass || Leave Blank if Full Chip
A26: Boot Breakpoint | C26: {=_xlfn.SWITCH(B16,"PYSVConsole",MiscData!U18,MiscData!U14)} -> Not used
A27: Disable 2 Cores | C27: =IF(MiscData!C1="AtomCore",MiscData!U17,MiscData!U14) -> Not used
A28: Check Core | B28: 36 | C28: Used in Mesh Mode to check an specific core data, such as voltage, frequency, license, dcf… If slice, this is set to the tested core. | D28: Limits
A29: Voltage Type | B29: vbump | C29: vbump or fixed | D29: MAX | E29: MIN
A30: Voltage IA | C30: {=_xlfn.SWITCH(B29,"vbump",_xlfn.SWITCH(TRUE,experiment07[[#This Row],[Value]]="",MiscData!U15,experiment07[[#This Row],[Value]]>MiscData!N3,MiscData!U4,experiment07[[#This Row],[Value]]<MiscData!O3,MiscData!U5,MiscData!U3),"fixed",_xlfn.SWITCH(TRUE,experiment07[[#This Row],[Value]]="",MiscData!U15,experiment07[[#This Row],[Value]]>MiscData!N7,MiscData!U4,experiment07[[#This Row],[Value]]<MiscData!O7,MiscData!U5,MiscData!U3),"")} -> Not Configured | D30: {=_xlfn.SWITCH(B$29,"vbump",MiscData!N3,"fixed",MiscData!N7,"")} -> 0.2 | E30: {=_xlfn.SWITCH(B$29,"vbump",MiscData!O3,"fixed",MiscData!O7,"")} -> -0.2
A31: Voltage CFC | C31: {=_xlfn.SWITCH(B29,"vbump",_xlfn.SWITCH(TRUE,experiment07[[#This Row],[Value]]="",MiscData!U15,experiment07[[#This Row],[Value]]>MiscData!N4,MiscData!U4,experiment07[[#This Row],[Value]]<MiscData!O4,MiscData!U5,MiscData!U3),"fixed",_xlfn.SWITCH(TRUE,experiment07[[#This Row],[Value]]="",MiscData!U15,experiment07[[#This Row],[Value]]>MiscData!N8,MiscData!U4,experiment07[[#This Row],[Value]]<MiscData!O8,MiscData!U5,MiscData!U3),"")} -> Not Configured | D31: {=_xlfn.SWITCH(B$29,"vbump",MiscData!N4,"fixed",MiscData!N8,"")} -> 0.2 | E31: {=_xlfn.SWITCH(B$29,"vbump",MiscData!O4,"fixed",MiscData!O8,"")} -> -0.2
A32: Frequency IA | C32: {=_xlfn.SWITCH(TRUE,experiment07[[#This Row],[Value]]="",MiscData!U15,experiment07[[#This Row],[Value]]>MiscData!Q3,MiscData!U4,experiment07[[#This Row],[Value]]<MiscData!R3,MiscData!U5,MiscData!U3)} -> Not Configured | D32: =MiscData!Q3 -> 44 | E32: =MiscData!R3 -> 5
A33: Frequency CFC | C33: {=_xlfn.SWITCH(TRUE,experiment07[[#This Row],[Value]]="",MiscData!U15,experiment07[[#This Row],[Value]]>MiscData!Q4,MiscData!U4,experiment07[[#This Row],[Value]]<MiscData!R4,MiscData!U5,MiscData!U3)} -> Not Configured | D33: =MiscData!Q4 -> 22 | E33: =MiscData!R4 -> 8
A34: Loops | B34: 5 | C34: {=_xlfn.SWITCH(B6,"Loops",MiscData!U6,MiscData!U14)} -> Not used
A35: Type | B35: Voltage | C35: {=_xlfn.SWITCH($B$6,"Sweep",MiscData!U7,MiscData!$U$14)} -> Select Type: Frequency or Voltage
A36: Domain | B36: CFC | C36: {=_xlfn.SWITCH($B$6,"Sweep",MiscData!U8,MiscData!$U$14)} -> Select domain: IA or CFC
A37: Start | B37: 0.05 | C37: {=_xlfn.SWITCH($B$6,"Sweep",MiscData!U9,MiscData!$U$14)} -> Start point of Sweep. Consider above limits for CFC / IA
A38: End | B38: 0.2 | C38: {=_xlfn.SWITCH($B$6,"Sweep",MiscData!U10,MiscData!$U$14)} -> End point of Sweep. Consider above limits for CFC / IA
A39: Steps | B39: 0.05 | C39: {=_xlfn.SWITCH($B$6,"Sweep",MiscData!U11,MiscData!$U$14)} -> Size of each step
A40: ShmooFile | B40: C:\SystemDebug\Shmoos\RVPShmooConfig.json | C40: {=_xlfn.SWITCH($B$6,"Shmoo",MiscData!U12,MiscData!$U$14)} -> Not used
...

Sheet CFC_Frequency
A1: Test Configuration | C1: Field Notes
A2: Field | B2: Value
A3: Experiment | B3: Enabled | C3: {=_xlfn.SWITCH(experiment078[[#This Row],[Value]],"Disabled","Experiment disabled will not run", " Experiment recipe enabled")} -> Experiment recipe enabled
A4: Test Name | B4: CFCFrequency | C4: Name of Test to be executed
A5: Test Mode | B5: Mesh | C5: Test Mode: Slice or Mesh
A6: Test Type | B6: Sweep | C6: Type of test: Loops, Sweep or Shmoo
A7: Visual ID | B7: TestUnitData | C7: Unit Visual ID
A8: Bucket | B8: IDIPAR | C8: Unit Assigned Bucket
A9: COM Port | B9: 11 | C9: Serial Port to communicate to MB
A10: IP Address | B10: 10.250.0.2 | C10: IP Address to communicate to MB
A11: TTL Folder | B11: S:\GNR\RVP\TTLs\TTL_DragonMesh | C11: Teraterm TTL Macros Folder Location with Commands.ttl and Connect.ttl files
A12: Scripts File | C12: Script File to be loaded before Test Execution
A13: Post Process | C13: Script File to be loaded after Test Execution
A14: Pass String | B14: Test Complete | C14: Lookup String for a Pass Condition of the Test
A15: Fail String | B15: Test Failed | C15: Lookup String for a Fail Condition of the Test
A16: Content | B16: Dragon | C16: Select your content: Linux | Dragon | PYSConsole (Custom Python Script)
A17: Test Number | B17: 11 | C17: First Number to be assigned to your test iteration
A18: Test Time | B18: 30 | C18: Wait time to be used for watchdog monitoring of console, in case unit is hang or failed during execution
A19: Reset | B19: TRUE | C19: Reset Unit before Starting first experiment
A20: Reset on PASS | B20: TRUE | C20: Reset Unit after each PASS
A21: FastBoot | B21: TRUE | C21: if Mesh Masking is selected, set this to False
A22: Core License | C22: Leave Blank if not used
A23: 600W Unit | B23: FALSE | C23: True or False
A24: Pseudo Config | B24: FALSE | C24: {=IF(MiscData!C1="AtomCore",MiscData!U14,_xlfn.SWITCH($B$5,"Slice",MiscData!U14,MiscData!U16))} -> Set if using Pseudo Mesh Content, to disable HT
A25: Configuration (Mask) | C25: =_xlfn.XLOOKUP(B5,MiscData!K3:K5,MiscData!L3:L5) -> Mesh Options: RowPass1, RowPass2, RowPass3, FirstPass, SecondPass, ThirdPass || Leave Blank if Full Chip
A26: Boot Breakpoint | C26: {=_xlfn.SWITCH(B16,"PYSVConsole",MiscData!U18,MiscData!U14)} -> Not used
A27: Disable 2 Cores | C27: =IF(MiscData!C1="AtomCore",MiscData!U17,MiscData!U14) -> Not used
A28: Check Core | B28: 36 | C28: Used in Mesh Mode to check an specific core data, such as voltage, frequency, license, dcf… If slice, this is set to the tested core. | D28: Limits
A29: Voltage Type | B29: vbump | C29: vbump or fixed | D29: MAX | E29: MIN
A30: Voltage IA | C30: {=_xlfn.SWITCH(B29,"vbump",_xlfn.SWITCH(TRUE,experiment078[[#This Row],[Value]]="",MiscData!U15,experiment078[[#This Row],[Value]]>MiscData!N3,MiscData!U4,experiment078[[#This Row],[Value]]<MiscData!O3,MiscData!U5,MiscData!U3),"fixed",_xlfn.SWITCH(TRUE,experiment078[[#This Row],[Value]]="",MiscData!U15,experiment078[[#This Row],[Value]]>MiscData!N7,MiscData!U4,experiment078[[#This Row],[Value]]<MiscData!O7,MiscData!U5,MiscData!U3),"")} -> Not Configured | D30: {=_xlfn.SWITCH(B$29,"vbump",MiscData!N3,"fixed",MiscData!N7,"")} -> 0.2 | E30: {=_xlfn.SWITCH(B$29,"vbump",MiscData!O3,"fixed",MiscData!O7,"")} -> -0.2
A31: Voltage CFC | C31: {=_xlfn.SWITCH(B29,"vbump",_xlfn.SWITCH(TRUE,experiment078[[#This Row],[Value]]="",MiscData!U15,experiment078[[#This Row],[Value]]>MiscData!N4,MiscData!U4,experiment078[[#This Row],[Value]]<MiscData!O4,MiscData!U5,MiscData!U3),"fixed",_xlfn.SWITCH(TRUE,experiment078[[#This Row],[Value]]="",MiscData!U15,experiment078[[#This Row],[Value]]>MiscData!N8,MiscData!U4,experiment078[[#This Row],[Value]]<MiscData!O8,MiscData!U5,MiscData!U3),"")} -> Not Configured | D31: {=_xlfn.SWITCH(B$29,"vbump",MiscData!N4,"fixed",MiscData!N8,"")} -> 0.2 | E31: {=_xlfn.SWITCH(B$29,"vbump",MiscData!O4,"fixed",MiscData!O8,"")} -> -0.2
A32: Frequency IA | C32: {=_xlfn.SWITCH(TRUE,experiment078[[#This Row],[Value]]="",MiscData!U15,experiment078[[#This Row],[Value]]>MiscData!Q3,MiscData!U4,experiment078[[#This Row],[Value]]<MiscData!R3,MiscData!U5,MiscData!U3)} -> Not Configured | D32: =MiscData!Q3 -> 44 | E32: =MiscData!R3 -> 5
A33: Frequency CFC | C33: {=_xlfn.SWITCH(TRUE,experiment078[[#This Row],[Value]]="",MiscData!U15,experiment078[[#This Row],[Value]]>MiscData!Q4,MiscData!U4,experiment078[[#This Row],[Value]]<MiscData!R4,MiscData!U5,MiscData!U3)} -> Not Configured | D33: =MiscData!Q4 -> 22 | E33: =MiscData!R4 -> 8
A34: Loops | B34: 5 | C34: {=_xlfn.SWITCH(B6,"Loops",MiscData!U6,MiscData!U14)} -> Not used
A35: Type | B35: Frequency | C35: {=_xlfn.SWITCH($B$6,"Sweep",MiscData!U7,MiscData!$U$14)} -> Select Type: Frequency or Voltage
A36: Domain | B36: CFC | C36: {=_xlfn.SWITCH($B$6,"Sweep",MiscData!U8,MiscData!$U$14)} -> Select domain: IA or CFC
A37: Start | B37: 8 | C37: {=_xlfn.SWITCH($B$6,"Sweep",MiscData!U9,MiscData!$U$14)} -> Start point of Sweep. Consider above limits for CFC / IA
A38: End | B38: 22 | C38: {=_xlfn.SWITCH($B$6,"Sweep",MiscData!U10,MiscData!$U$14)} -> End point of Sweep. Consider above limits for CFC / IA
A39: Steps | B39: 4 | C39: {=_xlfn.SWITCH($B$6,"Sweep",MiscData!U11,MiscData!$U$14)} -> Size of each step
A40: ShmooFile | B40: C:\SystemDebug\Shmoos\RVPShmooConfig.json | C40: {=_xlfn.SWITCH($B$6,"Shmoo",MiscData!U12,MiscData!$U$14)} -> Not used
...

Sheet IA_Voltage
A1: Test Configuration | C1: Field Notes
A2: Field | B2: Value
A3: Experiment | B3: Enabled | C3: {=_xlfn.SWITCH(experiment0712[[#This Row],[Value]],"Disabled","Experiment disabled will not run", " Experiment recipe enabled")} -> Experiment recipe enabled
A4: Test Name | B4: IAVoltage | C4: Name of Test to be executed
A5: Test Mode | B5: Mesh | C5: Test Mode: Slice or Mesh
A6: Test Type | B6: Sweep | C6: Type of test: Loops, Sweep or Shmoo
A7: Visual ID | B7: TestUnitData | C7: Unit Visual ID
A8: Bucket | B8: IDIPAR | C8: Unit Assigned Bucket
A9: COM Port | B9: 11 | C9: Serial Port to communicate to MB
A10: IP Address | B10: 10.250.0.2 | C10: IP Address to communicate to MB
A11: TTL Folder | B11: S:\GNR\RVP\TTLs\TTL_DragonMesh | C11: Teraterm TTL Macros Folder Location with Commands.ttl and Connect.ttl files
A12: Scripts File | C12: Script File to be loaded before Test Execution
A13: Post Process | C13: Script File to be loaded after Test Execution
A14: Pass String | B14: Test Complete | C14: Lookup String for a Pass Condition of the Test
A15: Fail String | B15: Test Failed | C15: Lookup String for a Fail Condition of the Test
A16: Content | B16: Dragon | C16: Select your content: Linux | Dragon | PYSConsole (Custom Python Script)
A17: Test Number | B17: 11 | C17: First Number to be assigned to your test iteration
A18: Test Time | B18: 30 | C18: Wait time to be used for watchdog monitoring of console, in case unit is hang or failed during execution
A19: Reset | B19: TRUE | C19: Reset Unit before Starting first experiment
A20: Reset on PASS | B20: TRUE | C20: Reset Unit after each PASS
A21: FastBoot | B21: TRUE | C21: if Mesh Masking is selected, set this to False
A22: Core License | C22: Leave Blank if not used
A23: 600W Unit | B23: FALSE | C23: True or False
A24: Pseudo Config | B24: FALSE | C24: {=IF(MiscData!C1="AtomCore",MiscData!U14,_xlfn.SWITCH($B$5,"Slice",MiscData!U14,MiscData!U16))} -> Set if using Pseudo Mesh Content, to disable HT
A25: Configuration (Mask) | C25: =_xlfn.XLOOKUP(B5,MiscData!K3:K5,MiscData!L3:L5) -> Mesh Options: RowPass1, RowPass2, RowPass3, FirstPass, SecondPass, ThirdPass || Leave Blank if Full Chip
A26: Boot Breakpoint | C26: {=_xlfn.SWITCH(B16,"PYSVConsole",MiscData!U18,MiscData!U14)} -> Not used
A27: Disable 2 Cores | C27: =IF(MiscData!C1="AtomCore",MiscData!U17,MiscData!U14) -> Not used
A28: Check Core | B28: 36 | C28: Used in Mesh Mode to check an specific core data, such as voltage, frequency, license, dcf… If slice, this is set to the tested core. | D28: Limits
A29: Voltage Type | B29: vbump | C29: vbump or fixed | D29: MAX | E29: MIN
A30: Voltage IA | C30: {=_xlfn.SWITCH(B29,"vbump",_xlfn.SWITCH(TRUE,experiment0712[[#This Row],[Value]]="",MiscData!U15,experiment0712[[#This Row],[Value]]>MiscData!N3,MiscData!U4,experiment0712[[#This Row],[Value]]<MiscData!O3,MiscData!U5,MiscData!U3),"fixed",_xlfn.SWITCH(TRUE,experiment0712[[#This Row],[Value]]="",MiscData!U15,experiment0712[[#This Row],[Value]]>MiscData!N7,MiscData!U4,experiment0712[[#This Row],[Value]]<MiscData!O7,MiscData!U5,MiscData!U3),"")} -> Not Configured | D30: {=_xlfn.SWITCH(B$29,"vbump",MiscData!N3,"fixed",MiscData!N7,"")} -> 0.2 | E30: {=_xlfn.SWITCH(B$29,"vbump",MiscData!O3,"fixed",MiscData!O7,"")} -> -0.2
A31: Voltage CFC | C31: {=_xlfn.SWITCH(B29,"vbump",_xlfn.SWITCH(TRUE,experiment0712[[#This Row],[Value]]="",MiscData!U15,experiment0712[[#This Row],[Value]]>MiscData!N4,MiscData!U4,experiment0712[[#This Row],[Value]]<MiscData!O4,MiscData!U5,MiscData!U3),"fixed",_xlfn.SWITCH(TRUE,experiment0712[[#This Row],[Value]]="",MiscData!U15,experiment0712[[#This Row],[Value]]>MiscData!N8,MiscData!U4,experiment0712[[#This Row],[Value]]<MiscData!O8,MiscData!U5,MiscData!U3),"")} -> Not Configured | D31: {=_xlfn.SWITCH(B$29,"vbump",MiscData!N4,"fixed",MiscData!N8,"")} -> 0.2 | E31: {=_xlfn.SWITCH(B$29,"vbump",MiscData!O4,"fixed",MiscData!O8,"")} -> -0.2
A32: Frequency IA | C32: {=_xlfn.SWITCH(TRUE,experiment0712[[#This Row],[Value]]="",MiscData!U15,experiment0712[[#This Row],[Value]]>MiscData!Q3,MiscData!U4,experiment0712[[#This Row],[Value]]<MiscData!R3,MiscData!U5,MiscData!U3)} -> Not Configured | D32: =MiscData!Q3 -> 44 | E32: =MiscData!R3 -> 5
A33: Frequency CFC | C33: {=_xlfn.SWITCH(TRUE,experiment0712[[#This Row],[Value]]="",MiscData!U15,experiment0712[[#This Row],[Value]]>MiscData!Q4,MiscData!U4,experiment0712[[#This Row],[Value]]<MiscData!R4,MiscData!U5,MiscData!U3)} -> Not Configured | D33: =MiscData!Q4 -> 22 | E33: =MiscData!R4 -> 8
A34: Loops | B34: 5 | C34: {=_xlfn.SWITCH(B6,"Loops",MiscData!U6,MiscData!U14)} -> Not used
A35: Type | B35: Voltage | C35: {=_xlfn.SWITCH($B$6,"Sweep",MiscData!U7,MiscData!$U$14)} -> Select Type: Frequency or Voltage
A36: Domain | B36: IA | C36: {=_xlfn.SWITCH($B$6,"Sweep",MiscData!U8,MiscData!$U$14)} -> Select domain: IA or CFC
A37: Start | B37: 0.05 | C37: {=_xlfn.SWITCH($B$6,"Sweep",MiscData!U9,MiscData!$U$14)} -> Start point of Sweep. Consider above limits for CFC / IA
A38: End | B38: 0.2 | C38: {=_xlfn.SWITCH($B$6,"Sweep",MiscData!U10,MiscData!$U$14)} -> End point of Sweep. Consider above limits for CFC / IA
A39: Steps | B39: 0.05 | C39: {=_xlfn.SWITCH($B$6,"Sweep",MiscData!U11,MiscData!$U$14)} -> Size of each step
A40: ShmooFile | B40: C:\SystemDebug\Shmoos\RVPShmooConfig.json | C40: {=_xlfn.SWITCH($B$6,"Shmoo",MiscData!U12,MiscData!$U$14)} -> Not used
...

Sheet IA_Frequency LO
A1: Test Configuration | C1: Field Notes
A2: Field | B2: Value
A3: Experiment | B3: Enabled | C3: {=_xlfn.SWITCH(experiment07815[[#This Row],[Value]],"Disabled","Experiment disabled will not run", " Experiment recipe enabled")} -> Experiment recipe enabled
A4: Test Name | B4: IAFrequencyLO | C4: Name of Test to be executed
A5: Test Mode | B5: Mesh | C5: Test Mode: Slice or Mesh
A6: Test Type | B6: Sweep | C6: Type of test: Loops, Sweep or Shmoo
A7: Visual ID | B7: TestUnitData | C7: Unit Visual ID
A8: Bucket | B8: IDIPAR | C8: Unit Assigned Bucket
A9: COM Port | B9: 11 | C9: Serial Port to communicate to MB
A10: IP Address | B10: 10.250.0.2 | C10: IP Address to communicate to MB
A11: TTL Folder | B11: S:\GNR\RVP\TTLs\TTL_DragonMesh | C11: Teraterm TTL Macros Folder Location with Commands.ttl and Connect.ttl files
A12: Scripts File | C12: Script File to be loaded before Test Execution
A13: Post Process | C13: Script File to be loaded after Test Execution
A14: Pass String | B14: Test Complete | C14: Lookup String for a Pass Condition of the Test
A15: Fail String | B15: Test Failed | C15: Lookup String for a Fail Condition of the Test
A16: Content | B16: Dragon | C16: Select your content: Linux | Dragon | PYSConsole (Custom Python Script)
A17: Test Number | B17: 11 | C17: First Number to be assigned to your test iteration
A18: Test Time | B18: 30 | C18: Wait time to be used for watchdog monitoring of console, in case unit is hang or failed during execution
A19: Reset | B19: TRUE | C19: Reset Unit before Starting first experiment
A20: Reset on PASS | B20: TRUE | C20: Reset Unit after each PASS
A21: FastBoot | B21: TRUE | C21: if Mesh Masking is selected, set this to False
A22: Core License | C22: Leave Blank if not used
A23: 600W Unit | B23: FALSE | C23: True or False
A24: Pseudo Config | B24: FALSE | C24: {=IF(MiscData!C1="AtomCore",MiscData!U14,_xlfn.SWITCH($B$5,"Slice",MiscData!U14,MiscData!U16))} -> Set if using Pseudo Mesh Content, to disable HT
A25: Configuration (Mask) | C25: =_xlfn.XLOOKUP(B5,MiscData!K3:K5,MiscData!L3:L5) -> Mesh Options: RowPass1, RowPass2, RowPass3, FirstPass, SecondPass, ThirdPass || Leave Blank if Full Chip
A26: Boot Breakpoint | C26: {=_xlfn.SWITCH(B16,"PYSVConsole",MiscData!U18,MiscData!U14)} -> Not used
A27: Disable 2 Cores | C27: =IF(MiscData!C1="AtomCore",MiscData!U17,MiscData!U14) -> Not used
A28: Check Core | B28: 36 | C28: Used in Mesh Mode to check an specific core data, such as voltage, frequency, license, dcf… If slice, this is set to the tested core. | D28: Limits
A29: Voltage Type | B29: vbump | C29: vbump or fixed | D29: MAX | E29: MIN
A30: Voltage IA | C30: {=_xlfn.SWITCH(B29,"vbump",_xlfn.SWITCH(TRUE,experiment07815[[#This Row],[Value]]="",MiscData!U15,experiment07815[[#This Row],[Value]]>MiscData!N3,MiscData!U4,experiment07815[[#This Row],[Value]]<MiscData!O3,MiscData!U5,MiscData!U3),"fixed",_xlfn.SWITCH(TRUE,experiment07815[[#This Row],[Value]]="",MiscData!U15,experiment07815[[#This Row],[Value]]>MiscData!N7,MiscData!U4,experiment07815[[#This Row],[Value]]<MiscData!O7,MiscData!U5,MiscData!U3),"")} -> Not Configured | D30: {=_xlfn.SWITCH(B$29,"vbump",MiscData!N3,"fixed",MiscData!N7,"")} -> 0.2 | E30: {=_xlfn.SWITCH(B$29,"vbump",MiscData!O3,"fixed",MiscData!O7,"")} -> -0.2
A31: Voltage CFC | C31: {=_xlfn.SWITCH(B29,"vbump",_xlfn.SWITCH(TRUE,experiment07815[[#This Row],[Value]]="",MiscData!U15,experiment07815[[#This Row],[Value]]>MiscData!N4,MiscData!U4,experiment07815[[#This Row],[Value]]<MiscData!O4,MiscData!U5,MiscData!U3),"fixed",_xlfn.SWITCH(TRUE,experiment07815[[#This Row],[Value]]="",MiscData!U15,experiment07815[[#This Row],[Value]]>MiscData!N8,MiscData!U4,experiment07815[[#This Row],[Value]]<MiscData!O8,MiscData!U5,MiscData!U3),"")} -> Not Configured | D31: {=_xlfn.SWITCH(B$29,"vbump",MiscData!N4,"fixed",MiscData!N8,"")} -> 0.2 | E31: {=_xlfn.SWITCH(B$29,"vbump",MiscData!O4,"fixed",MiscData!O8,"")} -> -0.2
A32: Frequency IA | C32: {=_xlfn.SWITCH(TRUE,experiment07815[[#This Row],[Value]]="",MiscData!U15,experiment07815[[#This Row],[Value]]>MiscData!Q3,MiscData!U4,experiment07815[[#This Row],[Value]]<MiscData!R3,MiscData!U5,MiscData!U3)} -> Not Configured | D32: =MiscData!Q3 -> 44 | E32: =MiscData!R3 -> 5
A33: Frequency CFC | C33: {=_xlfn.SWITCH(TRUE,experiment07815[[#This Row],[Value]]="",MiscData!U15,experiment07815[[#This Row],[Value]]>MiscData!Q4,MiscData!U4,experiment07815[[#This Row],[Value]]<MiscData!R4,MiscData!U5,MiscData!U3)} -> Not Configured | D33: =MiscData!Q4 -> 22 | E33: =MiscData!R4 -> 8
A34: Loops | B34: 5 | C34: {=_xlfn.SWITCH(B6,"Loops",MiscData!U6,MiscData!U14)} -> Not used
A35: Type | B35: Frequency | C35: {=_xlfn.SWITCH($B$6,"Sweep",MiscData!U7,MiscData!$U$14)} -> Select Type: Frequency or Voltage
A36: Domain | B36: IA | C36: {=_xlfn.SWITCH($B$6,"Sweep",MiscData!U8,MiscData!$U$14)} -> Select domain: IA or CFC
A37: Start | B37: 8 | C37: {=_xlfn.SWITCH($B$6,"Sweep",MiscData!U9,MiscData!$U$14)} -> Start point of Sweep. Consider above limits for CFC / IA
A38: End | B38: 32 | C38: {=_xlfn.SWITCH($B$6,"Sweep",MiscData!U10,MiscData!$U$14)} -> End point of Sweep. Consider above limits for CFC / IA
A39: Steps | B39: 4 | C39: {=_xlfn.SWITCH($B$6,"Sweep",MiscData!U11,MiscData!$U$14)} -> Size of each step
A40: ShmooFile | B40: C:\SystemDebug\Shmoos\RVPShmooConfig.json | C40: {=_xlfn.SWITCH($B$6,"Shmoo",MiscData!U12,MiscData!$U$14)} -> Not used
...

Sheet IA_Frequency HI
A1: Test Configuration | C1: Field Notes
A2: Field | B2: Value
A3: Experiment | B3: Enabled | C3: {=_xlfn.SWITCH(experiment0781518[[#This Row],[Value]],"Disabled","Experiment disabled will not run", " Experiment recipe enabled")} -> Experiment recipe enabled
A4: Test Name | B4: IAFrequencyHI | C4: Name of Test to be executed
A5: Test Mode | B5: Mesh | C5: Test Mode: Slice or Mesh
A6: Test Type | B6: Sweep | C6: Type of test: Loops, Sweep or Shmoo
A7: Visual ID | B7: TestUnitData | C7: Unit Visual ID
A8: Bucket | B8: IDIPAR | C8: Unit Assigned Bucket
A9: COM Port | B9: 11 | C9: Serial Port to communicate to MB
A10: IP Address | B10: 10.250.0.2 | C10: IP Address to communicate to MB
A11: TTL Folder | B11: S:\GNR\RVP\TTLs\TTL_DragonMesh | C11: Teraterm TTL Macros Folder Location with Commands.ttl and Connect.ttl files
A12: Scripts File | C12: Script File to be loaded before Test Execution
A13: Post Process | C13: Script File to be loaded after Test Execution
A14: Pass String | B14: Test Complete | C14: Lookup String for a Pass Condition of the Test
A15: Fail String | B15: Test Failed | C15: Lookup String for a Fail Condition of the Test
A16: Content | B16: Dragon | C16: Select your content: Linux | Dragon | PYSConsole (Custom Python Script)
A17: Test Number | B17: 11 | C17: First Number to be assigned to your test iteration
A18: Test Time | B18: 30 | C18: Wait time to be used for watchdog monitoring of console, in case unit is hang or failed during execution
A19: Reset | B19: TRUE | C19: Reset Unit before Starting first experiment
A20: Reset on PASS | B20: TRUE | C20: Reset Unit after each PASS
A21: FastBoot | B21: FALSE | C21: if Mesh Masking is selected, set this to False
A22: Core License | C22: Leave Blank if not used
A23: 600W Unit | B23: FALSE | C23: True or False
A24: Pseudo Config | B24: FALSE | C24: {=IF(MiscData!C1="AtomCore",MiscData!U14,_xlfn.SWITCH($B$5,"Slice",MiscData!U14,MiscData!U16))} -> Set if using Pseudo Mesh Content, to disable HT
A25: Configuration (Mask) | B25: FirstPass | C25: =_xlfn.XLOOKUP(B5,MiscData!K3:K5,MiscData!L3:L5) -> Mesh Options: RowPass1, RowPass2, RowPass3, FirstPass, SecondPass, ThirdPass || Leave Blank if Full Chip
A26: Boot Breakpoint | C26: {=_xlfn.SWITCH(B16,"PYSVConsole",MiscData!U18,MiscData!U14)} -> Not used
A27: Disable 2 Cores | C27: =IF(MiscData!C1="AtomCore",MiscData!U17,MiscData!U14) -> Not used
A28: Check Core | B28: 36 | C28: Used in Mesh Mode to check an specific core data, such as voltage, frequency, license, dcf… If slice, this is set to the tested core. | D28: Limits
A29: Voltage Type | B29: vbump | C29: vbump or fixed | D29: MAX | E29: MIN
A30: Voltage IA | C30: {=_xlfn.SWITCH(B29,"vbump",_xlfn.SWITCH(TRUE,experiment0781518[[#This Row],[Value]]="",MiscData!U15,experiment0781518[[#This Row],[Value]]>MiscData!N3,MiscData!U4,experiment0781518[[#This Row],[Value]]<MiscData!O3,MiscData!U5,MiscData!U3),"fixed",_xlfn.SWITCH(TRUE,experiment0781518[[#This Row],[Value]]="",MiscData!U15,experiment0781518[[#This Row],[Value]]>MiscData!N7,MiscData!U4,experiment0781518[[#This Row],[Value]]<MiscData!O7,MiscData!U5,MiscData!U3),"")} -> Not Configured | D30: {=_xlfn.SWITCH(B$29,"vbump",MiscData!N3,"fixed",MiscData!N7,"")} -> 0.2 | E30: {=_xlfn.SWITCH(B$29,"vbump",MiscData!O3,"fixed",MiscData!O7,"")} -> -0.2
A31: Voltage CFC | C31: {=_xlfn.SWITCH(B29,"vbump",_xlfn.SWITCH(TRUE,experiment0781518[[#This Row],[Value]]="",MiscData!U15,experiment0781518[[#This Row],[Value]]>MiscData!N4,MiscData!U4,experiment0781518[[#This Row],[Value]]<MiscData!O4,MiscData!U5,MiscData!U3),"fixed",_xlfn.SWITCH(TRUE,experiment0781518[[#This Row],[Value]]="",MiscData!U15,experiment0781518[[#This Row],[Value]]>MiscData!N8,MiscData!U4,experiment0781518[[#This Row],[Value]]<MiscData!O8,MiscData!U5,MiscData!U3),"")} -> Not Configured | D31: {=_xlfn.SWITCH(B$29,"vbump",MiscData!N4,"fixed",MiscData!N8,"")} -> 0.2 | E31: {=_xlfn.SWITCH(B$29,"vbump",MiscData!O4,"fixed",MiscData!O8,"")} -> -0.2
A32: Frequency IA | C32: {=_xlfn.SWITCH(TRUE,experiment0781518[[#This Row],[Value]]="",MiscData!U15,experiment0781518[[#This Row],[Value]]>MiscData!Q3,MiscData!U4,experiment0781518[[#This Row],[Value]]<MiscData!R3,MiscData!U5,MiscData!U3)} -> Not Configured | D32: =MiscData!Q3 -> 44 | E32: =MiscData!R3 -> 5
A33: Frequency CFC | C33: {=_xlfn.SWITCH(TRUE,experiment0781518[[#This Row],[Value]]="",MiscData!U15,experiment0781518[[#This Row],[Value]]>MiscData!Q4,MiscData!U4,experiment0781518[[#This Row],[Value]]<MiscData!R4,MiscData!U5,MiscData!U3)} -> Not Configured | D33: =MiscData!Q4 -> 22 | E33: =MiscData!R4 -> 8
A34: Loops | B34: 5 | C34: {=_xlfn.SWITCH(B6,"Loops",MiscData!U6,MiscData!U14)} -> Not used
A35: Type | B35: Frequency | C35: {=_xlfn.SWITCH($B$6,"Sweep",MiscData!U7,MiscData!$U$14)} -> Select Type: Frequency or Voltage
A36: Domain | B36: IA | C36: {=_xlfn.SWITCH($B$6,"Sweep",MiscData!U8,MiscData!$U$14)} -> Select domain: IA or CFC
A37: Start | B37: 36 | C37: {=_xlfn.SWITCH($B$6,"Sweep",MiscData!U9,MiscData!$U$14)} -> Start point of Sweep. Consider above limits for CFC / IA
A38: End | B38: 40 | C38: {=_xlfn.SWITCH($B$6,"Sweep",MiscData!U10,MiscData!$U$14)} -> End point of Sweep. Consider above limits for CFC / IA
A39: Steps | B39: 4 | C39: {=_xlfn.SWITCH($B$6,"Sweep",MiscData!U11,MiscData!$U$14)} -> Size of each step
A40: ShmooFile | B40: C:\SystemDebug\Shmoos\RVPShmooConfig.json | C40: {=_xlfn.SWITCH($B$6,"Shmoo",MiscData!U12,MiscData!$U$14)} -> Not used
...

Sheet TSL_3sBreadth
A1: Test Configuration | C1: Field Notes
A2: Field | B2: Value
A3: Experiment | B3: Enabled | C3: {=_xlfn.SWITCH(experiment013[[#This Row],[Value]],"Disabled","Experiment disabled will not run", " Experiment recipe enabled")} -> Experiment recipe enabled
A4: Test Name | B4: TSL3s_Breadth | C4: Name of Test to be executed
A5: Test Mode | B5: Mesh | C5: Test Mode: Slice or Mesh
A6: Test Type | B6: Loops | C6: Type of test: Loops, Sweep or Shmoo
A7: Visual ID | B7: 759Q17J500189 | C7: Unit Visual ID
A8: Bucket | B8: 3Strike | C8: Unit Assigned Bucket
A9: COM Port | B9: 8 | C9: Serial Port to communicate to MB
A10: IP Address | B10: 10.250.0.2 | C10: IP Address to communicate to MB
A11: TTL Folder | B11: Q:\DPM_Debug\GNR\Logs\3Strike\759Q17J500189\\TTL_Linux | C11: Teraterm TTL Macros Folder Location with Commands.ttl and Connect.ttl files
A12: Scripts File | C12: Script File to be loaded before Test Execution
A13: Post Process | C13: Script File to be loaded after Test Execution
A14: Pass String | B14: exit: pass | C14: Lookup String for a Pass Condition of the Test
A15: Fail String | B15: exit: fail | C15: Lookup String for a Fail Condition of the Test
A16: Content | B16: Linux | C16: Select your content: Linux | Dragon | PYSConsole (Custom Python Script)
A17: Test Number | B17: 9 | C17: First Number to be assigned to your test iteration
A18: Test Time | B18: 30 | C18: Wait time to be used for watchdog monitoring of console, in case unit is hang or failed during execution
A19: Reset | B19: TRUE | C19: Reset Unit before Starting first experiment
A20: Reset on PASS | B20: TRUE | C20: Reset Unit after each PASS
A21: FastBoot | B21: TRUE | C21: if Mesh Masking is selected, set this to False
A22: Core License | C22: Leave Blank if not used
A23: 600W Unit | B23: TRUE | C23: True or False
A24: Pseudo Config | B24: FALSE | C24: {=IF(MiscData!C1="AtomCore",MiscData!U14,_xlfn.SWITCH($B$5,"Slice",MiscData!U14,MiscData!U16))} -> Set if using Pseudo Mesh Content, to disable HT
A25: Configuration (Mask) | C25: =_xlfn.XLOOKUP(B5,MiscData!K3:K5,MiscData!L3:L5) -> Mesh Options: RowPass1, RowPass2, RowPass3, FirstPass, SecondPass, ThirdPass || Leave Blank if Full Chip
A26: Boot Breakpoint | C26: {=_xlfn.SWITCH(B16,"PYSVConsole",MiscData!U18,MiscData!U14)} -> Not used
A27: Disable 2 Cores | C27: =IF(MiscData!C1="AtomCore",MiscData!U17,MiscData!U14) -> Not used
A28: Check Core | B28: 36 | C28: Used in Mesh Mode to check an specific core data, such as voltage, frequency, license, dcf… If slice, this is set to the tested core. | D28: Limits
A29: Voltage Type | B29: vbump | C29: vbump or fixed | D29: MAX | E29: MIN
A30: Voltage IA | C30: {=_xlfn.SWITCH(B29,"vbump",_xlfn.SWITCH(TRUE,experiment013[[#This Row],[Value]]="",MiscData!U15,experiment013[[#This Row],[Value]]>MiscData!N3,MiscData!U4,experiment013[[#This Row],[Value]]<MiscData!O3,MiscData!U5,MiscData!U3),"fixed",_xlfn.SWITCH(TRUE,experiment013[[#This Row],[Value]]="",MiscData!U15,experiment013[[#This Row],[Value]]>MiscData!N7,MiscData!U4,experiment013[[#This Row],[Value]]<MiscData!O7,MiscData!U5,MiscData!U3),"")} -> Not Configured | D30: {=_xlfn.SWITCH(B$29,"vbump",MiscData!N3,"fixed",MiscData!N7,"")} -> 0.2 | E30: {=_xlfn.SWITCH(B$29,"vbump",MiscData!O3,"fixed",MiscData!O7,"")} -> -0.2
A31: Voltage CFC | C31: {=_xlfn.SWITCH(B29,"vbump",_xlfn.SWITCH(TRUE,experiment013[[#This Row],[Value]]="",MiscData!U15,experiment013[[#This Row],[Value]]>MiscData!N4,MiscData!U4,experiment013[[#This Row],[Value]]<MiscData!O4,MiscData!U5,MiscData!U3),"fixed",_xlfn.SWITCH(TRUE,experiment013[[#This Row],[Value]]="",MiscData!U15,experiment013[[#This Row],[Value]]>MiscData!N8,MiscData!U4,experiment013[[#This Row],[Value]]<MiscData!O8,MiscData!U5,MiscData!U3),"")} -> Not Configured | D31: {=_xlfn.SWITCH(B$29,"vbump",MiscData!N4,"fixed",MiscData!N8,"")} -> 0.2 | E31: {=_xlfn.SWITCH(B$29,"vbump",MiscData!O4,"fixed",MiscData!O8,"")} -> -0.2
A32: Frequency IA | C32: {=_xlfn.SWITCH(TRUE,experiment013[[#This Row],[Value]]="",MiscData!U15,experiment013[[#This Row],[Value]]>MiscData!Q3,MiscData!U4,experiment013[[#This Row],[Value]]<MiscData!R3,MiscData!U5,MiscData!U3)} -> Not Configured | D32: =MiscData!Q3 -> 44 | E32: =MiscData!R3 -> 5
A33: Frequency CFC | C33: {=_xlfn.SWITCH(TRUE,experiment013[[#This Row],[Value]]="",MiscData!U15,experiment013[[#This Row],[Value]]>MiscData!Q4,MiscData!U4,experiment013[[#This Row],[Value]]<MiscData!R4,MiscData!U5,MiscData!U3)} -> Not Configured | D33: =MiscData!Q4 -> 22 | E33: =MiscData!R4 -> 8
A34: Loops | B34: 5 | C34: {=_xlfn.SWITCH(B6,"Loops",MiscData!U6,MiscData!U14)} -> Number of Loops to run
A35: Type | B35: Voltage | C35: {=_xlfn.SWITCH($B$6,"Sweep",MiscData!U7,MiscData!$U$14)} -> Not used
A36: Domain | B36: IA | C36: {=_xlfn.SWITCH($B$6,"Sweep",MiscData!U8,MiscData!$U$14)} -> Not used
A37: Start | B37: -0.03 | C37: {=_xlfn.SWITCH($B$6,"Sweep",MiscData!U9,MiscData!$U$14)} -> Not used
A38: End | B38: 0.06 | C38: {=_xlfn.SWITCH($B$6,"Sweep",MiscData!U10,MiscData!$U$14)} -> Not used
A39: Steps | B39: 0.03 | C39: {=_xlfn.SWITCH($B$6,"Sweep",MiscData!U11,MiscData!$U$14)} -> Not used
A40: ShmooFile | B40: C:\SystemDebug\Shmoos\RVPShmooConfig.json | C40: {=_xlfn.SWITCH($B$6,"Shmoo",MiscData!U12,MiscData!$U$14)} -> Not used
...

Sheet TSL_1sBreadth
A1: Test Configuration | C1: Field Notes
A2: Field | B2: Value
A3: Experiment | B3: Enabled | C3: {=_xlfn.SWITCH(experiment0139[[#This Row],[Value]],"Disabled","Experiment disabled will not run", " Experiment recipe enabled")} -> Experiment recipe enabled
A4: Test Name | B4: TSL1s_Breadth | C4: Name of Test to be executed
A5: Test Mode | B5: Mesh | C5: Test Mode: Slice or Mesh
A6: Test Type | B6: Loops | C6: Type of test: Loops, Sweep or Shmoo
A7: Visual ID | B7: 759Q17J500189 | C7: Unit Visual ID
A8: Bucket | B8: 3Strike | C8: Unit Assigned Bucket
A9: COM Port | B9: 8 | C9: Serial Port to communicate to MB
A10: IP Address | B10: 10.250.0.2 | C10: IP Address to communicate to MB
A11: TTL Folder | B11: Q:\DPM_Debug\GNR\Logs\3Strike\759Q17J500189\\TTL_Linux | C11: Teraterm TTL Macros Folder Location with Commands.ttl and Connect.ttl files
A12: Scripts File | C12: Script File to be loaded before Test Execution
A13: Post Process | C13: Script File to be loaded after Test Execution
A14: Pass String | B14: exit: pass | C14: Lookup String for a Pass Condition of the Test
A15: Fail String | B15: exit: fail | C15: Lookup String for a Fail Condition of the Test
A16: Content | B16: Linux | C16: Select your content: Linux | Dragon | PYSConsole (Custom Python Script)
A17: Test Number | B17: 9 | C17: First Number to be assigned to your test iteration
A18: Test Time | B18: 30 | C18: Wait time to be used for watchdog monitoring of console, in case unit is hang or failed during execution
A19: Reset | B19: TRUE | C19: Reset Unit before Starting first experiment
A20: Reset on PASS | B20: TRUE | C20: Reset Unit after each PASS
A21: FastBoot | B21: TRUE | C21: if Mesh Masking is selected, set this to False
A22: Core License | C22: Leave Blank if not used
A23: 600W Unit | B23: TRUE | C23: True or False
A24: Pseudo Config | B24: FALSE | C24: {=IF(MiscData!C1="AtomCore",MiscData!U14,_xlfn.SWITCH($B$5,"Slice",MiscData!U14,MiscData!U16))} -> Set if using Pseudo Mesh Content, to disable HT
A25: Configuration (Mask) | C25: =_xlfn.XLOOKUP(B5,MiscData!K3:K5,MiscData!L3:L5) -> Mesh Options: RowPass1, RowPass2, RowPass3, FirstPass, SecondPass, ThirdPass || Leave Blank if Full Chip
A26: Boot Breakpoint | C26: {=_xlfn.SWITCH(B16,"PYSVConsole",MiscData!U18,MiscData!U14)} -> Not used
A27: Disable 2 Cores | C27: =IF(MiscData!C1="AtomCore",MiscData!U17,MiscData!U14) -> Not used
A28: Check Core | B28: 36 | C28: Used in Mesh Mode to check an specific core data, such as voltage, frequency, license, dcf… If slice, this is set to the tested core. | D28: Limits
A29: Voltage Type | B29: vbump | C29: vbump or fixed | D29: MAX | E29: MIN
A30: Voltage IA | C30: {=_xlfn.SWITCH(B29,"vbump",_xlfn.SWITCH(TRUE,experiment0139[[#This Row],[Value]]="",MiscData!U15,experiment0139[[#This Row],[Value]]>MiscData!N3,MiscData!U4,experiment0139[[#This Row],[Value]]<MiscData!O3,MiscData!U5,MiscData!U3),"fixed",_xlfn.SWITCH(TRUE,experiment0139[[#This Row],[Value]]="",MiscData!U15,experiment0139[[#This Row],[Value]]>MiscData!N7,MiscData!U4,experiment0139[[#This Row],[Value]]<MiscData!O7,MiscData!U5,MiscData!U3),"")} -> Not Configured | D30: {=_xlfn.SWITCH(B$29,"vbump",MiscData!N3,"fixed",MiscData!N7,"")} -> 0.2 | E30: {=_xlfn.SWITCH(B$29,"vbump",MiscData!O3,"fixed",MiscData!O7,"")} -> -0.2
A31: Voltage CFC | C31: {=_xlfn.SWITCH(B29,"vbump",_xlfn.SWITCH(TRUE,experiment0139[[#This Row],[Value]]="",MiscData!U15,experiment0139[[#This Row],[Value]]>MiscData!N4,MiscData!U4,experiment0139[[#This Row],[Value]]<MiscData!O4,MiscData!U5,MiscData!U3),"fixed",_xlfn.SWITCH(TRUE,experiment0139[[#This Row],[Value]]="",MiscData!U15,experiment0139[[#This Row],[Value]]>MiscData!N8,MiscData!U4,experiment0139[[#This Row],[Value]]<MiscData!O8,MiscData!U5,MiscData!U3),"")} -> Not Configured | D31: {=_xlfn.SWITCH(B$29,"vbump",MiscData!N4,"fixed",MiscData!N8,"")} -> 0.2 | E31: {=_xlfn.SWITCH(B$29,"vbump",MiscData!O4,"fixed",MiscData!O8,"")} -> -0.2
A32: Frequency IA | C32: {=_xlfn.SWITCH(TRUE,experiment0139[[#This Row],[Value]]="",MiscData!U15,experiment0139[[#This Row],[Value]]>MiscData!Q3,MiscData!U4,experiment0139[[#This Row],[Value]]<MiscData!R3,MiscData!U5,MiscData!U3)} -> Not Configured | D32: =MiscData!Q3 -> 44 | E32: =MiscData!R3 -> 5
A33: Frequency CFC | C33: {=_xlfn.SWITCH(TRUE,experiment0139[[#This Row],[Value]]="",MiscData!U15,experiment0139[[#This Row],[Value]]>MiscData!Q4,MiscData!U4,experiment0139[[#This Row],[Value]]<MiscData!R4,MiscData!U5,MiscData!U3)} -> Not Configured | D33: =MiscData!Q4 -> 22 | E33: =MiscData!R4 -> 8
A34: Loops | B34: 5 | C34: {=_xlfn.SWITCH(B6,"Loops",MiscData!U6,MiscData!U14)} -> Number of Loops to run
A35: Type | B35: Voltage | C35: {=_xlfn.SWITCH($B$6,"Sweep",MiscData!U7,MiscData!$U$14)} -> Not used
A36: Domain | B36: IA | C36: {=_xlfn.SWITCH($B$6,"Sweep",MiscData!U8,MiscData!$U$14)} -> Not used
A37: Start | B37: -0.03 | C37: {=_xlfn.SWITCH($B$6,"Sweep",MiscData!U9,MiscData!$U$14)} -> Not used
A38: End | B38: 0.06 | C38: {=_xlfn.SWITCH($B$6,"Sweep",MiscData!U10,MiscData!$U$14)} -> Not used
A39: Steps | B39: 0.03 | C39: {=_xlfn.SWITCH($B$6,"Sweep",MiscData!U11,MiscData!$U$14)} -> Not used
A40: ShmooFile | B40: C:\SystemDebug\Shmoos\RVPShmooConfig.json | C40: {=_xlfn.SWITCH($B$6,"Shmoo",MiscData!U12,MiscData!$U$14)} -> Not used
...

Sheet TSL_500msBreadth
A1: Test Configuration | C1: Field Notes
A2: Field | B2: Value
A3: Experiment | B3: Enabled | C3: {=_xlfn.SWITCH(experiment013910[[#This Row],[Value]],"Disabled","Experiment disabled will not run", " Experiment recipe enabled")} -> Experiment recipe enabled
A4: Test Name | B4: TSL500ms_Breadth | C4: Name of Test to be executed
A5: Test Mode | B5: Mesh | C5: Test Mode: Slice or Mesh
A6: Test Type | B6: Loops | C6: Type of test: Loops, Sweep or Shmoo
A7: Visual ID | B7: 759Q17J500189 | C7: Unit Visual ID
A8: Bucket | B8: 3Strike | C8: Unit Assigned Bucket
A9: COM Port | B9: 8 | C9: Serial Port to communicate to MB
A10: IP Address | B10: 10.250.0.2 | C10: IP Address to communicate to MB
A11: TTL Folder | B11: Q:\DPM_Debug\GNR\Logs\3Strike\759Q17J500189\\TTL_Linux | C11: Teraterm TTL Macros Folder Location with Commands.ttl and Connect.ttl files
A12: Scripts File | C12: Script File to be loaded before Test Execution
A13: Post Process | C13: Script File to be loaded after Test Execution
A14: Pass String | B14: exit: pass | C14: Lookup String for a Pass Condition of the Test
A15: Fail String | B15: exit: fail | C15: Lookup String for a Fail Condition of the Test
A16: Content | B16: Linux | C16: Select your content: Linux | Dragon | PYSConsole (Custom Python Script)
A17: Test Number | B17: 9 | C17: First Number to be assigned to your test iteration
