Workbook
Name splitchar: ErrorData!$G$1

Sheet CHA
A1: VisualId | B1: Lot | C1: LatoStartWW | D1: LotsSeqKey | E1: UnitTestingSeqKey | F1: TestName | G1: TestValue | H1: Operation | I1: TestNameNumber | J1: TestNameWithoutNumeric | K1: PPVRun_MC
A2: 74TN777200064 | B2: J429E842 | C2: 202431 | D2: 13 | E2: 2 | F2: DPMB_SOCKET0__COMPUTE0__CPU__CORE8__ML2_CR_MC3_STATUS_8749 | G2: 0XB200000000400405 | H2: 8749 | I2: 0 | J2: DPMB_SOCKET0__COMPUTE0__CPU__CORE8__ML2_CR_MC3_STATUS_8749
A3: 74TN777200293 | B3: J431F837 | C3: 202433 | D3: 34 | E3: 3 | F3: DPMB_SOCKET0__COMPUTE1__CPU__CORE60__ML2_CR_MC3_STATUS_8749 | G3: 0XB200000000400405 | H3: 8749 | I3: 0 | J3: DPMB_SOCKET0__COMPUTE1__CPU__CORE60__ML2_CR_MC3_STATUS_8749
A4: 74UY667400068 | B4: J431F950 | C4: 202433 | D4: 81 | E4: 6 | F4: DPMB_SOCKET0__COMPUTE0__CPU__CORE0__ML2_CR_MC3_STATUS_8749 | G4: 0XE200000000400405 | H4: 8749 | I4: 0 | J4: DPMB_SOCKET0__COMPUTE0__CPU__CORE0__ML2_CR_MC3_STATUS_8749
A5: 74Y31V5300591 | B5: J432F360 | C5: 202433 | D5: 63 | E5: 6 | F5: DPMB_SOCKET0__COMPUTE1__CPU__CORE117__ML2_CR_MC3_STATUS_8749 | G5: 0XB200000000400405 | H5: 8749 | I5: 0 | J5: DPMB_SOCKET0__COMPUTE1__CPU__CORE117__ML2_CR_MC3_STATUS_8749
A6: 74BQ270100157 | B6: J429F054 | C6: 202432 | D6: 41 | E6: 15 | F6: DPMB_SOCKET0__COMPUTE2__CPU__CORE169__ML2_CR_MC3_STATUS_8749 | G6: 0XB200000000400405 | H6: 8749 | I6: 0 | J6: DPMB_SOCKET0__COMPUTE2__CPU__CORE169__ML2_CR_MC3_STATUS_8749

Sheet CORE
A1: VisualId | B1: Lot | C1: LatoStartWW | D1: LotsSeqKey | E1: UnitTestingSeqKey | F1: TestName | G1: TestValue | H1: Operation | I1: TestNameNumber | J1: TestNameWithoutNumeric | K1: PPVRun_MC
A2: 74TN777200064 | B2: J429E842 | C2: 202431 | D2: 13 | E2: 2 | F2: DPMB_SOCKET0__COMPUTE0__CPU__CORE8__ML2_CR_MC3_STATUS_8749 | G2: 0XB200000000400405 | H2: 8749 | I2: 0 | J2: DPMB_SOCKET0__COMPUTE0__CPU__CORE8__ML2_CR_MC3_STATUS_8749
A3: 74TN777200293 | B3: J431F837 | C3: 202433 | D3: 34 | E3: 3 | F3: DPMB_SOCKET0__COMPUTE1__CPU__CORE60__ML2_CR_MC3_STATUS_8749 | G3: 0XB200000000400405 | H3: 8749 | I3: 0 | J3: DPMB_SOCKET0__COMPUTE1__CPU__CORE60__ML2_CR_MC3_STATUS_8749
A4: 74UY667400068 | B4: J431F950 | C4: 202433 | D4: 81 | E4: 6 | F4: DPMB_SOCKET0__COMPUTE0__CPU__CORE0__ML2_CR_MC3_STATUS_8749 | G4: 0XE200000000400405 | H4: 8749 | I4: 0 | J4: DPMB_SOCKET0__COMPUTE0__CPU__CORE0__ML2_CR_MC3_STATUS_8749

Sheet PPV
B3: Final Bucket Data
B4: VisualId | C4: DpmBucket | D4: DecimaSite | E4: DecimaWW | F4: DecimaBucket | G4: DpmBucketAccuracy | H4: ProductConfigurationName | I4: BinDesc | J4: SubBucket | K4: Comments | L4: NextSteps
B5: 74TN777200064 | C5: UNCORE.LLC.DATA.PAR | E5: 202431 | G5: 40 | I5: LINUX_81_LINUX_OS_CONTENT_MLC_MP1_TIMEOUT, LINUX_81_TSL_HOT_NOMINAL_FREQUENCY_DEPTH_ROUND_ROBIN_SDETESTSEEDLOADER_3143_DQ20220X05RRC0_L_H_D_D_D, EFI_MARIONETTEWAITFOROS_WAITFOREFI_UNDEFINED_POWEROFF_HOT_COLD, LINUX_81_LINUX_OS_CONTENT_MLC_MP1_TIMEOUT, LINUX_81_LINUX_OS_CONTENT_MLC_MP1_TIMEOUT

Sheet MC_Check
B1: Bucket | C1: All | K1: Bin | L1: =_xlfn.XLOOKUP(H2,ppv[VisualId],ppv[BinDesc],"") -> LINUX_81_LINUX_OS_CONTENT_MLC_MP1_TIMEOUT, LINUX_81_TSL_HOT_NOMINAL_FREQUENCY_DEPTH_ROUND_ROBIN_SDETESTSEEDLOADER_3143_DQ20220X05RRC0_L_H_D_D_D, EFI_MARIONETTEWAITFOROS_WAITFOREFI_UNDEFINED_POWEROFF_HOT_COLD, LINUX_81_LINUX_OS_CONTENT_MLC_MP1_TIMEOUT, LINUX_81_LINUX_OS_CONTENT_MLC_MP1_TIMEOUT
B2: Units | C2: PPV | D2: Comments | E2: Next Steps | G2: Unit | H2: =B3 -> 74TN777200064 | X2: Data Format | AB2: DPMB | AD2: Show Top | AG2: 1
B3: {=IF(C1="All",_xlfn.UNIQUE(ppv[VisualId]),_xlfn._xlws.FILTER(ppv[VisualId],(ppv[SubBucket]=C1)*(IF(D1<>"",ISNUMBER(SEARCH(D1, ppv[Comments])),TRUE))))} -> 74TN777200064 | C3: =_xlfn.XLOOKUP(B3,ppv[VisualId],ppv[DpmBucket],"") -> UNCORE.LLC.DATA.PAR | G3: Accuracy | H3: =_xlfn.XLOOKUP(H2,ppv[VisualId],ppv[DpmBucketAccuracy],"") -> 40 | K3: CDIE | L3: R/C | M3: 0 | N3: 1 | O3: 2 | P3: 3 | Q3: 4 | R3: 5 | S3: 6 | T3: 7 | U3: 8 | V3: 9 | X3: Other | Z3: MEMORY | AC3: CORE | AG3: CHA | AJ3: LLC
C4: =_xlfn.XLOOKUP(B4,ppv[VisualId],ppv[DpmBucket],"") | G4: WW | H4: =_xlfn.XLOOKUP(H2,ppv[VisualId],ppv[DecimaWW],"") -> 202431 | K4: 0 | L4: 0 | M4: MDF | N4: MDF | O4: MDF | P4: MDF | Q4: MDF | R4: MDF | S4: MDF | T4: MDF | U4: MDF | V4: MDF | X4: Punit | Z4: MEM | AA4: Fail(s) | AC4: Top Failing Core(s) | AD4: Fail(s) | AE4: Type(s) | AG4: Top Failing CHA(s) | AH4: Fail(s) | AJ4: TopFailing LLC | AK4: Fail(s)
C5: =_xlfn.XLOOKUP(B5,ppv[VisualId],ppv[DpmBucket],"") | G5: Bucket | H5: =_xlfn.XLOOKUP(H2,ppv[VisualId],ppv[SubBucket]) -> 0 | L5: 1 | M5: 0 | N5: 2 | O5: =N5+7 -> 9 | P5: =O5+7 -> 16 | Q5: =P5+7 -> 23 | R5: =Q5+7 -> 30 | S5: =R5+7 -> 37 | T5: =S5+7 -> 44 | U5: =T5+7 -> 51 | V5: =U5+7 -> 58 | X5: {=IFERROR(_xlfn._xlws.FILTER(punitmcas[type],punitmcas[Counter]>0),"")} | Z5: {=IFERROR(_xlfn._xlws.FILTER(memss[Name],memss[MEMSS_Hitter_Count]>0),"")} | AA5: {=IFERROR(_xlfn._xlws.FILTER(memss[MEMSS_Hitter_Count],memss[MEMSS_Hitter_Count]>0),"")} | AC5: {=IFERROR("CORE"&_xlfn._xlws.FILTER(misc[location],misc[Core_Hitter_Count]>MAX(misc[Core_Hitter_Count]-AG2,0)),"")} -> CORE8 | AD5: {=IFERROR(_xlfn._xlws.FILTER(misc[Core_Hitter_Count],misc[Core_Hitter_Count]>MAX(misc[Core_Hitter_Count]-$AG$2,0)),"")} -> 1 | AE5: {=IFERROR(_xlfn._xlws.FILTER(misc[Core_FAILS],misc[Core_Hitter_Count]>MAX(misc[Core_Hitter_Count]-$AG$2,0)),"")} -> ML2 | AG5: {=IFERROR("CHA"&_xlfn._xlws.FILTER(misc[location],misc[CHA_Hitter_Count]>MAX(misc[CHA_Hitter_Count]-$AG$2,0)),"")} | AH5: {=IFERROR(_xlfn._xlws.FILTER(misc[CHA_Hitter_Count],misc[CHA_Hitter_Count]>MAX(misc[CHA_Hitter_Count]-$AG$2,0)),"")} | AJ5: {=IFERROR("LLC"&_xlfn._xlws.FILTER(misc[location],misc[LLC_Hitter_Count]>MAX(misc[LLC_Hitter_Count]-$AG$2,0)),"")} | AK5: {=IFERROR(_xlfn._xlws.FILTER(misc[LLC_Hitter_Count],misc[LLC_Hitter_Count]>MAX(misc[LLC_Hitter_Count]-$AG$2,0)),"")}
C6: =_xlfn.XLOOKUP(B6,ppv[VisualId],ppv[DpmBucket],"") | G6: =_xlfn.XLOOKUP(H2,ppv[VisualId],ppv[Comments]) -> 0 | L6: 2 | M6: =M5+1 -> 1 | N6: =N5+1 -> 3 | O6: =N6+7 -> 10 | P6: =O6+7 -> 17 | Q6: =P6+7 -> 24 | R6: =Q6+7 -> 31 | S6: =R6+7 -> 38 | T6: =S6+7 -> 45 | U6: =T6+7 -> 52 | V6: =U6+7 -> 59
C7: =_xlfn.XLOOKUP(B7,ppv[VisualId],ppv[DpmBucket],"") | G7: Postcodes | J7: FAILS | L7: 3 | M7: MC0 | N7: 4 | O7: =N7+7 -> 11 | P7: =O7+7 -> 18 | Q7: =P7+7 -> 25 | R7: =Q7+7 -> 32 | S7: =R7+7 -> 39 | T7: =S7+7 -> 46 | U7: =T7+7 -> 53 | V7: MC4
C8: =_xlfn.XLOOKUP(B8,ppv[VisualId],ppv[DpmBucket],"") | G8: {=_xlfn._xlws.FILTER(cha_mc[PPVRun_MC],((cha_mc[VisualId]=H2)*(ISNUMBER(SEARCH("BIOSNONSTICKYSCRATCHPAD",cha_mc[TestName])))),"")} | H8: {=_xlfn._xlws.FILTER(cha_mc[TestValue],((cha_mc[VisualId]=H2)*(ISNUMBER(SEARCH("BIOSNONSTICKYSCRATCHPAD",cha_mc[TestName])))),"")} | J8: LLC | L8: 4 | M8: MC1 | N8: 5 | O8: =N8+7 -> 12 | P8: =O8+7 -> 19 | Q8: =P8+7 -> 26 | R8: =Q8+7 -> 33 | S8: =R8+7 -> 40 | T8: =S8+7 -> 47 | U8: =T8+7 -> 54 | V8: MC5
C9: =_xlfn.XLOOKUP(B9,ppv[VisualId],ppv[DpmBucket],"") | J9: CORE | L9: 5 | M9: CH8 | N9: 6 | O9: =N9+7 -> 13 | P9: =O9+7 -> 20 | Q9: =P9+7 -> 27 | R9: =Q9+7 -> 34 | S9: =R9+7 -> 41 | T9: =S9+7 -> 48 | U9: =T9+7 -> 55 | V9: CH2
C10: =_xlfn.XLOOKUP(B10,ppv[VisualId],ppv[DpmBucket],"") | J10: CHA | L10: 6 | M10: CH9 | N10: 7 | O10: =N10+7 -> 14 | P10: =O10+7 -> 21 | Q10: =P10+7 -> 28 | R10: =Q10+7 -> 35 | S10: =R10+7 -> 42 | T10: =S10+7 -> 49 | U10: =T10+7 -> 56 | V10: CH3
C11: =_xlfn.XLOOKUP(B11,ppv[VisualId],ppv[DpmBucket],"") | J11: MEM | L11: 7 | M11: SPK | N11: 8 | O11: =N11+7 -> 15 | P11: =O11+7 -> 22 | Q11: =P11+7 -> 29 | R11: =Q11+7 -> 36 | S11: =R11+7 -> 43 | T11: =S11+7 -> 50 | U11: =T11+7 -> 57 | V11: SPK | X11: S3M
C12: =_xlfn.XLOOKUP(B12,ppv[VisualId],ppv[DpmBucket],"") | L12: 8 | M12: MDF | N12: MDF | O12: MDF | P12: MDF | Q12: MDF | R12: MDF | S12: MDF | T12: MDF | U12: MDF | V12: MDF | X12: {=IFERROR(_xlfn._xlws.FILTER(s3errors[type],s3errors[Counter]>0),"")}
C13: =_xlfn.XLOOKUP(B13,ppv[VisualId],ppv[DpmBucket],"")
C14: =_xlfn.XLOOKUP(B14,ppv[VisualId],ppv[DpmBucket],"") | K14: CDIE | L14: R/C | M14: 0 | N14: 1 | O14: 2 | P14: 3 | Q14: 4 | R14: 5 | S14: 6 | T14: 7 | U14: 8 | V14: 9
C15: =_xlfn.XLOOKUP(B15,ppv[VisualId],ppv[DpmBucket],"") | K15: 1 | L15: 0 | M15: MDF | N15: MDF | O15: MDF | P15: MDF | Q15: MDF | R15: MDF | S15: MDF | T15: MDF | U15: MDF | V15: MDF
C16: =_xlfn.XLOOKUP(B16,ppv[VisualId],ppv[DpmBucket],"") | L16: 1 | M16: =M5+60 -> 60 | N16: =N5+60 -> 62 | O16: =O5+60 -> 69 | P16: =P5+60 -> 76 | Q16: =Q5+60 -> 83 | R16: =R5+60 -> 90 | S16: =S5+60 -> 97 | T16: =T5+60 -> 104 | ... V16: =V5+60 -> 118
C17: =_xlfn.XLOOKUP(B17,ppv[VisualId],ppv[DpmBucket],"") | L17: 2 | M17: =M6+60 -> 61 | N17: =N6+60 -> 63 | O17: =O6+60 -> 70 | P17: =P6+60 -> 77 | Q17: =Q6+60 -> 84 | R17: =R6+60 -> 91 | S17: =S6+60 -> 98 | T17: =T6+60 -> 105 | ... V17: =V6+60 -> 119
C18: =_xlfn.XLOOKUP(B18,ppv[VisualId],ppv[DpmBucket],"") | J18: FAILS | L18: 3 | M18: MC0 | N18: =N7+60 -> 64 | O18: =O7+60 -> 71 | P18: =P7+60 -> 78 | Q18: =Q7+60 -> 85 | R18: =R7+60 -> 92 | S18: =S7+60 -> 99 | T18: =T7+60 -> 106 | U18: =T18+7 -> 113 | V18: MC4
C19: =_xlfn.XLOOKUP(B19,ppv[VisualId],ppv[DpmBucket],"") | J19: LLC | L19: 4 | M19: MC1 | N19: =N8+60 -> 65 | O19: =O8+60 -> 72 | P19: =P8+60 -> 79 | Q19: =Q8+60 -> 86 | R19: =R8+60 -> 93 | S19: =S8+60 -> 100 | T19: =T8+60 -> 107 | U19: =T19+7 -> 114 | V19: MC5
C20: =_xlfn.XLOOKUP(B20,ppv[VisualId],ppv[DpmBucket],"") | J20: CORE | L20: 5 | M20: CH6 | N20: =N9+60 -> 66 | O20: =O9+60 -> 73 | P20: =P9+60 -> 80 | Q20: =Q9+60 -> 87 | R20: =R9+60 -> 94 | S20: =S9+60 -> 101 | T20: =T9+60 -> 108 | U20: =T20+7 -> 115 | V20: CH0
C21: =_xlfn.XLOOKUP(B21,ppv[VisualId],ppv[DpmBucket],"") | J21: CHA | L21: 6 | M21: CH7 | N21: =N10+60 -> 67 | O21: =O10+60 -> 74 | P21: =P10+60 -> 81 | Q21: =Q10+60 -> 88 | R21: =R10+60 -> 95 | S21: =S10+60 -> 102 | T21: =T10+60 -> 109 | U21: =T21+7 -> 116 | V21: CH1
C22: =_xlfn.XLOOKUP(B22,ppv[VisualId],ppv[DpmBucket],"") | J22: MEM | L22: 7 | M22: SPK | N22: =N11+60 -> 68 | O22: =O11+60 -> 75 | P22: =P11+60 -> 82 | Q22: =Q11+60 -> 89 | R22: =R11+60 -> 96 | S22: =S11+60 -> 103 | T22: =T11+60 -> 110 | U22: =T22+7 -> 117 | V22: SPK
C23: =_xlfn.XLOOKUP(B23,ppv[VisualId],ppv[DpmBucket],"") | L23: 8 | M23: MDF | N23: MDF | O23: MDF | P23: MDF | Q23: MDF | R23: MDF | S23: MDF | T23: MDF | U23: MDF | V23: MDF
C24: =_xlfn.XLOOKUP(B24,ppv[VisualId],ppv[DpmBucket],"")
C25: =_xlfn.XLOOKUP(B25,ppv[VisualId],ppv[DpmBucket],"") | K25: CDIE | L25: R/C | M25: 0 | N25: 1 | O25: 2 | P25: 3 | Q25: 4 | R25: 5 | S25: 6 | T25: 7 | U25: 8 | V25: 9
C26: =_xlfn.XLOOKUP(B26,ppv[VisualId],ppv[DpmBucket],"") | K26: 2 | L26: 0 | M26: MDF | N26: MDF | O26: MDF | P26: MDF | Q26: MDF | R26: MDF | S26: MDF | T26: MDF | U26: MDF | V26: MDF
C27: =_xlfn.XLOOKUP(B27,ppv[VisualId],ppv[DpmBucket],"") | L27: 1 | M27: =M16+60 -> 120 | N27: =N16+60 -> 122 | O27: =O16+60 -> 129 | P27: =P16+60 -> 136 | Q27: =Q16+60 -> 143 | R27: =R16+60 -> 150 | S27: =S16+60 -> 157 | T27: =T16+60 -> 164 | ... V27: =V16+60 -> 178
C28: =_xlfn.XLOOKUP(B28,ppv[VisualId],ppv[DpmBucket],"") | L28: 2 | M28: =M17+60 -> 121 | N28: =N17+60 -> 123 | O28: =O17+60 -> 130 | P28: =P17+60 -> 137 | Q28: =Q17+60 -> 144 | R28: =R17+60 -> 151 | S28: =S17+60 -> 158 | T28: =T17+60 -> 165 | ... V28: =V17+60 -> 179
C29: =_xlfn.XLOOKUP(B29,ppv[VisualId],ppv[DpmBucket],"") | J29: FAILS | L29: 3 | M29: MC0 | N29: =N18+60 -> 124 | O29: =O18+60 -> 131 | P29: =P18+60 -> 138 | Q29: =Q18+60 -> 145 | R29: =R18+60 -> 152 | S29: =S18+60 -> 159 | T29: =T18+60 -> 166 | U29: =U18+60 -> 173 | V29: MC4
C30: =_xlfn.XLOOKUP(B30,ppv[VisualId],ppv[DpmBucket],"") | J30: LLC | L30: 4 | M30: MC1 | N30: =N19+60 -> 125 | O30: =O19+60 -> 132 | P30: =P19+60 -> 139 | Q30: =Q19+60 -> 146 | R30: =R19+60 -> 153 | S30: =S19+60 -> 160 | T30: =T19+60 -> 167 | U30: =U19+60 -> 174 | V30: MC5
C31: =_xlfn.XLOOKUP(B31,ppv[VisualId],ppv[DpmBucket],"") | J31: CORE | L31: 5 | M31: CH10 | N31: =N20+60 -> 126 | O31: =O20+60 -> 133 | P31: =P20+60 -> 140 | Q31: =Q20+60 -> 147 | R31: =R20+60 -> 154 | S31: =S20+60 -> 161 | T31: =T20+60 -> 168 | U31: =U20+60 -> 175 | V31: CH4
C32: =_xlfn.XLOOKUP(B32,ppv[VisualId],ppv[DpmBucket],"") | J32: CHA | L32: 6 | M32: CH11 | N32: =N21+60 -> 127 | O32: =O21+60 -> 134 | P32: =P21+60 -> 141 | Q32: =Q21+60 -> 148 | R32: =R21+60 -> 155 | S32: =S21+60 -> 162 | T32: =T21+60 -> 169 | U32: =U21+60 -> 176 | V32: CH5
C33: =_xlfn.XLOOKUP(B33,ppv[VisualId],ppv[DpmBucket],"") | J33: MEM | L33: 7 | M33: SPK | N33: =N22+60 -> 128 | O33: =O22+60 -> 135 | P33: =P22+60 -> 142 | Q33: =Q22+60 -> 149 | R33: =R22+60 -> 156 | S33: =S22+60 -> 163 | T33: =T22+60 -> 170 | U33: =U22+60 -> 177 | V33: SPK
C34: =_xlfn.XLOOKUP(B34,ppv[VisualId],ppv[DpmBucket],"") | L34: 8 | M34: MDF | N34: MDF | O34: MDF | P34: MDF | Q34: MDF | R34: MDF | S34: MDF | T34: MDF | U34: MDF | V34: MDF
C35: =_xlfn.XLOOKUP(B35,ppv[VisualId],ppv[DpmBucket],"")
C36: =_xlfn.XLOOKUP(B36,ppv[VisualId],ppv[DpmBucket],"")
C37: =_xlfn.XLOOKUP(B37,ppv[VisualId],ppv[DpmBucket],"")

Sheet ErrorData
A1: This Sheet is for miscelanous calculations, avoid modifying it unless necessary as it might end up giving wrong data analysis if not managed carefully. | F1: char | G1: =IF(MC_Check!AB2="DPMB","__",".") -> __ | AJ1: S3M | AN1: PUNIT
A2: Failing_LLC | B2: Failing_CHA | C2: Failing_Core | D2: Formats | F2: Compute | G2: location | H2: corefail | I2: llcfail | J2: chafail | K2: CHA_MCA_String | L2: CHA_Hitter_Count | M2: DCU_MCA_String | N2: Core_DCU_Count | O2: DTLB_MCA_String | P2: Core_DTLB_Count | Q2: IFU_MCA_String | R2: Core_IFU_Count | S2: CORE_MCA_String | T2: Core_ML2_Count | U2: Core_Hitter_Count | V2: Core_FAILS | W2: LLC_MCA_String | X2: LLC_Hitter_Count | AA2: Compute | AB2: location | AC2: Name | AD2: fail | AE2: MEMMS_MCA_String | AF2: MEMSS_Hitter_Count | AJ2: type | AK2: MCA_String | AL2: Counter | AN2: type | AO2: MCA_String | AP2: Counter
A3: {=IFERROR(SUBSTITUTE(_xlfn._xlws.FILTER(_xlfn.UNIQUE(cha_mc[VisualId]&cha_mc[TestName]),ISNUMBER(SEARCH(MC_Check!H2 & "*LLC*__MCI_STATUS*", _xlfn.UNIQUE(cha_mc[VisualId]&cha_mc[TestName])))),MC_Check!H2,""),"No LLC Data Found")} -> No LLC Data Found | B3: {=IFERROR(SUBSTITUTE(_xlfn._xlws.FILTER(_xlfn.UNIQUE(cha_mc[VisualId]&cha_mc[TestName]),ISNUMBER(SEARCH(MC_Check!H2 & "*CHA*UTIL__MC_STATUS*", _xlfn.UNIQUE(cha_mc[VisualId]&cha_mc[TestName])))),MC_Check!H2,""), "No CHA Data Found")} -> No CHA Data Found | C3: {=IFERROR(SUBSTITUTE(_xlfn._xlws.FILTER(_xlfn.UNIQUE(core_mc[VisualId]&core_mc[TestName]),ISNUMBER(SEARCH(MC_Check!H2 & "*CPU*CR_MC3_STATUS*", _xlfn.UNIQUE(core_mc[VisualId]&core_mc[TestName])))),MC_Check!H2,""), "No CORE Data Found")} -> DPMB_SOCKET0__COMPUTE0__CPU__CORE8__ML2_CR_MC3_STATUS_8749 | D3: DPMB | F3: 0 | G3: 0 | H3: =misc[[#This Row],[Core_Hitter_Count]]>0 -> FALSE | I3: =misc[[#This Row],[LLC_Hitter_Count]]>0 -> FALSE | J3: =misc[[#This Row],[CHA_Hitter_Count]]>0 -> FALSE | K3: =_xlfn.TEXTJOIN("",,"*SOCKET0**COMPUTE",misc[[#This Row],[Compute]],"**UNCORE**CHA**CHA",misc[[#This Row],[location]],splitchar,"UTIL**MC*STATUS*") -> *SOCKET0**COMPUTE0**UNCORE**CHA**CHA0__UTIL**MC*STATUS* | L3: =COUNTIFS(cha_mc[TestName],misc[[#This Row],[CHA_MCA_String]],cha_mc[VisualId],MC_Check!$H$2) -> 0 | M3: =_xlfn.TEXTJOIN("",,"*SOCKET0**COMPUTE",misc[[#This Row],[Compute]],"**CPU**CORE",misc[[#This Row],[location]],splitchar,"THREAD"&"*",splitchar,"DCU*CR*MC1*STATUS**") -> *SOCKET0**COMPUTE0**CPU**CORE0__THREAD*__DCU*CR*MC1*STATUS** | N3: =COUNTIFS(core_mc[TestName],misc[[#This Row],[DCU_MCA_String]],core_mc[VisualId],MC_Check!$H$2) -> 0 | O3: =_xlfn.TEXTJOIN("",,"*SOCKET0**COMPUTE",misc[[#This Row],[Compute]],"**CPU**CORE",misc[[#This Row],[location]],splitchar,"DTLB*CR*MC2*STATUS**") -> *SOCKET0**COMPUTE0**CPU**CORE0__DTLB*CR*MC2*STATUS** | P3: =COUNTIFS(core_mc[TestName],misc[[#This Row],[DTLB_MCA_String]],core_mc[VisualId],MC_Check!$H$2) -> 0 | Q3: =_xlfn.TEXTJOIN("",,"*SOCKET0**COMPUTE",misc[[#This Row],[Compute]],"**CPU**CORE",misc[[#This Row],[location]],splitchar,"THREAD"&"*",splitchar,"IFU*CR*MC0*STATUS**") -> *SOCKET0**COMPUTE0**CPU**CORE0__THREAD*__IFU*CR*MC0*STATUS** | R3: =COUNTIFS(core_mc[TestName],misc[[#This Row],[IFU_MCA_String]],core_mc[VisualId],MC_Check!$H$2) -> 0 | S3: =_xlfn.TEXTJOIN("",,"*SOCKET0**COMPUTE",misc[[#This Row],[Compute]],"**CPU**CORE",misc[[#This Row],[location]],splitchar,"ML2*CR*MC3*STATUS*") -> *SOCKET0**COMPUTE0**CPU**CORE0__ML2*CR*MC3*STATUS* | T3: =COUNTIFS(core_mc[TestName],misc[[#This Row],[CORE_MCA_String]],core_mc[VisualId],MC_Check!$H$2) -> 0 | U3: =misc[[#This Row],[Core_ML2_Count]]+misc[[#This Row],[Core_IFU_Count]]+misc[[#This Row],[Core_DCU_Count]]+misc[[#This Row],[Core_DTLB_Count]] -> 0 | V3: =_xlfn.TEXTJOIN(", ",,IF(misc[[#This Row],[Core_DCU_Count]]>0,"DCU",""),IF(misc[[#This Row],[Core_IFU_Count]]>0,"IFU",""),IF(misc[[#This Row],[Core_ML2_Count]]>0,"ML2",""),IF(misc[[#This Row],[Core_DTLB_Count]]>0,"DTLB","")) | W3: =_xlfn.TEXTJOIN("",,"*SOCKET0**COMPUTE",misc[[#This Row],[Compute]],"**UNCORE**SCF**SCF*LLC**SCF*LLC",misc[[#This Row],[location]],splitchar,"MCI*STATUS*") -> *SOCKET0**COMPUTE0**UNCORE**SCF**SCF*LLC**SCF*LLC0__MCI*STATUS* | X3: =COUNTIFS(cha_mc[TestName],misc[[#This Row],[LLC_MCA_String]],cha_mc[VisualId],MC_Check!$H$2) -> 0 | AA3: 1 | AB3: 0 | AC3: ="CH"&memss[[#This Row],[location]] -> CH0 | AD3: =memss[[#This Row],[MEMSS_Hitter_Count]]>0 -> FALSE | AE3: =_xlfn.TEXTJOIN("",,"*SOCKET0**SOC**MEMSS**B2CMI",memss[[#This Row],[location]],splitchar,"MCI*STATUS*SHADOW*") -> *SOCKET0**SOC**MEMSS**B2CMI0__MCI*STATUS*SHADOW* | AF3: =COUNTIFS(cha_mc[TestName],memss[[#This Row],[MEMMS_MCA_String]],cha_mc[VisualId],MC_Check!$H$2) -> 0 | AJ3: io0 | AK3: ="*SOCKET0**IO0**TAPS**IOW*GLBW*IS3M*IBL*TOP110"&splitchar&"TAP*S3M*ERR*STS*" -> *SOCKET0**IO0**TAPS**IOW*GLBW*IS3M*IBL*TOP110__TAP*S3M*ERR*STS* | AL3: =COUNTIFS(cha_mc[TestName],s3errors[[#This Row],[MCA_String]],cha_mc[VisualId],MC_Check!$H$2) -> 0 | AN3: io0 | AO3: ="*SOCKET0**IO0**UNCORE**PUNIT**PTPCFSMS**PTPCFSMS"&splitchar&"MC*STATUS*" -> *SOCKET0**IO0**UNCORE**PUNIT**PTPCFSMS**PTPCFSMS__MC*STATUS* | AP3: =COUNTIFS(cha_mc[TestName],punitmcas[[#This Row],[MCA_String]],cha_mc[VisualId],MC_Check!$H$2) -> 0
D4: REGISTERS | F4: 0 | G4: 1 | H4: =misc[[#This Row],[Core_Hitter_Count]]>0 -> FALSE | I4: =misc[[#This Row],[LLC_Hitter_Count]]>0 -> FALSE | J4: =misc[[#This Row],[CHA_Hitter_Count]]>0 -> FALSE | K4: =_xlfn.TEXTJOIN("",,"*SOCKET0**COMPUTE",misc[[#This Row],[Compute]],"**UNCORE**CHA**CHA",misc[[#This Row],[location]],splitchar,"UTIL**MC*STATUS*") -> *SOCKET0**COMPUTE0**UNCORE**CHA**CHA1__UTIL**MC*STATUS* | L4: =COUNTIFS(cha_mc[TestName],misc[[#This Row],[CHA_MCA_String]],cha_mc[VisualId],MC_Check!$H$2) -> 0 | M4: =_xlfn.TEXTJOIN("",,"*SOCKET0**COMPUTE",misc[[#This Row],[Compute]],"**CPU**CORE",misc[[#This Row],[location]],splitchar,"THREAD"&"*",splitchar,"DCU*CR*MC1*STATUS**") -> *SOCKET0**COMPUTE0**CPU**CORE1__THREAD*__DCU*CR*MC1*STATUS** | N4: =COUNTIFS(core_mc[TestName],misc[[#This Row],[DCU_MCA_String]],core_mc[VisualId],MC_Check!$H$2) -> 0 | O4: =_xlfn.TEXTJOIN("",,"*SOCKET0**COMPUTE",misc[[#This Row],[Compute]],"**CPU**CORE",misc[[#This Row],[location]],splitchar,"DTLB*CR*MC2*STATUS**") -> *SOCKET0**COMPUTE0**CPU**CORE1__DTLB*CR*MC2*STATUS** | P4: =COUNTIFS(core_mc[TestName],misc[[#This Row],[DTLB_MCA_String]],core_mc[VisualId],MC_Check!$H$2) -> 0 | Q4: =_xlfn.TEXTJOIN("",,"*SOCKET0**COMPUTE",misc[[#This Row],[Compute]],"**CPU**CORE",misc[[#This Row],[location]],splitchar,"THREAD"&"*",splitchar,"IFU*CR*MC0*STATUS**") -> *SOCKET0**COMPUTE0**CPU**CORE1__THREAD*__IFU*CR*MC0*STATUS** | R4: =COUNTIFS(core_mc[TestName],misc[[#This Row],[IFU_MCA_String]],core_mc[VisualId],MC_Check!$H$2) -> 0 | S4: =_xlfn.TEXTJOIN("",,"*SOCKET0**COMPUTE",misc[[#This Row],[Compute]],"**CPU**CORE",misc[[#This Row],[location]],splitchar,"ML2*CR*MC3*STATUS*") -> *SOCKET0**COMPUTE0**CPU**CORE1__ML2*CR*MC3*STATUS* | T4: =COUNTIFS(core_mc[TestName],misc[[#This Row],[CORE_MCA_String]],core_mc[VisualId],MC_Check!$H$2) -> 0 | U4: =misc[[#This Row],[Core_ML2_Count]]+misc[[#This Row],[Core_IFU_Count]]+misc[[#This Row],[Core_DCU_Count]]+misc[[#This Row],[Core_DTLB_Count]] -> 0 | V4: =_xlfn.TEXTJOIN(", ",,IF(misc[[#This Row],[Core_DCU_Count]]>0,"DCU",""),IF(misc[[#This Row],[Core_IFU_Count]]>0,"IFU",""),IF(misc[[#This Row],[Core_ML2_Count]]>0,"ML2",""),IF(misc[[#This Row],[Core_DTLB_Count]]>0,"DTLB","")) | W4: =_xlfn.TEXTJOIN("",,"*SOCKET0**COMPUTE",misc[[#This Row],[Compute]],"**UNCORE**SCF**SCF*LLC**SCF*LLC",misc[[#This Row],[location]],splitchar,"MCI*STATUS*") -> *SOCKET0**COMPUTE0**UNCORE**SCF**SCF*LLC**SCF*LLC1__MCI*STATUS* | X4: =COUNTIFS(cha_mc[TestName],misc[[#This Row],[LLC_MCA_String]],cha_mc[VisualId],MC_Check!$H$2) -> 0 | AA4: 1 | AB4: 1 | AC4: ="CH"&memss[[#This Row],[location]] -> CH1 | AD4: =memss[[#This Row],[MEMSS_Hitter_Count]]>0 -> FALSE | AE4: =_xlfn.TEXTJOIN("",,"*SOCKET0**SOC**MEMSS**B2CMI",memss[[#This Row],[location]],splitchar,"MCI*STATUS*SHADOW*") -> *SOCKET0**SOC**MEMSS**B2CMI1__MCI*STATUS*SHADOW* | AF4: =COUNTIFS(cha_mc[TestName],memss[[#This Row],[MEMMS_MCA_String]],cha_mc[VisualId],MC_Check!$H$2) -> 0 | AJ4: io1 | AK4: ="*SOCKET0**IO1**TAPS**IOW*GLBW*IS3M*IBL*TOP110"&splitchar&"TAP*S3M*ERR*STS**" -> *SOCKET0**IO1**TAPS**IOW*GLBW*IS3M*IBL*TOP110__TAP*S3M*ERR*STS** | AL4: =COUNTIFS(cha_mc[TestName],s3errors[[#This Row],[MCA_String]],cha_mc[VisualId],MC_Check!$H$2) -> 0 | AN4: io1 | AO4: ="*SOCKET0**IO1**UNCORE**PUNIT**PTPCFSMS**PTPCFSMS"&splitchar&"MC*STATUS*" -> *SOCKET0**IO1**UNCORE**PUNIT**PTPCFSMS**PTPCFSMS__MC*STATUS* | AP4: =COUNTIFS(cha_mc[TestName],punitmcas[[#This Row],[MCA_String]],cha_mc[VisualId],MC_Check!$H$2) -> 0
F5: 0 | G5: 2 | H5: =misc[[#This Row],[Core_Hitter_Count]]>0 -> FALSE | I5: =misc[[#This Row],[LLC_Hitter_Count]]>0 -> FALSE | J5: =misc[[#This Row],[CHA_Hitter_Count]]>0 -> FALSE | K5: =_xlfn.TEXTJOIN("",,"*SOCKET0**COMPUTE",misc[[#This Row],[Compute]],"**UNCORE**CHA**CHA",misc[[#This Row],[location]],splitchar,"UTIL**MC*STATUS*") -> *SOCKET0**COMPUTE0**UNCORE**CHA**CHA2__UTIL**MC*STATUS* | L5: =COUNTIFS(cha_mc[TestName],misc[[#This Row],[CHA_MCA_String]],cha_mc[VisualId],MC_Check!$H$2) -> 0 | M5: =_xlfn.TEXTJOIN("",,"*SOCKET0**COMPUTE",misc[[#This Row],[Compute]],"**CPU**CORE",misc[[#This Row],[location]],splitchar,"THREAD"&"*",splitchar,"DCU*CR*MC1*STATUS**") -> *SOCKET0**COMPUTE0**CPU**CORE2__THREAD*__DCU*CR*MC1*STATUS** | N5: =COUNTIFS(core_mc[TestName],misc[[#This Row],[DCU_MCA_String]],core_mc[VisualId],MC_Check!$H$2) -> 0 | O5: =_xlfn.TEXTJOIN("",,"*SOCKET0**COMPUTE",misc[[#This Row],[Compute]],"**CPU**CORE",misc[[#This Row],[location]],splitchar,"DTLB*CR*MC2*STATUS**") -> *SOCKET0**COMPUTE0**CPU**CORE2__DTLB*CR*MC2*STATUS** | P5: =COUNTIFS(core_mc[TestName],misc[[#This Row],[DTLB_MCA_String]],core_mc[VisualId],MC_Check!$H$2) -> 0 | Q5: =_xlfn.TEXTJOIN("",,"*SOCKET0**COMPUTE",misc[[#This Row],[Compute]],"**CPU**CORE",misc[[#This Row],[location]],splitchar,"THREAD"&"*",splitchar,"IFU*CR*MC0*STATUS**") -> *SOCKET0**COMPUTE0**CPU**CORE2__THREAD*__IFU*CR*MC0*STATUS** | R5: =COUNTIFS(core_mc[TestName],misc[[#This Row],[IFU_MCA_String]],core_mc[VisualId],MC_Check!$H$2) -> 0 | S5: =_xlfn.TEXTJOIN("",,"*SOCKET0**COMPUTE",misc[[#This Row],[Compute]],"**CPU**CORE",misc[[#This Row],[location]],splitchar,"ML2*CR*MC3*STATUS*") -> *SOCKET0**COMPUTE0**CPU**CORE2__ML2*CR*MC3*STATUS* | T5: =COUNTIFS(core_mc[TestName],misc[[#This Row],[CORE_MCA_String]],core_mc[VisualId],MC_Check!$H$2) -> 0 | U5: =misc[[#This Row],[Core_ML2_Count]]+misc[[#This Row],[Core_IFU_Count]]+misc[[#This Row],[Core_DCU_Count]]+misc[[#This Row],[Core_DTLB_Count]] -> 0 | V5: =_xlfn.TEXTJOIN(", ",,IF(misc[[#This Row],[Core_DCU_Count]]>0,"DCU",""),IF(misc[[#This Row],[Core_IFU_Count]]>0,"IFU",""),IF(misc[[#This Row],[Core_ML2_Count]]>0,"ML2",""),IF(misc[[#This Row],[Core_DTLB_Count]]>0,"DTLB","")) | W5: =_xlfn.TEXTJOIN("",,"*SOCKET0**COMPUTE",misc[[#This Row],[Compute]],"**UNCORE**SCF**SCF*LLC**SCF*LLC",misc[[#This Row],[location]],splitchar,"MCI*STATUS*") -> *SOCKET0**COMPUTE0**UNCORE**SCF**SCF*LLC**SCF*LLC2__MCI*STATUS* | X5: =COUNTIFS(cha_mc[TestName],misc[[#This Row],[LLC_MCA_String]],cha_mc[VisualId],MC_Check!$H$2) -> 0 | AA5: 0 | AB5: 2 | AC5: ="CH"&memss[[#This Row],[location]] -> CH2 | AD5: =memss[[#This Row],[MEMSS_Hitter_Count]]>0 -> FALSE | AE5: =_xlfn.TEXTJOIN("",,"*SOCKET0**SOC**MEMSS**B2CMI",memss[[#This Row],[location]],splitchar,"MCI*STATUS*SHADOW*") -> *SOCKET0**SOC**MEMSS**B2CMI2__MCI*STATUS*SHADOW* | AF5: =COUNTIFS(cha_mc[TestName],memss[[#This Row],[MEMMS_MCA_String]],cha_mc[VisualId],MC_Check!$H$2) -> 0 | AJ5: cdie0 | AK5: ="*SOCKET0**COMPUTE0**TAPS**IOW*GLBW*IS3M*IBL*TOP110"&splitchar&"TAP*S3M*ERR*STS**" -> *SOCKET0**COMPUTE0**TAPS**IOW*GLBW*IS3M*IBL*TOP110__TAP*S3M*ERR*STS** | AL5: =COUNTIFS(cha_mc[TestName],s3errors[[#This Row],[MCA_String]],cha_mc[VisualId],MC_Check!$H$2) -> 0 | AN5: cdie0 | AO5: ="*SOCKET0**COMPUTE0**UNCORE**PUNIT**PTPCFSMS**PTPCFSMS"&splitchar&"MC*STATUS*" -> *SOCKET0**COMPUTE0**UNCORE**PUNIT**PTPCFSMS**PTPCFSMS__MC*STATUS* | AP5: =COUNTIFS(cha_mc[TestName],punitmcas[[#This Row],[MCA_String]],cha_mc[VisualId],MC_Check!$H$2) -> 0
F6: 0 | G6: 3 | H6: =misc[[#This Row],[Core_Hitter_Count]]>0 -> FALSE | I6: =misc[[#This Row],[LLC_Hitter_Count]]>0 -> FALSE | J6: =misc[[#This Row],[CHA_Hitter_Count]]>0 -> FALSE | K6: =_xlfn.TEXTJOIN("",,"*SOCKET0**COMPUTE",misc[[#This Row],[Compute]],"**UNCORE**CHA**CHA",misc[[#This Row],[location]],splitchar,"UTIL**MC*STATUS*") -> *SOCKET0**COMPUTE0**UNCORE**CHA**CHA3__UTIL**MC*STATUS* | L6: =COUNTIFS(cha_mc[TestName],misc[[#This Row],[CHA_MCA_String]],cha_mc[VisualId],MC_Check!$H$2) -> 0 | M6: =_xlfn.TEXTJOIN("",,"*SOCKET0**COMPUTE",misc[[#This Row],[Compute]],"**CPU**CORE",misc[[#This Row],[location]],splitchar,"THREAD"&"*",splitchar,"DCU*CR*MC1*STATUS**") -> *SOCKET0**COMPUTE0**CPU**CORE3__THREAD*__DCU*CR*MC1*STATUS** | N6: =COUNTIFS(core_mc[TestName],misc[[#This Row],[DCU_MCA_String]],core_mc[VisualId],MC_Check!$H$2) -> 0 | O6: =_xlfn.TEXTJOIN("",,"*SOCKET0**COMPUTE",misc[[#This Row],[Compute]],"**CPU**CORE",misc[[#This Row],[location]],splitchar,"DTLB*CR*MC2*STATUS**") -> *SOCKET0**COMPUTE0**CPU**CORE3__DTLB*CR*MC2*STATUS** | P6: =COUNTIFS(core_mc[TestName],misc[[#This Row],[DTLB_MCA_String]],core_mc[VisualId],MC_Check!$H$2) -> 0 | Q6: =_xlfn.TEXTJOIN("",,"*SOCKET0**COMPUTE",misc[[#This Row],[Compute]],"**CPU**CORE",misc[[#This Row],[location]],splitchar,"THREAD"&"*",splitchar,"IFU*CR*MC0*STATUS**") -> *SOCKET0**COMPUTE0**CPU**CORE3__THREAD*__IFU*CR*MC0*STATUS** | R6: =COUNTIFS(core_mc[TestName],misc[[#This Row],[IFU_MCA_String]],core_mc[VisualId],MC_Check!$H$2) -> 0 | S6: =_xlfn.TEXTJOIN("",,"*SOCKET0**COMPUTE",misc[[#This Row],[Compute]],"**CPU**CORE",misc[[#This Row],[location]],splitchar,"ML2*CR*MC3*STATUS*") -> *SOCKET0**COMPUTE0**CPU**CORE3__ML2*CR*MC3*STATUS* | T6: =COUNTIFS(core_mc[TestName],misc[[#This Row],[CORE_MCA_String]],core_mc[VisualId],MC_Check!$H$2) -> 0 | U6: =misc[[#This Row],[Core_ML2_Count]]+misc[[#This Row],[Core_IFU_Count]]+misc[[#This Row],[Core_DCU_Count]]+misc[[#This Row],[Core_DTLB_Count]] -> 0 | V6: =_xlfn.TEXTJOIN(", ",,IF(misc[[#This Row],[Core_DCU_Count]]>0,"DCU",""),IF(misc[[#This Row],[Core_IFU_Count]]>0,"IFU",""),IF(misc[[#This Row],[Core_ML2_Count]]>0,"ML2",""),IF(misc[[#This Row],[Core_DTLB_Count]]>0,"DTLB","")) | W6: =_xlfn.TEXTJOIN("",,"*SOCKET0**COMPUTE",misc[[#This Row],[Compute]],"**UNCORE**SCF**SCF*LLC**SCF*LLC",misc[[#This Row],[location]],splitchar,"MCI*STATUS*") -> *SOCKET0**COMPUTE0**UNCORE**SCF**SCF*LLC**SCF*LLC3__MCI*STATUS* | X6: =COUNTIFS(cha_mc[TestName],misc[[#This Row],[LLC_MCA_String]],cha_mc[VisualId],MC_Check!$H$2) -> 0 | AA6: 0 | AB6: 3 | AC6: ="CH"&memss[[#This Row],[location]] -> CH3 | AD6: =memss[[#This Row],[MEMSS_Hitter_Count]]>0 -> FALSE | AE6: =_xlfn.TEXTJOIN("",,"*SOCKET0**SOC**MEMSS**B2CMI",memss[[#This Row],[location]],splitchar,"MCI*STATUS*SHADOW*") -> *SOCKET0**SOC**MEMSS**B2CMI3__MCI*STATUS*SHADOW* | AF6: =COUNTIFS(cha_mc[TestName],memss[[#This Row],[MEMMS_MCA_String]],cha_mc[VisualId],MC_Check!$H$2) -> 0 | AJ6: cdie1 | AK6: ="*SOCKET0**COMPUTE1**TAPS**IOW*GLBW*IS3M*IBL*TOP110"&splitchar&"TAP*S3M*ERR*STS**" -> *SOCKET0**COMPUTE1**TAPS**IOW*GLBW*IS3M*IBL*TOP110__TAP*S3M*ERR*STS** | AL6: =COUNTIFS(cha_mc[TestName],s3errors[[#This Row],[MCA_String]],cha_mc[VisualId],MC_Check!$H$2) -> 0 | AN6: cdie1 | AO6: ="*SOCKET0**COMPUTE1**UNCORE**PUNIT**PTPCFSMS**PTPCFSMS"&splitchar&"MC*STATUS*" -> *SOCKET0**COMPUTE1**UNCORE**PUNIT**PTPCFSMS**PTPCFSMS__MC*STATUS* | AP6: =COUNTIFS(cha_mc[TestName],punitmcas[[#This Row],[MCA_String]],cha_mc[VisualId],MC_Check!$H$2) -> 0
D7: ShowTop | F7: 0 | G7: 4 | H7: =misc[[#This Row],[Core_Hitter_Count]]>0 -> FALSE | I7: =misc[[#This Row],[LLC_Hitter_Count]]>0 -> FALSE | J7: =misc[[#This Row],[CHA_Hitter_Count]]>0 -> FALSE | K7: =_xlfn.TEXTJOIN("",,"*SOCKET0**COMPUTE",misc[[#This Row],[Compute]],"**UNCORE**CHA**CHA",misc[[#This Row],[location]],splitchar,"UTIL**MC*STATUS*") -> *SOCKET0**COMPUTE0**UNCORE**CHA**CHA4__UTIL**MC*STATUS* | L7: =COUNTIFS(cha_mc[TestName],misc[[#This Row],[CHA_MCA_String]],cha_mc[VisualId],MC_Check!$H$2) -> 0 | M7: =_xlfn.TEXTJOIN("",,"*SOCKET0**COMPUTE",misc[[#This Row],[Compute]],"**CPU**CORE",misc[[#This Row],[location]],splitchar,"THREAD"&"*",splitchar,"DCU*CR*MC1*STATUS**") -> *SOCKET0**COMPUTE0**CPU**CORE4__THREAD*__DCU*CR*MC1*STATUS** | N7: =COUNTIFS(core_mc[TestName],misc[[#This Row],[DCU_MCA_String]],core_mc[VisualId],MC_Check!$H$2) -> 0 | O7: =_xlfn.TEXTJOIN("",,"*SOCKET0**COMPUTE",misc[[#This Row],[Compute]],"**CPU**CORE",misc[[#This Row],[location]],splitchar,"DTLB*CR*MC2*STATUS**") -> *SOCKET0**COMPUTE0**CPU**CORE4__DTLB*CR*MC2*STATUS** | P7: =COUNTIFS(core_mc[TestName],misc[[#This Row],[DTLB_MCA_String]],core_mc[VisualId],MC_Check!$H$2) -> 0 | Q7: =_xlfn.TEXTJOIN("",,"*SOCKET0**COMPUTE",misc[[#This Row],[Compute]],"**CPU**CORE",misc[[#This Row],[location]],splitchar,"THREAD"&"*",splitchar,"IFU*CR*MC0*STATUS**") -> *SOCKET0**COMPUTE0**CPU**CORE4__THREAD*__IFU*CR*MC0*STATUS** | R7: =COUNTIFS(core_mc[TestName],misc[[#This Row],[IFU_MCA_String]],core_mc[VisualId],MC_Check!$H$2) -> 0 | S7: =_xlfn.TEXTJOIN("",,"*SOCKET0**COMPUTE",misc[[#This Row],[Compute]],"**CPU**CORE",misc[[#This Row],[location]],splitchar,"ML2*CR*MC3*STATUS*") -> *SOCKET0**COMPUTE0**CPU**CORE4__ML2*CR*MC3*STATUS* | T7: =COUNTIFS(core_mc[TestName],misc[[#This Row],[CORE_MCA_String]],core_mc[VisualId],MC_Check!$H$2) -> 0 | U7: =misc[[#This Row],[Core_ML2_Count]]+misc[[#This Row],[Core_IFU_Count]]+misc[[#This Row],[Core_DCU_Count]]+misc[[#This Row],[Core_DTLB_Count]] -> 0 | V7: =_xlfn.TEXTJOIN(", ",,IF(misc[[#This Row],[Core_DCU_Count]]>0,"DCU",""),IF(misc[[#This Row],[Core_IFU_Count]]>0,"IFU",""),IF(misc[[#This Row],[Core_ML2_Count]]>0,"ML2",""),IF(misc[[#This Row],[Core_DTLB_Count]]>0,"DTLB","")) | W7: =_xlfn.TEXTJOIN("",,"*SOCKET0**COMPUTE",misc[[#This Row],[Compute]],"**UNCORE**SCF**SCF*LLC**SCF*LLC",misc[[#This Row],[location]],splitchar,"MCI*STATUS*") -> *SOCKET0**COMPUTE0**UNCORE**SCF**SCF*LLC**SCF*LLC4__MCI*STATUS* | X7: =COUNTIFS(cha_mc[TestName],misc[[#This Row],[LLC_MCA_String]],cha_mc[VisualId],MC_Check!$H$2) -> 0 | AA7: 2 | AB7: 4 | AC7: ="CH"&memss[[#This Row],[location]] -> CH4 | AD7: =memss[[#This Row],[MEMSS_Hitter_Count]]>0 -> FALSE | AE7: =_xlfn.TEXTJOIN("",,"*SOCKET0**SOC**MEMSS**B2CMI",memss[[#This Row],[location]],splitchar,"MCI*STATUS*SHADOW*") -> *SOCKET0**SOC**MEMSS**B2CMI4__MCI*STATUS*SHADOW* | AF7: =COUNTIFS(cha_mc[TestName],memss[[#This Row],[MEMMS_MCA_String]],cha_mc[VisualId],MC_Check!$H$2) -> 0 | AJ7: cdie2 | AK7: ="*SOCKET0**COMPUTE2**TAPS**IOW*GLBW*IS3M*IBL*TOP110"&splitchar&"TAP*S3M*ERR*STS**" -> *SOCKET0**COMPUTE2**TAPS**IOW*GLBW*IS3M*IBL*TOP110__TAP*S3M*ERR*STS** | AL7: =COUNTIFS(cha_mc[TestName],s3errors[[#This Row],[MCA_String]],cha_mc[VisualId],MC_Check!$H$2) -> 0 | AN7: cdie2 | AO7: ="*SOCKET0**COMPUTE2**UNCORE**PUNIT**PTPCFSMS**PTPCFSMS"&splitchar&"MC*STATUS*" -> *SOCKET0**COMPUTE2**UNCORE**PUNIT**PTPCFSMS**PTPCFSMS__MC*STATUS* | AP7: =COUNTIFS(cha_mc[TestName],punitmcas[[#This Row],[MCA_String]],cha_mc[VisualId],MC_Check!$H$2) -> 0
D8: 1 | F8: 0 | G8: 5 | H8: =misc[[#This Row],[Core_Hitter_Count]]>0 -> FALSE | I8: =misc[[#This Row],[LLC_Hitter_Count]]>0 -> FALSE | J8: =misc[[#This Row],[CHA_Hitter_Count]]>0 -> FALSE | K8: =_xlfn.TEXTJOIN("",,"*SOCKET0**COMPUTE",misc[[#This Row],[Compute]],"**UNCORE**CHA**CHA",misc[[#This Row],[location]],splitchar,"UTIL**MC*STATUS*") -> *SOCKET0**COMPUTE0**UNCORE**CHA**CHA5__UTIL**MC*STATUS* | L8: =COUNTIFS(cha_mc[TestName],misc[[#This Row],[CHA_MCA_String]],cha_mc[VisualId],MC_Check!$H$2) -> 0 | M8: =_xlfn.TEXTJOIN("",,"*SOCKET0**COMPUTE",misc[[#This Row],[Compute]],"**CPU**CORE",misc[[#This Row],[location]],splitchar,"THREAD"&"*",splitchar,"DCU*CR*MC1*STATUS**") -> *SOCKET0**COMPUTE0**CPU**CORE5__THREAD*__DCU*CR*MC1*STATUS** | N8: =COUNTIFS(core_mc[TestName],misc[[#This Row],[DCU_MCA_String]],core_mc[VisualId],MC_Check!$H$2) -> 0 | O8: =_xlfn.TEXTJOIN("",,"*SOCKET0**COMPUTE",misc[[#This Row],[Compute]],"**CPU**CORE",misc[[#This Row],[location]],splitchar,"DTLB*CR*MC2*STATUS**") -> *SOCKET0**COMPUTE0**CPU**CORE5__DTLB*CR*MC2*STATUS** | P8: =COUNTIFS(core_mc[TestName],misc[[#This Row],[DTLB_MCA_String]],core_mc[VisualId],MC_Check!$H$2) -> 0 | Q8: =_xlfn.TEXTJOIN("",,"*SOCKET0**COMPUTE",misc[[#This Row],[Compute]],"**CPU**CORE",misc[[#This Row],[location]],splitchar,"THREAD"&"*",splitchar,"IFU*CR*MC0*STATUS**") -> *SOCKET0**COMPUTE0**CPU**CORE5__THREAD*__IFU*CR*MC0*STATUS** | R8: =COUNTIFS(core_mc[TestName],misc[[#This Row],[IFU_MCA_String]],core_mc[VisualId],MC_Check!$H$2) -> 0 | S8: =_xlfn.TEXTJOIN("",,"*SOCKET0**COMPUTE",misc[[#This Row],[Compute]],"**CPU**CORE",misc[[#This Row],[location]],splitchar,"ML2*CR*MC3*STATUS*") -> *SOCKET0**COMPUTE0**CPU**CORE5__ML2*CR*MC3*STATUS* | T8: =COUNTIFS(core_mc[TestName],misc[[#This Row],[CORE_MCA_String]],core_mc[VisualId],MC_Check!$H$2) -> 0 | U8: =misc[[#This Row],[Core_ML2_Count]]+misc[[#This Row],[Core_IFU_Count]]+misc[[#This Row],[Core_DCU_Count]]+misc[[#This Row],[Core_DTLB_Count]] -> 0 | V8: =_xlfn.TEXTJOIN(", ",,IF(misc[[#This Row],[Core_DCU_Count]]>0,"DCU",""),IF(misc[[#This Row],[Core_IFU_Count]]>0,"IFU",""),IF(misc[[#This Row],[Core_ML2_Count]]>0,"ML2",""),IF(misc[[#This Row],[Core_DTLB_Count]]>0,"DTLB","")) | W8: =_xlfn.TEXTJOIN("",,"*SOCKET0**COMPUTE",misc[[#This Row],[Compute]],"**UNCORE**SCF**SCF*LLC**SCF*LLC",misc[[#This Row],[location]],splitchar,"MCI*STATUS*") -> *SOCKET0**COMPUTE0**UNCORE**SCF**SCF*LLC**SCF*LLC5__MCI*STATUS* | X8: =COUNTIFS(cha_mc[TestName],misc[[#This Row],[LLC_MCA_String]],cha_mc[VisualId],MC_Check!$H$2) -> 0 | AA8: 2 | AB8: 5 | AC8: ="CH"&memss[[#This Row],[location]] -> CH5 | AD8: =memss[[#This Row],[MEMSS_Hitter_Count]]>0 -> FALSE | AE8: =_xlfn.TEXTJOIN("",,"*SOCKET0**SOC**MEMSS**B2CMI",memss[[#This Row],[location]],splitchar,"MCI*STATUS*SHADOW*") -> *SOCKET0**SOC**MEMSS**B2CMI5__MCI*STATUS*SHADOW* | AF8: =COUNTIFS(cha_mc[TestName],memss[[#This Row],[MEMMS_MCA_String]],cha_mc[VisualId],MC_Check!$H$2) -> 0
D9: 2 | F9: 0 | G9: 6 | H9: =misc[[#This Row],[Core_Hitter_Count]]>0 -> FALSE | I9: =misc[[#This Row],[LLC_Hitter_Count]]>0 -> FALSE | J9: =misc[[#This Row],[CHA_Hitter_Count]]>0 -> FALSE | K9: =_xlfn.TEXTJOIN("",,"*SOCKET0**COMPUTE",misc[[#This Row],[Compute]],"**UNCORE**CHA**CHA",misc[[#This Row],[location]],splitchar,"UTIL**MC*STATUS*") -> *SOCKET0**COMPUTE0**UNCORE**CHA**CHA6__UTIL**MC*STATUS* | L9: =COUNTIFS(cha_mc[TestName],misc[[#This Row],[CHA_MCA_String]],cha_mc[VisualId],MC_Check!$H$2) -> 0 | M9: =_xlfn.TEXTJOIN("",,"*SOCKET0**COMPUTE",misc[[#This Row],[Compute]],"**CPU**CORE",misc[[#This Row],[location]],splitchar,"THREAD"&"*",splitchar,"DCU*CR*MC1*STATUS**") -> *SOCKET0**COMPUTE0**CPU**CORE6__THREAD*__DCU*CR*MC1*STATUS** | N9: =COUNTIFS(core_mc[TestName],misc[[#This Row],[DCU_MCA_String]],core_mc[VisualId],MC_Check!$H$2) -> 0 | O9: =_xlfn.TEXTJOIN("",,"*SOCKET0**COMPUTE",misc[[#This Row],[Compute]],"**CPU**CORE",misc[[#This Row],[location]],splitchar,"DTLB*CR*MC2*STATUS**") -> *SOCKET0**COMPUTE0**CPU**CORE6__DTLB*CR*MC2*STATUS** | P9: =COUNTIFS(core_mc[TestName],misc[[#This Row],[DTLB_MCA_String]],core_mc[VisualId],MC_Check!$H$2) -> 0 | Q9: =_xlfn.TEXTJOIN("",,"*SOCKET0**COMPUTE",misc[[#This Row],[Compute]],"**CPU**CORE",misc[[#This Row],[location]],splitchar,"THREAD"&"*",splitchar,"IFU*CR*MC0*STATUS**") -> *SOCKET0**COMPUTE0**CPU**CORE6__THREAD*__IFU*CR*MC0*STATUS** | R9: =COUNTIFS(core_mc[TestName],misc[[#This Row],[IFU_MCA_String]],core_mc[VisualId],MC_Check!$H$2) -> 0 | S9: =_xlfn.TEXTJOIN("",,"*SOCKET0**COMPUTE",misc[[#This Row],[Compute]],"**CPU**CORE",misc[[#This Row],[location]],splitchar,"ML2*CR*MC3*STATUS*") -> *SOCKET0**COMPUTE0**CPU**CORE6__ML2*CR*MC3*STATUS* | T9: =COUNTIFS(core_mc[TestName],misc[[#This Row],[CORE_MCA_String]],core_mc[VisualId],MC_Check!$H$2) -> 0 | U9: =misc[[#This Row],[Core_ML2_Count]]+misc[[#This Row],[Core_IFU_Count]]+misc[[#This Row],[Core_DCU_Count]]+misc[[#This Row],[Core_DTLB_Count]] -> 0 | V9: =_xlfn.TEXTJOIN(", ",,IF(misc[[#This Row],[Core_DCU_Count]]>0,"DCU",""),IF(misc[[#This Row],[Core_IFU_Count]]>0,"IFU",""),IF(misc[[#This Row],[Core_ML2_Count]]>0,"ML2",""),IF(misc[[#This Row],[Core_DTLB_Count]]>0,"DTLB","")) | W9: =_xlfn.TEXTJOIN("",,"*SOCKET0**COMPUTE",misc[[#This Row],[Compute]],"**UNCORE**SCF**SCF*LLC**SCF*LLC",misc[[#This Row],[location]],splitchar,"MCI*STATUS*") -> *SOCKET0**COMPUTE0**UNCORE**SCF**SCF*LLC**SCF*LLC6__MCI*STATUS* | X9: =COUNTIFS(cha_mc[TestName],misc[[#This Row],[LLC_MCA_String]],cha_mc[VisualId],MC_Check!$H$2) -> 0 | AA9: 1 | AB9: 6 | AC9: ="CH"&memss[[#This Row],[location]] -> CH6 | AD9: =memss[[#This Row],[MEMSS_Hitter_Count]]>0 -> FALSE | AE9: =_xlfn.TEXTJOIN("",,"*SOCKET0**SOC**MEMSS**B2CMI",memss[[#This Row],[location]],splitchar,"MCI*STATUS*SHADOW*") -> *SOCKET0**SOC**MEMSS**B2CMI6__MCI*STATUS*SHADOW* | AF9: =COUNTIFS(cha_mc[TestName],memss[[#This Row],[MEMMS_MCA_String]],cha_mc[VisualId],MC_Check!$H$2) -> 0
D10: 3 | F10: 0 | G10: 7 | H10: =misc[[#This Row],[Core_Hitter_Count]]>0 -> FALSE | I10: =misc[[#This Row],[LLC_Hitter_Count]]>0 -> FALSE | J10: =misc[[#This Row],[CHA_Hitter_Count]]>0 -> FALSE | K10: =_xlfn.TEXTJOIN("",,"*SOCKET0**COMPUTE",misc[[#This Row],[Compute]],"**UNCORE**CHA**CHA",misc[[#This Row],[location]],splitchar,"UTIL**MC*STATUS*") -> *SOCKET0**COMPUTE0**UNCORE**CHA**CHA7__UTIL**MC*STATUS* | L10: =COUNTIFS(cha_mc[TestName],misc[[#This Row],[CHA_MCA_String]],cha_mc[VisualId],MC_Check!$H$2) -> 0 | M10: =_xlfn.TEXTJOIN("",,"*SOCKET0**COMPUTE",misc[[#This Row],[Compute]],"**CPU**CORE",misc[[#This Row],[location]],splitchar,"THREAD"&"*",splitchar,"DCU*CR*MC1*STATUS**") -> *SOCKET0**COMPUTE0**CPU**CORE7__THREAD*__DCU*CR*MC1*STATUS** | N10: =COUNTIFS(core_mc[TestName],misc[[#This Row],[DCU_MCA_String]],core_mc[VisualId],MC_Check!$H$2) -> 0 | O10: =_xlfn.TEXTJOIN("",,"*SOCKET0**COMPUTE",misc[[#This Row],[Compute]],"**CPU**CORE",misc[[#This Row],[location]],splitchar,"DTLB*CR*MC2*STATUS**") -> *SOCKET0**COMPUTE0**CPU**CORE7__DTLB*CR*MC2*STATUS** | P10: =COUNTIFS(core_mc[TestName],misc[[#This Row],[DTLB_MCA_String]],core_mc[VisualId],MC_Check!$H$2) -> 0 | Q10: =_xlfn.TEXTJOIN("",,"*SOCKET0**COMPUTE",misc[[#This Row],[Compute]],"**CPU**CORE",misc[[#This Row],[location]],splitchar,"THREAD"&"*",splitchar,"IFU*CR*MC0*STATUS**") -> *SOCKET0**COMPUTE0**CPU**CORE7__THREAD*__IFU*CR*MC0*STATUS** | R10: =COUNTIFS(core_mc[TestName],misc[[#This Row],[IFU_MCA_String]],core_mc[VisualId],MC_Check!$H$2) -> 0 | S10: =_xlfn.TEXTJOIN("",,"*SOCKET0**COMPUTE",misc[[#This Row],[Compute]],"**CPU**CORE",misc[[#This Row],[location]],splitchar,"ML2*CR*MC3*STATUS*") -> *SOCKET0**COMPUTE0**CPU**CORE7__ML2*CR*MC3*STATUS* | T10: =COUNTIFS(core_mc[TestName],misc[[#This Row],[CORE_MCA_String]],core_mc[VisualId],MC_Check!$H$2) -> 0 | U10: =misc[[#This Row],[Core_ML2_Count]]+misc[[#This Row],[Core_IFU_Count]]+misc[[#This Row],[Core_DCU_Count]]+misc[[#This Row],[Core_DTLB_Count]] -> 0 | V10: =_xlfn.TEXTJOIN(", ",,IF(misc[[#This Row],[Core_DCU_Count]]>0,"DCU",""),IF(misc[[#This Row],[Core_IFU_Count]]>0,"IFU",""),IF(misc[[#This Row],[Core_ML2_Count]]>0,"ML2",""),IF(misc[[#This Row],[Core_DTLB_Count]]>0,"DTLB","")) | W10: =_xlfn.TEXTJOIN("",,"*SOCKET0**COMPUTE",misc[[#This Row],[Compute]],"**UNCORE**SCF**SCF*LLC**SCF*LLC",misc[[#This Row],[location]],splitchar,"MCI*STATUS*") -> *SOCKET0**COMPUTE0**UNCORE**SCF**SCF*LLC**SCF*LLC7__MCI*STATUS* | X10: =COUNTIFS(cha_mc[TestName],misc[[#This Row],[LLC_MCA_String]],cha_mc[VisualId],MC_Check!$H$2) -> 0 | AA10: 1 | AB10: 7 | AC10: ="CH"&memss[[#This Row],[location]] -> CH7 | AD10: =memss[[#This Row],[MEMSS_Hitter_Count]]>0 -> FALSE | AE10: =_xlfn.TEXTJOIN("",,"*SOCKET0**SOC**MEMSS**B2CMI",memss[[#This Row],[location]],splitchar,"MCI*STATUS*SHADOW*") -> *SOCKET0**SOC**MEMSS**B2CMI7__MCI*STATUS*SHADOW* | AF10: =COUNTIFS(cha_mc[TestName],memss[[#This Row],[MEMMS_MCA_String]],cha_mc[VisualId],MC_Check!$H$2) -> 0
F11: 0 | G11: 8 | H11: =misc[[#This Row],[Core_Hitter_Count]]>0 -> TRUE | I11: =misc[[#This Row],[LLC_Hitter_Count]]>0 -> FALSE | J11: =misc[[#This Row],[CHA_Hitter_Count]]>0 -> FALSE | K11: =_xlfn.TEXTJOIN("",,"*SOCKET0**COMPUTE",misc[[#This Row],[Compute]],"**UNCORE**CHA**CHA",misc[[#This Row],[location]],splitchar,"UTIL**MC*STATUS*") -> *SOCKET0**COMPUTE0**UNCORE**CHA**CHA8__UTIL**MC*STATUS* | L11: =COUNTIFS(cha_mc[TestName],misc[[#This Row],[CHA_MCA_String]],cha_mc[VisualId],MC_Check!$H$2) -> 0 | M11: =_xlfn.TEXTJOIN("",,"*SOCKET0**COMPUTE",misc[[#This Row],[Compute]],"**CPU**CORE",misc[[#This Row],[location]],splitchar,"THREAD"&"*",splitchar,"DCU*CR*MC1*STATUS**") -> *SOCKET0**COMPUTE0**CPU**CORE8__THREAD*__DCU*CR*MC1*STATUS** | N11: =COUNTIFS(core_mc[TestName],misc[[#This Row],[DCU_MCA_String]],core_mc[VisualId],MC_Check!$H$2) -> 0 | O11: =_xlfn.TEXTJOIN("",,"*SOCKET0**COMPUTE",misc[[#This Row],[Compute]],"**CPU**CORE",misc[[#This Row],[location]],splitchar,"DTLB*CR*MC2*STATUS**") -> *SOCKET0**COMPUTE0**CPU**CORE8__DTLB*CR*MC2*STATUS** | P11: =COUNTIFS(core_mc[TestName],misc[[#This Row],[DTLB_MCA_String]],core_mc[VisualId],MC_Check!$H$2) -> 0 | Q11: =_xlfn.TEXTJOIN("",,"*SOCKET0**COMPUTE",misc[[#This Row],[Compute]],"**CPU**CORE",misc[[#This Row],[location]],splitchar,"THREAD"&"*",splitchar,"IFU*CR*MC0*STATUS**") -> *SOCKET0**COMPUTE0**CPU**CORE8__THREAD*__IFU*CR*MC0*STATUS** | R11: =COUNTIFS(core_mc[TestName],misc[[#This Row],[IFU_MCA_String]],core_mc[VisualId],MC_Check!$H$2) -> 0 | S11: =_xlfn.TEXTJOIN("",,"*SOCKET0**COMPUTE",misc[[#This Row],[Compute]],"**CPU**CORE",misc[[#This Row],[location]],splitchar,"ML2*CR*MC3*STATUS*") -> *SOCKET0**COMPUTE0**CPU**CORE8__ML2*CR*MC3*STATUS* | T11: =COUNTIFS(core_mc[TestName],misc[[#This Row],[CORE_MCA_String]],core_mc[VisualId],MC_Check!$H$2) -> 1 | U11: =misc[[#This Row],[Core_ML2_Count]]+misc[[#This Row],[Core_IFU_Count]]+misc[[#This Row],[Core_DCU_Count]]+misc[[#This Row],[Core_DTLB_Count]] -> 1 | V11: =_xlfn.TEXTJOIN(", ",,IF(misc[[#This Row],[Core_DCU_Count]]>0,"DCU",""),IF(misc[[#This Row],[Core_IFU_Count]]>0,"IFU",""),IF(misc[[#This Row],[Core_ML2_Count]]>0,"ML2",""),IF(misc[[#This Row],[Core_DTLB_Count]]>0,"DTLB","")) -> ML2 | W11: =_xlfn.TEXTJOIN("",,"*SOCKET0**COMPUTE",misc[[#This Row],[Compute]],"**UNCORE**SCF**SCF*LLC**SCF*LLC",misc[[#This Row],[location]],splitchar,"MCI*STATUS*") -> *SOCKET0**COMPUTE0**UNCORE**SCF**SCF*LLC**SCF*LLC8__MCI*STATUS* | X11: =COUNTIFS(cha_mc[TestName],misc[[#This Row],[LLC_MCA_String]],cha_mc[VisualId],MC_Check!$H$2) -> 0 | AA11: 0 | AB11: 8 | AC11: ="CH"&memss[[#This Row],[location]] -> CH8 | AD11: =memss[[#This Row],[MEMSS_Hitter_Count]]>0 -> FALSE | AE11: =_xlfn.TEXTJOIN("",,"*SOCKET0**SOC**MEMSS**B2CMI",memss[[#This Row],[location]],splitchar,"MCI*STATUS*SHADOW*") -> *SOCKET0**SOC**MEMSS**B2CMI8__MCI*STATUS*SHADOW* | AF11: =COUNTIFS(cha_mc[TestName],memss[[#This Row],[MEMMS_MCA_String]],cha_mc[VisualId],MC_Check!$H$2) -> 0
F12: 0 | G12: 9 | H12: =misc[[#This Row],[Core_Hitter_Count]]>0 -> FALSE | I12: =misc[[#This Row],[LLC_Hitter_Count]]>0 -> FALSE | J12: =misc[[#This Row],[CHA_Hitter_Count]]>0 -> FALSE | K12: =_xlfn.TEXTJOIN("",,"*SOCKET0**COMPUTE",misc[[#This Row],[Compute]],"**UNCORE**CHA**CHA",misc[[#This Row],[location]],splitchar,"UTIL**MC*STATUS*") -> *SOCKET0**COMPUTE0**UNCORE**CHA**CHA9__UTIL**MC*STATUS* | L12: =COUNTIFS(cha_mc[TestName],misc[[#This Row],[CHA_MCA_String]],cha_mc[VisualId],MC_Check!$H$2) -> 0 | M12: =_xlfn.TEXTJOIN("",,"*SOCKET0**COMPUTE",misc[[#This Row],[Compute]],"**CPU**CORE",misc[[#This Row],[location]],splitchar,"THREAD"&"*",splitchar,"DCU*CR*MC1*STATUS**") -> *SOCKET0**COMPUTE0**CPU**CORE9__THREAD*__DCU*CR*MC1*STATUS** | N12: =COUNTIFS(core_mc[TestName],misc[[#This Row],[DCU_MCA_String]],core_mc[VisualId],MC_Check!$H$2) -> 0 | O12: =_xlfn.TEXTJOIN("",,"*SOCKET0**COMPUTE",misc[[#This Row],[Compute]],"**CPU**CORE",misc[[#This Row],[location]],splitchar,"DTLB*CR*MC2*STATUS**") -> *SOCKET0**COMPUTE0**CPU**CORE9__DTLB*CR*MC2*STATUS** | P12: =COUNTIFS(core_mc[TestName],misc[[#This Row],[DTLB_MCA_String]],core_mc[VisualId],MC_Check!$H$2) -> 0 | Q12: =_xlfn.TEXTJOIN("",,"*SOCKET0**COMPUTE",misc[[#This Row],[Compute]],"**CPU**CORE",misc[[#This Row],[location]],splitchar,"THREAD"&"*",splitchar,"IFU*CR*MC0*STATUS**") -> *SOCKET0**COMPUTE0**CPU**CORE9__THREAD*__IFU*CR*MC0*STATUS** | R12: =COUNTIFS(core_mc[TestName],misc[[#This Row],[IFU_MCA_String]],core_mc[VisualId],MC_Check!$H$2) -> 0 | S12: =_xlfn.TEXTJOIN("",,"*SOCKET0**COMPUTE",misc[[#This Row],[Compute]],"**CPU**CORE",misc[[#This Row],[location]],splitchar,"ML2*CR*MC3*STATUS*") -> *SOCKET0**COMPUTE0**CPU**CORE9__ML2*CR*MC3*STATUS* | T12: =COUNTIFS(core_mc[TestName],misc[[#This Row],[CORE_MCA_String]],core_mc[VisualId],MC_Check!$H$2) -> 0 | U12: =misc[[#This Row],[Core_ML2_Count]]+misc[[#This Row],[Core_IFU_Count]]+misc[[#This Row],[Core_DCU_Count]]+misc[[#This Row],[Core_DTLB_Count]] -> 0 | V12: =_xlfn.TEXTJOIN(", ",,IF(misc[[#This Row],[Core_DCU_Count]]>0,"DCU",""),IF(misc[[#This Row],[Core_IFU_Count]]>0,"IFU",""),IF(misc[[#This Row],[Core_ML2_Count]]>0,"ML2",""),IF(misc[[#This Row],[Core_DTLB_Count]]>0,"DTLB","")) | W12: =_xlfn.TEXTJOIN("",,"*SOCKET0**COMPUTE",misc[[#This Row],[Compute]],"**UNCORE**SCF**SCF*LLC**SCF*LLC",misc[[#This Row],[location]],splitchar,"MCI*STATUS*") -> *SOCKET0**COMPUTE0**UNCORE**SCF**SCF*LLC**SCF*LLC9__MCI*STATUS* | X12: =COUNTIFS(cha_mc[TestName],misc[[#This Row],[LLC_MCA_String]],cha_mc[VisualId],MC_Check!$H$2) -> 0 | AA12: 0 | AB12: 9 | AC12: ="CH"&memss[[#This Row],[location]] -> CH9 | AD12: =memss[[#This Row],[MEMSS_Hitter_Count]]>0 -> FALSE | AE12: =_xlfn.TEXTJOIN("",,"*SOCKET0**SOC**MEMSS**B2CMI",memss[[#This Row],[location]],splitchar,"MCI*STATUS*SHADOW*") -> *SOCKET0**SOC**MEMSS**B2CMI9__MCI*STATUS*SHADOW* | AF12: =COUNTIFS(cha_mc[TestName],memss[[#This Row],[MEMMS_MCA_String]],cha_mc[VisualId],MC_Check!$H$2) -> 0
F13: 0 | G13: 10 | H13: =misc[[#This Row],[Core_Hitter_Count]]>0 -> FALSE | I13: =misc[[#This Row],[LLC_Hitter_Count]]>0 -> FALSE | J13: =misc[[#This Row],[CHA_Hitter_Count]]>0 -> FALSE | K13: =_xlfn.TEXTJOIN("",,"*SOCKET0**COMPUTE",misc[[#This Row],[Compute]],"**UNCORE**CHA**CHA",misc[[#This Row],[location]],splitchar,"UTIL**MC*STATUS*") -> *SOCKET0**COMPUTE0**UNCORE**CHA**CHA10__UTIL**MC*STATUS* | L13: =COUNTIFS(cha_mc[TestName],misc[[#This Row],[CHA_MCA_String]],cha_mc[VisualId],MC_Check!$H$2) -> 0 | M13: =_xlfn.TEXTJOIN("",,"*SOCKET0**COMPUTE",misc[[#This Row],[Compute]],"**CPU**CORE",misc[[#This Row],[location]],splitchar,"THREAD"&"*",splitchar,"DCU*CR*MC1*STATUS**") -> *SOCKET0**COMPUTE0**CPU**CORE10__THREAD*__DCU*CR*MC1*STATUS** | N13: =COUNTIFS(core_mc[TestName],misc[[#This Row],[DCU_MCA_String]],core_mc[VisualId],MC_Check!$H$2) -> 0 | O13: =_xlfn.TEXTJOIN("",,"*SOCKET0**COMPUTE",misc[[#This Row],[Compute]],"**CPU**CORE",misc[[#This Row],[location]],splitchar,"DTLB*CR*MC2*STATUS**") -> *SOCKET0**COMPUTE0**CPU**CORE10__DTLB*CR*MC2*STATUS** | P13: =COUNTIFS(core_mc[TestName],misc[[#This Row],[DTLB_MCA_String]],core_mc[VisualId],MC_Check!$H$2) -> 0 | Q13: =_xlfn.TEXTJOIN("",,"*SOCKET0**COMPUTE",misc[[#This Row],[Compute]],"**CPU**CORE",misc[[#This Row],[location]],splitchar,"THREAD"&"*",splitchar,"IFU*CR*MC0*STATUS**") -> *SOCKET0**COMPUTE0**CPU**CORE10__THREAD*__IFU*CR*MC0*STATUS** | R13: =COUNTIFS(core_mc[TestName],misc[[#This Row],[IFU_MCA_String]],core_mc[VisualId],MC_Check!$H$2) -> 0 | S13: =_xlfn.TEXTJOIN("",,"*SOCKET0**COMPUTE",misc[[#This Row],[Compute]],"**CPU**CORE",misc[[#This Row],[location]],splitchar,"ML2*CR*MC3*STATUS*") -> *SOCKET0**COMPUTE0**CPU**CORE10__ML2*CR*MC3*STATUS* | T13: =COUNTIFS(core_mc[TestName],misc[[#This Row],[CORE_MCA_String]],core_mc[VisualId],MC_Check!$H$2) -> 0 | U13: =misc[[#This Row],[Core_ML2_Count]]+misc[[#This Row],[Core_IFU_Count]]+misc[[#This Row],[Core_DCU_Count]]+misc[[#This Row],[Core_DTLB_Count]] -> 0 | V13: =_xlfn.TEXTJOIN(", ",,IF(misc[[#This Row],[Core_DCU_Count]]>0,"DCU",""),IF(misc[[#This Row],[Core_IFU_Count]]>0,"IFU",""),IF(misc[[#This Row],[Core_ML2_Count]]>0,"ML2",""),IF(misc[[#This Row],[Core_DTLB_Count]]>0,"DTLB","")) | W13: =_xlfn.TEXTJOIN("",,"*SOCKET0**COMPUTE",misc[[#This Row],[Compute]],"**UNCORE**SCF**SCF*LLC**SCF*LLC",misc[[#This Row],[location]],splitchar,"MCI*STATUS*") -> *SOCKET0**COMPUTE0**UNCORE**SCF**SCF*LLC**SCF*LLC10__MCI*STATUS* | X13: =COUNTIFS(cha_mc[TestName],misc[[#This Row],[LLC_MCA_String]],cha_mc[VisualId],MC_Check!$H$2) -> 0 | AA13: 2 | AB13: 10 | AC13: ="CH"&memss[[#This Row],[location]] -> CH10 | AD13: =memss[[#This Row],[MEMSS_Hitter_Count]]>0 -> FALSE | AE13: =_xlfn.TEXTJOIN("",,"*SOCKET0**SOC**MEMSS**B2CMI",memss[[#This Row],[location]],splitchar,"MCI*STATUS*SHADOW*") -> *SOCKET0**SOC**MEMSS**B2CMI10__MCI*STATUS*SHADOW* | AF13: =COUNTIFS(cha_mc[TestName],memss[[#This Row],[MEMMS_MCA_String]],cha_mc[VisualId],MC_Check!$H$2) -> 0
F14: 0 | G14: 11 | H14: =misc[[#This Row],[Core_Hitter_Count]]>0 -> FALSE | I14: =misc[[#This Row],[LLC_Hitter_Count]]>0 -> FALSE | J14: =misc[[#This Row],[CHA_Hitter_Count]]>0 -> FALSE | K14: =_xlfn.TEXTJOIN("",,"*SOCKET0**COMPUTE",misc[[#This Row],[Compute]],"**UNCORE**CHA**CHA",misc[[#This Row],[location]],splitchar,"UTIL**MC*STATUS*") -> *SOCKET0**COMPUTE0**UNCORE**CHA**CHA11__UTIL**MC*STATUS* | L14: =COUNTIFS(cha_mc[TestName],misc[[#This Row],[CHA_MCA_String]],cha_mc[VisualId],MC_Check!$H$2) -> 0 | M14: =_xlfn.TEXTJOIN("",,"*SOCKET0**COMPUTE",misc[[#This Row],[Compute]],"**CPU**CORE",misc[[#This Row],[location]],splitchar,"THREAD"&"*",splitchar,"DCU*CR*MC1*STATUS**") -> *SOCKET0**COMPUTE0**CPU**CORE11__THREAD*__DCU*CR*MC1*STATUS** | N14: =COUNTIFS(core_mc[TestName],misc[[#This Row],[DCU_MCA_String]],core_mc[VisualId],MC_Check!$H$2) -> 0 | O14: =_xlfn.TEXTJOIN("",,"*SOCKET0**COMPUTE",misc[[#This Row],[Compute]],"**CPU**CORE",misc[[#This Row],[location]],splitchar,"DTLB*CR*MC2*STATUS**") -> *SOCKET0**COMPUTE0**CPU**CORE11__DTLB*CR*MC2*STATUS** | P14: =COUNTIFS(core_mc[TestName],misc[[#This Row],[DTLB_MCA_String]],core_mc[VisualId],MC_Check!$H$2) -> 0 | Q14: =_xlfn.TEXTJOIN("",,"*SOCKET0**COMPUTE",misc[[#This Row],[Compute]],"**CPU**CORE",misc[[#This Row],[location]],splitchar,"THREAD"&"*",splitchar,"IFU*CR*MC0*STATUS**") -> *SOCKET0**COMPUTE0**CPU**CORE11__THREAD*__IFU*CR*MC0*STATUS** | R14: =COUNTIFS(core_mc[TestName],misc[[#This Row],[IFU_MCA_String]],core_mc[VisualId],MC_Check!$H$2) -> 0 | S14: =_xlfn.TEXTJOIN("",,"*SOCKET0**COMPUTE",misc[[#This Row],[Compute]],"**CPU**CORE",misc[[#This Row],[location]],splitchar,"ML2*CR*MC3*STATUS*") -> *SOCKET0**COMPUTE0**CPU**CORE11__ML2*CR*MC3*STATUS* | T14: =COUNTIFS(core_mc[TestName],misc[[#This Row],[CORE_MCA_String]],core_mc[VisualId],MC_Check!$H$2) -> 0 | U14: =misc[[#This Row],[Core_ML2_Count]]+misc[[#This Row],[Core_IFU_Count]]+misc[[#This Row],[Core_DCU_Count]]+misc[[#This Row],[Core_DTLB_Count]] -> 0 | V14: =_xlfn.TEXTJOIN(", ",,IF(misc[[#This Row],[Core_DCU_Count]]>0,"DCU",""),IF(misc[[#This Row],[Core_IFU_Count]]>0,"IFU",""),IF(misc[[#This Row],[Core_ML2_Count]]>0,"ML2",""),IF(misc[[#This Row],[Core_DTLB_Count]]>0,"DTLB","")) | W14: =_xlfn.TEXTJOIN("",,"*SOCKET0**COMPUTE",misc[[#This Row],[Compute]],"**UNCORE**SCF**SCF*LLC**SCF*LLC",misc[[#This Row],[location]],splitchar,"MCI*STATUS*") -> *SOCKET0**COMPUTE0**UNCORE**SCF**SCF*LLC**SCF*LLC11__MCI*STATUS* | X14: =COUNTIFS(cha_mc[TestName],misc[[#This Row],[LLC_MCA_String]],cha_mc[VisualId],MC_Check!$H$2) -> 0 | AA14: 2 | AB14: 11 | AC14: ="CH"&memss[[#This Row],[location]] -> CH11 | AD14: =memss[[#This Row],[MEMSS_Hitter_Count]]>0 -> FALSE | AE14: =_xlfn.TEXTJOIN("",,"*SOCKET0**SOC**MEMSS**B2CMI",memss[[#This Row],[location]],splitchar,"MCI*STATUS*SHADOW*") -> *SOCKET0**SOC**MEMSS**B2CMI11__MCI*STATUS*SHADOW* | AF14: =COUNTIFS(cha_mc[TestName],memss[[#This Row],[MEMMS_MCA_String]],cha_mc[VisualId],MC_Check!$H$2) -> 0
F15: 0 | G15: 12 | H15: =misc[[#This Row],[Core_Hitter_Count]]>0 -> FALSE | I15: =misc[[#This Row],[LLC_Hitter_Count]]>0 -> FALSE | J15: =misc[[#This Row],[CHA_Hitter_Count]]>0 -> FALSE | K15: =_xlfn.TEXTJOIN("",,"*SOCKET0**COMPUTE",misc[[#This Row],[Compute]],"**UNCORE**CHA**CHA",misc[[#This Row],[location]],splitchar,"UTIL**MC*STATUS*") -> *SOCKET0**COMPUTE0**UNCORE**CHA**CHA12__UTIL**MC*STATUS* | L15: =COUNTIFS(cha_mc[TestName],misc[[#This Row],[CHA_MCA_String]],cha_mc[VisualId],MC_Check!$H$2) -> 0 | M15: =_xlfn.TEXTJOIN("",,"*SOCKET0**COMPUTE",misc[[#This Row],[Compute]],"**CPU**CORE",misc[[#This Row],[location]],splitchar,"THREAD"&"*",splitchar,"DCU*CR*MC1*STATUS**") -> *SOCKET0**COMPUTE0**CPU**CORE12__THREAD*__DCU*CR*MC1*STATUS** | N15: =COUNTIFS(core_mc[TestName],misc[[#This Row],[DCU_MCA_String]],core_mc[VisualId],MC_Check!$H$2) -> 0 | O15: =_xlfn.TEXTJOIN("",,"*SOCKET0**COMPUTE",misc[[#This Row],[Compute]],"**CPU**CORE",misc[[#This Row],[location]],splitchar,"DTLB*CR*MC2*STATUS**") -> *SOCKET0**COMPUTE0**CPU**CORE12__DTLB*CR*MC2*STATUS** | P15: =COUNTIFS(core_mc[TestName],misc[[#This Row],[DTLB_MCA_String]],core_mc[VisualId],MC_Check!$H$2) -> 0 | Q15: =_xlfn.TEXTJOIN("",,"*SOCKET0**COMPUTE",misc[[#This Row],[Compute]],"**CPU**CORE",misc[[#This Row],[location]],splitchar,"THREAD"&"*",splitchar,"IFU*CR*MC0*STATUS**") -> *SOCKET0**COMPUTE0**CPU**CORE12__THREAD*__IFU*CR*MC0*STATUS** | R15: =COUNTIFS(core_mc[TestName],misc[[#This Row],[IFU_MCA_String]],core_mc[VisualId],MC_Check!$H$2) -> 0 | S15: =_xlfn.TEXTJOIN("",,"*SOCKET0**COMPUTE",misc[[#This Row],[Compute]],"**CPU**CORE",misc[[#This Row],[location]],splitchar,"ML2*CR*MC3*STATUS*") -> *SOCKET0**COMPUTE0**CPU**CORE12__ML2*CR*MC3*STATUS* | T15: =COUNTIFS(core_mc[TestName],misc[[#This Row],[CORE_MCA_String]],core_mc[VisualId],MC_Check!$H$2) -> 0 | U15: =misc[[#This Row],[Core_ML2_Count]]+misc[[#This Row],[Core_IFU_Count]]+misc[[#This Row],[Core_DCU_Count]]+misc[[#This Row],[Core_DTLB_Count]] -> 0 | V15: =_xlfn.TEXTJOIN(", ",,IF(misc[[#This Row],[Core_DCU_Count]]>0,"DCU",""),IF(misc[[#This Row],[Core_IFU_Count]]>0,"IFU",""),IF(misc[[#This Row],[Core_ML2_Count]]>0,"ML2",""),IF(misc[[#This Row],[Core_DTLB_Count]]>0,"DTLB","")) | W15: =_xlfn.TEXTJOIN("",,"*SOCKET0**COMPUTE",misc[[#This Row],[Compute]],"**UNCORE**SCF**SCF*LLC**SCF*LLC",misc[[#This Row],[location]],splitchar,"MCI*STATUS*") -> *SOCKET0**COMPUTE0**UNCORE**SCF**SCF*LLC**SCF*LLC12__MCI*STATUS* | X15: =COUNTIFS(cha_mc[TestName],misc[[#This Row],[LLC_MCA_String]],cha_mc[VisualId],MC_Check!$H$2) -> 0
F16: 0 | G16: 13 | H16: =misc[[#This Row],[Core_Hitter_Count]]>0 -> FALSE | I16: =misc[[#This Row],[LLC_Hitter_Count]]>0 -> FALSE | J16: =misc[[#This Row],[CHA_Hitter_Count]]>0 -> FALSE | K16: =_xlfn.TEXTJOIN("",,"*SOCKET0**COMPUTE",misc[[#This Row],[Compute]],"**UNCORE**CHA**CHA",misc[[#This Row],[location]],splitchar,"UTIL**MC*STATUS*") -> *SOCKET0**COMPUTE0**UNCORE**CHA**CHA13__UTIL**MC*STATUS* | L16: =COUNTIFS(cha_mc[TestName],misc[[#This Row],[CHA_MCA_String]],cha_mc[VisualId],MC_Check!$H$2) -> 0 | M16: =_xlfn.TEXTJOIN("",,"*SOCKET0**COMPUTE",misc[[#This Row],[Compute]],"**CPU**CORE",misc[[#This Row],[location]],splitchar,"THREAD"&"*",splitchar,"DCU*CR*MC1*STATUS**") -> *SOCKET0**COMPUTE0**CPU**CORE13__THREAD*__DCU*CR*MC1*STATUS** | N16: =COUNTIFS(core_mc[TestName],misc[[#This Row],[DCU_MCA_String]],core_mc[VisualId],MC_Check!$H$2) -> 0 | O16: =_xlfn.TEXTJOIN("",,"*SOCKET0**COMPUTE",misc[[#This Row],[Compute]],"**CPU**CORE",misc[[#This Row],[location]],splitchar,"DTLB*CR*MC2*STATUS**") -> *SOCKET0**COMPUTE0**CPU**CORE13__DTLB*CR*MC2*STATUS** | P16: =COUNTIFS(core_mc[TestName],misc[[#This Row],[DTLB_MCA_String]],core_mc[VisualId],MC_Check!$H$2) -> 0 | Q16: =_xlfn.TEXTJOIN("",,"*SOCKET0**COMPUTE",misc[[#This Row],[Compute]],"**CPU**CORE",misc[[#This Row],[location]],splitchar,"THREAD"&"*",splitchar,"IFU*CR*MC0*STATUS**") -> *SOCKET0**COMPUTE0**CPU**CORE13__THREAD*__IFU*CR*MC0*STATUS** | R16: =COUNTIFS(core_mc[TestName],misc[[#This Row],[IFU_MCA_String]],core_mc[VisualId],MC_Check!$H$2) -> 0 | S16: =_xlfn.TEXTJOIN("",,"*SOCKET0**COMPUTE",misc[[#This Row],[Compute]],"**CPU**CORE",misc[[#This Row],[location]],splitchar,"ML2*CR*MC3*STATUS*") -> *SOCKET0**COMPUTE0**CPU**CORE13__ML2*CR*MC3*STATUS* | T16: =COUNTIFS(core_mc[TestName],misc[[#This Row],[CORE_MCA_String]],core_mc[VisualId],MC_Check!$H$2) -> 0 | U16: =misc[[#This Row],[Core_ML2_Count]]+misc[[#This Row],[Core_IFU_Count]]+misc[[#This Row],[Core_DCU_Count]]+misc[[#This Row],[Core_DTLB_Count]] -> 0 | V16: =_xlfn.TEXTJOIN(", ",,IF(misc[[#This Row],[Core_DCU_Count]]>0,"DCU",""),IF(misc[[#This Row],[Core_IFU_Count]]>0,"IFU",""),IF(misc[[#This Row],[Core_ML2_Count]]>0,"ML2",""),IF(misc[[#This Row],[Core_DTLB_Count]]>0,"DTLB","")) | W16: =_xlfn.TEXTJOIN("",,"*SOCKET0**COMPUTE",misc[[#This Row],[Compute]],"**UNCORE**SCF**SCF*LLC**SCF*LLC",misc[[#This Row],[location]],splitchar,"MCI*STATUS*") -> *SOCKET0**COMPUTE0**UNCORE**SCF**SCF*LLC**SCF*LLC13__MCI*STATUS* | X16: =COUNTIFS(cha_mc[TestName],misc[[#This Row],[LLC_MCA_String]],cha_mc[VisualId],MC_Check!$H$2) -> 0
