Workbook

Sheet PPV
A1: Name | B1: Data.UNIT | C1: Data.Visual_ID | D1: Data.Start_WW | E1: Data.Facility | F1: Data.PPV_TP | G1: Data.CLASS_TP | H1: Data.Step | I1: Data.DevRevStep | J1: Data.S_Spec | K1: Data.DPM_Bucket | L1: Data.SubBucket | M1: Data.Subbucket - Notes | N1: Data.DPM | O1: Data.Root Cause | P1: Data.Group | Q1: Data.Weekly_DPM | R1: Data.1st CORE | S1: Item | T1: Kind | U1: Hidden
A2: Table6 | B2: 1 | C2: 75NW258700164 | D2: 202532 | E2: CR | F2: GNRSDEAHBA2531 | G2: GNRUCAPB3H04H01S531 | H2: REV4 | I2: 8AAHRVCB | J2: RVH4 | K2: CORE.ML2.3STRIKE | L2: LINUX | M2: PYTHONCOMMAND | N2: 13.730228 | P2: COOL | Q2: 329.8153 | R2: CORE60 | S2: Table6 | T2: Table | U2: FALSE
A3: Table6 | B3: 2 | C3: 75FQ351600172 | D3: 202532 | E3: CR | F3: GNRSDEAHBA2531 | G3: GNRUCAPB3H04H01S531 | H3: REV4 | I3: 8AAHQVCB | J3: RVH4 | K3: UNCORE.PCU.AGG | L3: LINUX | M3: SDESANDSTONE | N3: 13.730228 | P3: PUNIT | Q3: 329.8153 | R3: CORE77 | S3: Table6 | T3: Table | U3: FALSE
A4: Table6 | B4: 3 | C4: 752C6K2600230 | D4: 202532 | E4: CR | F4: GNRSDEAHBA2531 | G4: GNRUCAPB3H04H01S531 | H4: REV4 | I4: 8AAHRVCB | J4: RVF5 | K4: CORE.ML2.3STRIKE | L4: LINUX | M4: JASPER/BOOT | N4: 13.730228 | P4: SINGLE CORE (SC) | Q4: 329.8153 | R4: CORE168 | S4: Table6 | T4: Table | U4: FALSE
A5: Table6 | B5: 4 | C5: 75AV271100370 | D5: 202532 | E5: CR | F5: GNRSDEAHBA2531 | G5: GNRUCAPB3H04H01S531 | H5: REV4 | I5: 8AAHRVCB | J5: RVF5 | K5: CORE.ML2.3STRIKE | L5: DRAGON | M5: FIREWORX | N5: 13.730228 | P5: SINGLE CORE (SC) | Q5: 329.8153 | R5: CORE42 | S5: Table6 | T5: Table | U5: FALSE
A6: Table6 | B6: 5 | C6: 75PC435200207 | D6: 202532 | E6: CR | F6: GNRSDEAHBA2531 | G6: GNRUCAPB3H04H01S531 | H6: REV4 | I6: 8AAHRVCB | J6: RVH4 | K6: UNCORE.PCU.AGG | L6: DRAGON | M6: LEEKSPIN | N6: 13.730228 | P6: UNKNOWN | Q6: 329.8153 | S6: Table6 | T6: Table | U6: FALSE
A7: Table6 | B7: 6 | C7: 759Q17J500189 | D7: 202532 | E7: CR | F7: GNRSDEAHBA2531 | G7: GNRUCAPB3H04H01S531 | H7: REV4 | I7: 8AAHRVCB | J7: RVF5 | K7: CORE.ML2.3STRIKE | L7: DRAGON | M7: FRENZY | N7: 13.730228 | P7: SINGLE CORE (SC) | Q7: 329.8153 | R7: CORE9 | S7: Table6 | T7: Table | U7: FALSE
A8: Table6 | B8: 7 | C8: 75PC435200440 | D8: 202532 | E8: CR | F8: GNRSDEAHBA2531 | G8: GNRUCAPB3H04H01S531 | H8: REV4 | I8: 8AAHRVCB | J8: RVH4 | K8: UNCORE.PCU.AGG | L8: LINUX | M8: SDESANDSTONE | N8: 13.730228 | P8: PUNIT | Q8: 329.8153 | R8: CORE24 | S8: Table6 | T8: Table | U8: FALSE
A9: Table6 | B9: 8 | C9: 75Y86K5200361 | D9: 202533 | E9: CR | F9: GNRSDEAHBA2531 | G9: GNRUCAPB3H04H01S531 | H9: REV4 | I9: 8AAHRVCB | J9: RVH4 | K9: UNCORE.PCU.AGG | L9: LINUX | M9: PYTHONCOMMAND | N9: 13.730228 | P9: COOL | Q9: 169.60651 | R9: CORE95 | S9: Table6 | T9: Table | U9: FALSE
A10: Table6 | B10: 9 | C10: 75PC521100281 | D10: 202533 | E10: CR | F10: GNRSDEAHBA2531 | G10: GNRUCAPB3H04H01S531 | H10: REV4 | I10: 8AAHQVCB | J10: RVH4 | K10: CORE.ML2.3STRIKE | L10: MARIONETTE | M10: 0X54000000 | N10: 13.730228 | P10: UNKNOWN | Q10: 169.60651 | R10: CORE121 | S10: Table6 | T10: Table | U10: FALSE
A11: Table6 | B11: 10 | C11: 75DN054300086 | D11: 202533 | E11: CR | F11: GNRSDEAHBA2531 | G11: GNRUCAPB3H04H01S531 | H11: REV4 | I11: 8AAHQVCB | J11: RVH4 | K11: CORE.ML2.3STRIKE | L11: LINUX | M11: SDESANDSTONE | N11: 13.730228 | P11: SINGLE CORE (SC) | Q11: 169.60651 | R11: CORE129 | S11: Table6 | T11: Table | U11: FALSE
A12: Table6 | B12: 11 | C12: 759Q17J500021 | D12: 202533 | E12: CR | F12: GNRSDEAHBA2531 | G12: GNRUCAPB3H04H01S531 | H12: REV4 | I12: 8AAHRVCB | J12: RQ6Q | K12: CORE.ML2.3STRIKE | L12: LINUX | M12: IFS | N12: 13.730228 | P12: SINGLE CORE (SC) | Q12: 169.60651 | R12: CORE80 | S12: Table6 | T12: Table | U12: FALSE
A13: Table6 | B13: 12 | C13: 75XF413800100 | D13: 202533 | E13: CR | F13: GNRSDEAHBA2531 | G13: GNRUCAPB3H04H01S531 | H13: REV4 | I13: 8AAHRVCB | J13: RQ6Q | K13: CORE.ML2.3STRIKE | L13: MARIONETTE | M13: 0XA9041FFF | N13: 13.730228 | P13: SINGLE CORE (SC) | Q13: 169.60651 | R13: CORE0 | S13: Table6 | T13: Table | U13: FALSE
A14: Table6 | B14: 13 | C14: 753D2R1700369 | D14: 202533 | E14: CR | F14: GNRSDEAHBA2531 | G14: GNRUCAPB3H04H01S531 | H14: REV4 | I14: 8AAHPVCB | J14: RQ6Q | K14: CORE.ML2.3STRIKE | L14: DRAGON | M14: LEEKSPIN | N14: 13.730228 | P14: SINGLE CORE (SC) | Q14: 169.60651 | R14: CORE129 | S14: Table6 | T14: Table | U14: FALSE
A15: Table6 | B15: 14 | C15: 75K59B6100019 | D15: 202534 | E15: CR | F15: GNRSDEAHBA2533A | G15: GNRUCAPB3H04H01S531 | H15: REV4 | I15: 8AAHQVCB | J15: RVH4 | K15: CORE.ML2.3STRIKE | L15: MARIONETTE | M15: 0XAF001FFF | N15: 13.730228 | P15: SINGLE CORE (SC) | Q15: 151.42338 | R15: CORE143 | S15: Table6 | T15: Table | U15: FALSE
A16: Table6 | B16: 15 | C16: 75HQ026900353 | D16: 202535 | E16: CR | F16: GNRSDEAHBA2533A | G16: GNRUCAPB3H04H01S531 | H16: REV4 | I16: 8AAHRVCB | J16: RPKX | K16: CORE.ML2.3STRIKE | L16: MARIONETTE | N16: 13.730228 | P16: SINGLE CORE (SC) | Q16: 141.06362 | S16: Table6 | T16: Table | U16: FALSE
A17: Table6 | B17: 16 | C17: 759T8U8600262 | D17: 202535 | E17: CR | F17: GNRSDEAHBA2533A | G17: GNRUCAPB3H04H01S531 | H17: REV4 | I17: 8AAHQVCB | J17: RVF5 | K17: CORE.ML2.3STRIKE | L17: MARIONETTE | N17: 13.730228 | P17: SINGLE CORE (SC) | Q17: 141.06362 | R17: CORE119 | S17: Table6 | T17: Table | U17: FALSE
A18: Table6 | B18: 17 | C18: 750M6Q2200272 | D18: 202535 | E18: A15 | F18: GNRSDEAHBA2533A | G18: GNRUCAPB3H04H01S531 | H18: REV4 | I18: 8AAHQVCB | J18: RVF5 | K18: CORE.ML2.3STRIKE | L18: LINUX | M18: SDESANDSTONE | N18: 13.730228 | P18: COOL | Q18: 0 | S18: Table6 | T18: Table | U18: FALSE
A19: Table6 | B19: 18 | C19: 759T8U8600129 | D19: 202535 | E19: A15 | F19: GNRSDEAHBA2533A | G19: GNRUCAPB3H04H01S531 | H19: REV4 | I19: 8AAHQVCB | J19: RVF5 | K19: CORE.ML2.3STRIKE | L19: LINUX | M19: SDESANDSTONE | N19: 13.730228 | P19: COOL | Q19: 0 | R19: CORE55 | S19: Table6 | T19: Table | U19: FALSE
A20: Table6 | B20: 19 | C20: 759D38N100120 | D20: 202535 | E20: CR | F20: GNRSDEAHBA2533A | G20: GNRUCAPB3H04H01S531 | H20: REV4 | I20: 8AAHQVCB | J20: RVF5 | K20: CORE.ML2.3STRIKE | L20: LINUX | M20: SDESANDSTONE | N20: 13.730228 | P20: COOL | Q20: 141.06362 | S20: Table6 | T20: Table | U20: FALSE
A21: Table6 | B21: 20 | C21: 75EA153200192 | D21: 202535 | E21: A15 | F21: GNRSDEAHBA2533A | G21: GNRUCAPB3H04H01S531 | H21: REV4 | I21: 8AAHQVCB | J21: RVF5 | K21: CORE.ML2.3STRIKE | L21: LINUX | M21: SDESANDSTONE / JASPER / IFS | N21: 13.730228 | P21: PUNIT | Q21: 141.06362 | S21: Table6 | T21: Table | U21: FALSE
A22: Table6 | B22: 21 | C22: 75892BG300186 | D22: 202535 | E22: CR | F22: GNRSDEAHBA2533A | G22: GNRUCAPB3H04H01S531 | H22: REV4 | I22: 8AAHQVCB | J22: RVF5 | K22: CORE.ML2.3STRIKE | L22: LINUX | M22: TSL | N22: 13.730228 | P22: COOL | Q22: 141.06362 | R22: CORE103 | S22: Table6 | T22: Table | U22: FALSE
A23: Table6 | B23: 22 | C23: 759T8U8600274 | D23: 202535 | E23: CR | F23: GNRSDEAHBA2531 | G23: GNRUCAPB3H04H01S531 | H23: REV4 | I23: 8AAHQVCB | J23: RVF5 | K23: CORE.ML2.3STRIKE | L23: LINUX | M23: SDESANDSTONE | N23: 13.730228 | P23: COOL | Q23: 141.06362 | R23: CORE60 | S23: Table6 | T23: Table | U23: FALSE
A24: Table6 | B24: 23 | C24: 75KL115000196 | D24: 202535 | E24: CR | F24: GNRSDEAHBA2533A | G24: GNRUCAPB3H04H01S531 | H24: REV4 | I24: 8AAHQVCB | J24: RVF5 | K24: CORE.ML2.3STRIKE | L24: LINUX | M24: SOLAR | N24: 13.730228 | P24: SINGLE CORE (SC) | Q24: 141.06362 | R24: CORE67 | S24: Table6 | T24: Table | U24: FALSE
A25: Table6 | B25: 24 | C25: 75060KC200101 | D25: 202536 | E25: A15 | F25: GNRSDEAHBA2533A | G25: GNRUCAPB3H04H01S531 | H25: REV4 | I25: 8AAHRVCB | J25: RPKY | K25: CORE.ML2.3STRIKE | L25: LINUX | M25: SDESANDSTONE | N25: 13.730228 | P25: COOL | Q25: 117.13717 | S25: Table6 | T25: Table | U25: FALSE
A26: Table6 | B26: 25 | C26: 75PN442200154 | D26: 202536 | E26: A15 | F26: GNRSDEAHBA2533A | G26: GNRUCAPB3H04H01S531 | H26: REV4 | I26: 8AAHRVCB | J26: RPKY | K26: CORE.ML2.3STRIKE | L26: LINUX | M26: RAINBOW | N26: 13.730228 | P26: SINGLE CORE (SC) | Q26: 117.13717 | S26: Table6 | T26: Table | U26: FALSE
A27: Table6 | B27: 26 | C27: 75HV625900261 | D27: 202536 | E27: A15 | F27: GNRSDEAHBA2533A | G27: GNRUCAPB3H04H01S531 | H27: REV4 | I27: 8AAHRVCB | J27: RVF5 | K27: CORE.ML2.3STRIKE | L27: LINUX | M27: TSL | N27: 13.730228 | P27: SINGLE CORE (SC) | Q27: 117.13717 | S27: Table6 | T27: Table | U27: FALSE
A28: Table6 | B28: 27 | C28: 755905Q200303 | D28: 202536 | E28: A15 | F28: GNRSDEAHBA2533A | G28: GNRUCAPB3H04J01S535 | H28: REV4 | I28: 8AAHPVCB | J28: RVF5 | K28: CORE.ML2.3STRIKE | L28: DRAGON | M28: SCYLLA | N28: 13.730228 | P28: PUNIT | Q28: 117.13717 | S28: Table6 | T28: Table | U28: FALSE
A29: Table6 | B29: 28 | C29: 755905Q200002 | D29: 202536 | E29: A15 | F29: GNRSDEAHBA2533A | G29: GNRUCAPB3H04J01S535 | H29: REV4 | I29: 8AAHPVCB | J29: RPKX | K29: CORE.ML2.3STRIKE | L29: MARIONETTE | N29: 13.730228 | P29: SINGLE CORE (SC) | Q29: 117.13717 | R29: CORE0 | S29: Table6 | T29: Table | U29: FALSE
A30: Table6 | B30: 29 | C30: 75M7S84700143 | D30: 202536 | E30: A15 | F30: GNRSDEAHBA2533A | G30: GNRUCAPB3H04J01S535 | H30: REV4 | I30: 8AAHPVCB | J30: RQ6Q | K30: CORE.ML2.3STRIKE | L30: MARIONETTE | M30: 0XA9011FFF | N30: 13.730228 | P30: SINGLE CORE (SC) | Q30: 117.13717 | R30: CORE0 | S30: Table6 | T30: Table | U30: FALSE
A31: Table6 | B31: 30 | C31: 754D9U8400114 | D31: 202536 | E31: A15 | F31: GNRSDEAHBA2533A | G31: GNRUCAPB3H04H01S531 | H31: REV4 | I31: 8AAHQVCB | J31: RVF5 | K31: CORE.ML2.3STRIKE | L31: MARIONETTE | N31: 13.730228 | P31: SINGLE CORE (SC) | Q31: 117.13717 | R31: CORE9 | S31: Table6 | T31: Table | U31: FALSE
A32: Table6 | B32: 31 | C32: 750M6Q2200031 | D32: 202536 | E32: A15 | F32: GNRSDEAHBA2533A | G32: GNRUCAPB3H04H01S531 | H32: REV4 | I32: 8AAHQVCB | J32: RVF5 | K32: CORE.ML2.3STRIKE | L32: LINUX | M32: SDESANDSTONE | N32: 13.730228 | P32: COOL | Q32: 117.13717 | R32: CORE2 | S32: Table6 | T32: Table | U32: FALSE
A33: Table6 | B33: 32 | C33: 75M7S84700054 | D33: 202536 | E33: A15 | F33: GNRSDEAHBA2533A | G33: GNRUCAPB3H04J01S535 | H33: REV4 | I33: 8AAHPVCB | J33: RQ6Q | K33: CORE.ML2.3STRIKE | L33: LINUX | M33: SDESANDSTONE | N33: 13.730228 | P33: PUNIT | Q33: 117.13717 | R33: CORE63 | S33: Table6 | T33: Table | U33: FALSE
A34: Table6 | B34: 33 | C34: 758H6X4500166 | D34: 202536 | E34: A15 | F34: GNRSDEAHBA2533A | G34: GNRUCAPB3H04H01S531 | H34: REV4 | I34: 8AAHRVCB | J34: RPL9 | K34: CORE.ML2.3STRIKE | L34: DRAGON | M34: FRM | N34: 13.730228 | P34: COOL | Q34: 117.13717 | R34: CORE9 | S34: Table6 | T34: Table | U34: FALSE
A35: Table6 | B35: 34 | C35: 75AW816800059 | D35: 202536 | E35: A15 | F35: GNRSDEAHBA2533A | G35: GNRUCAPB3H04H01S531 | H35: REV4 | I35: 8AAHPVCB | J35: RVF5 | K35: CORE.ML2.3STRIKE | L35: DRAGON | M35: FRENZY | N35: 13.730228 | P35: SINGLE CORE (SC) | Q35: 117.13717 | R35: CORE119 | S35: Table6 | T35: Table | U35: FALSE
A36: Table6 | B36: 35 | C36: 753D2R1700164 | D36: 202537 | E36: A15 | F36: GNRSDEAHBA2533A | G36: GNRUCAPB3H04H01S531 | H36: REV4 | I36: 8AAHPVCB | J36: RVF5 | K36: UNCORE.PCU.AGG | L36: DRAGON | M36: FRENZY | N36: 13.730228 | P36: PUNIT | Q36: 155.59359 | R36: CORE29 | S36: Table6 | T36: Table | U36: FALSE
A37: Table6 | B37: 36 | C37: 75CK138400398 | D37: 202537 | E37: A15 | F37: GNRSDEAHBA2533A | G37: GNRUCAPB3H04H01S531 | H37: REV4 | I37: 8AAHRVCB | J37: RVF5 | K37: CORE.ML2.3STRIKE | L37: LINUX | M37: SDESANDSTONE | N37: 13.730228 | P37: COOL | Q37: 155.59359 | R37: CORE24 | S37: Table6 | T37: Table | U37: FALSE
A38: Table6 | B38: 37 | C38: 75LQ380100341 | D38: 202537 | E38: A15 | F38: GNRSDEAHBA2533A | G38: GNRUCAPB3H04H01S531 | H38: REV4 | I38: 8AAHQVCB | J38: RVF5 | K38: CORE.ML2.3STRIKE | L38: LINUX | M38: TSL | N38: 13.730228 | P38: SINGLE CORE (SC) | Q38: 155.59359 | R38: CORE177 | S38: Table6 | T38: Table | U38: FALSE
A39: Table6 | B39: 38 | C39: 752Q3N4700368 | D39: 202537 | E39: A15 | F39: GNRSDEAHBA2533A | G39: GNRUCAPB3H04H01S531 | H39: REV4 | I39: 8AAHRVCB | J39: RVF5 | K39: CORE.ML2.3STRIKE | L39: DRAGON | M39: FRM | N39: 13.730228 | P39: SINGLE CORE (SC) | Q39: 155.59359 | R39: CORE59 | S39: Table6 | T39: Table | U39: FALSE
A40: Table6 | B40: 39 | C40: 75CK138400551 | D40: 202537 | E40: A15 | F40: GNRSDEAHBA2533A | G40: GNRUCAPB3H04H01S531 | H40: REV4 | I40: 8AAHRVCB | J40: RVF5 | K40: CORE.ML2.3STRIKE | L40: LINUX | M40: JASPER | N40: 13.730228 | P40: SINGLE CORE (SC) | Q40: 155.59359 | S40: Table6 | T40: Table | U40: FALSE
...

Sheet Analysis
A1: VisualIDs | B1: Step | C1: WW | D1: # Runs | E1: Core Hint | F1: Core Fail Area | G1: CHA Hint | H1: CHA Fail Area | I1: LLC Hint | J1: LLC Fail Area | K1: SrcIDs | L1: Other | M1: Top OrigReq | N1: Top OpCode | O1: Top ISMQ | P1: Top SAD | Q1: Top SAD LocPort | R1: Core Mcas | S1: Root Cause | T1: Core Next Steps | U1: CHA Next Steps | V1: LLC Next Steps | W1: Other Next Steps | X1: Debug Hints | Y1: Failing Area
A2: 74JU522300112 | B2: =_xlfn.XLOOKUP(summ[[#This Row],[VisualIDs]],ppv[Data.Visual_ID],ppv[Data.Step], "") | C2: =_xlfn.XLOOKUP(summ[[#This Row],[VisualIDs]],ppv[Data.Visual_ID],ppv[Data.Start_WW]) -> #N/A | D2: =_xlfn.XLOOKUP(summ[[#This Row],[VisualIDs]],REV_Units!A:A,REV_Units!F:F) -> 2 | E2: =_xlfn.XLOOKUP(summ[[#This Row],[VisualIDs]],REV_Units!A:A,REV_Units!G:G) -> CORE143 | F2: =_xlfn.XLOOKUP(summ[[#This Row],[VisualIDs]],REV_Units!A:A,REV_Units!H:H) | G2: =_xlfn.XLOOKUP(summ[[#This Row],[VisualIDs]],REV_Units!A:A,REV_Units!I:I) -> NotFound | H2: =_xlfn.XLOOKUP(summ[[#This Row],[VisualIDs]],REV_Units!A:A,REV_Units!J:J) | I2: =_xlfn.XLOOKUP(summ[[#This Row],[VisualIDs]],REV_Units!A:A,REV_Units!K:K) -> NotFound | J2: =_xlfn.XLOOKUP(summ[[#This Row],[VisualIDs]],REV_Units!A:A,REV_Units!L:L) | K2: =_xlfn.XLOOKUP(summ[[#This Row],[VisualIDs]],REV_Units!A:A,REV_Units!M:M) -> NotFound | L2: =_xlfn.XLOOKUP(summ[[#This Row],[VisualIDs]],REV_Units!A:A,REV_Units!N:N) -> PUNIT:EPRPUNIT0 | M2: =_xlfn.XLOOKUP(summ[[#This Row],[VisualIDs]],REV_Units!A:A,REV_Units!O:O) -> PortIn | N2: =_xlfn.XLOOKUP(summ[[#This Row],[VisualIDs]],REV_Units!A:A,REV_Units!P:P) -> RspI | O2: =_xlfn.XLOOKUP(summ[[#This Row],[VisualIDs]],REV_Units!A:A,REV_Units!Q:Q) -> Wdata_Wcmp | P2: =_xlfn.XLOOKUP(summ[[#This Row],[VisualIDs]],REV_Units!A:A,REV_Units!R:R) -> IO | Q2: =_xlfn.XLOOKUP(summ[[#This Row],[VisualIDs]],REV_Units!A:A,REV_Units!S:S) -> PCIE0 | R2: =_xlfn.XLOOKUP(summ[[#This Row],[VisualIDs]],REV_Units!A:A,REV_Units!U:U) -> WDTimeout (3 strike) | S2: {=_xlfn.IFNA(_xlfn.IFS(summ[[#This Row],[LLC Hint]]<>"NotFound",summ[[#This Row],[LLC Hint]],summ[[#This Row],[Other]]<>"",summ[[#This Row],[Other]],AND(summ[[#This Row],[Top OrigReq]]="PortIn",summ[[#This Row],[Core Hint]]<>"NotFound"),summ[[#This Row],[Core Hint]],summ[[#This Row],[CHA Hint]]<>"NotFound",summ[[#This Row],[CHA Hint]],summ[[#This Row],[SrcIDs]]<>"NotFound","SrcID: "&summ[[#This Row],[SrcIDs]],summ[[#This Row],[Core Hint]]<>"NotFound",summ[[#This Row],[Core Hint]]),"")} -> PUNIT:EPRPUNIT0 | T2: =IF(summ[[#This Row],[Core Hint]]<>"NotFound",_xlfn.TEXTJOIN(" ",,"Disable CORE:",summ[[#This Row],[Core Hint]],"- MCAs:",summ[[#This Row],[Core Mcas]]),"") -> Disable CORE: CORE143 - MCAs: WDTimeout (3 strike) | U2: =IF(summ[[#This Row],[CHA Hint]]<>"NotFound",_xlfn.TEXTJOIN(" ",,"Disable CHA:",summ[[#This Row],[CHA Hint]],"- Signature:",summ[[#This Row],[Top OrigReq]],"-",summ[[#This Row],[Top ISMQ]],":",summ[[#This Row],[Top SAD LocPort]]),IF(summ[[#This Row],[SrcIDs]]<>"NotFound",_xlfn.TEXTJOIN(" ",,"Disable SrcID: ",summ[[#This Row],[SrcIDs]],"- Signature:",summ[[#This Row],[Top OrigReq]],"-",summ[[#This Row],[Top ISMQ]],":",summ[[#This Row],[Top SAD LocPort]]),"")) | V2: =IF(summ[[#This Row],[LLC Hint]]<>"NotFound",_xlfn.TEXTJOIN(" ",,"Disable LLC:",summ[[#This Row],[LLC Hint]]),"") | W2: =IF(summ[[#This Row],[Other]]<>"",_xlfn.TEXTJOIN(" ",,"Defeature:",summ[[#This Row],[Other]]," -- Check CORE or CHA MCAs for more data."),"") -> Defeature: PUNIT:EPRPUNIT0 -- Check CORE or CHA MCAs for more data. | X2: {=_xlfn.IFS(COUNTIF(summ[[#This Row],[Root Cause]],"CORE*")>0,summ[[#This Row],[Core Next Steps]],COUNTIF(summ[[#This Row],[Root Cause]],"LLC*")>0,summ[[#This Row],[LLC Next Steps]],(COUNTIF(summ[[#This Row],[Root Cause]],"CHA*")+COUNTIF(summ[[#This Row],[Root Cause]],"SrcID*"))>0,summ[[#This Row],[CHA Next Steps]],summ[[#This Row],[Root Cause]]<>"",summ[[#This Row],[Other Next Steps]],summ[[#This Row],[Root Cause]]="","")} -> Defeature: PUNIT:EPRPUNIT0 -- Check CORE or CHA MCAs for more data. | Y2: =_xlfn.TEXTJOIN(" - ",,IF(summ[[#This Row],[Core Fail Area]]<>"","CORE: "&summ[[#This Row],[Core Fail Area]],""),IF(summ[[#This Row],[CHA Fail Area]]<>"","CHA: "&summ[[#This Row],[CHA Fail Area]],""),IF(summ[[#This Row],[LLC Fail Area]]<>"","LLC: "&summ[[#This Row],[LLC Fail Area]],""))
A3: 759Y5U8800863 | B3: =_xlfn.XLOOKUP(summ[[#This Row],[VisualIDs]],ppv[Data.Visual_ID],ppv[Data.Step], "") | C3: =_xlfn.XLOOKUP(summ[[#This Row],[VisualIDs]],ppv[Data.Visual_ID],ppv[Data.Start_WW]) -> #N/A | D3: =_xlfn.XLOOKUP(summ[[#This Row],[VisualIDs]],REV_Units!A:A,REV_Units!F:F) -> 1 | E3: =_xlfn.XLOOKUP(summ[[#This Row],[VisualIDs]],REV_Units!A:A,REV_Units!G:G) -> CORE13 | F3: =_xlfn.XLOOKUP(summ[[#This Row],[VisualIDs]],REV_Units!A:A,REV_Units!H:H) | G3: =_xlfn.XLOOKUP(summ[[#This Row],[VisualIDs]],REV_Units!A:A,REV_Units!I:I) -> CHA134 | H3: =_xlfn.XLOOKUP(summ[[#This Row],[VisualIDs]],REV_Units!A:A,REV_Units!J:J) -> Compute2 : Row6 : Col2 | I3: =_xlfn.XLOOKUP(summ[[#This Row],[VisualIDs]],REV_Units!A:A,REV_Units!K:K) -> NotFound | J3: =_xlfn.XLOOKUP(summ[[#This Row],[VisualIDs]],REV_Units!A:A,REV_Units!L:L) | K3: =_xlfn.XLOOKUP(summ[[#This Row],[VisualIDs]],REV_Units!A:A,REV_Units!M:M) -> 10 | L3: =_xlfn.XLOOKUP(summ[[#This Row],[VisualIDs]],REV_Units!A:A,REV_Units!N:N) | M3: =_xlfn.XLOOKUP(summ[[#This Row],[VisualIDs]],REV_Units!A:A,REV_Units!O:O) -> WbMtoI | N3: =_xlfn.XLOOKUP(summ[[#This Row],[VisualIDs]],REV_Units!A:A,REV_Units!P:P) -> PullData | O3: =_xlfn.XLOOKUP(summ[[#This Row],[VisualIDs]],REV_Units!A:A,REV_Units!Q:Q) -> Ismq_Idle | P3: =_xlfn.XLOOKUP(summ[[#This Row],[VisualIDs]],REV_Units!A:A,REV_Units!R:R) -> HOM | Q3: =_xlfn.XLOOKUP(summ[[#This Row],[VisualIDs]],REV_Units!A:A,REV_Units!S:S) -> MEM4 | R3: =_xlfn.XLOOKUP(summ[[#This Row],[VisualIDs]],REV_Units!A:A,REV_Units!U:U) -> WDTimeout (3 strike) | S3: {=_xlfn.IFNA(_xlfn.IFS(summ[[#This Row],[LLC Hint]]<>"NotFound",summ[[#This Row],[LLC Hint]],summ[[#This Row],[Other]]<>"",summ[[#This Row],[Other]],AND(summ[[#This Row],[Top OrigReq]]="PortIn",summ[[#This Row],[Core Hint]]<>"NotFound"),summ[[#This Row],[Core Hint]],summ[[#This Row],[CHA Hint]]<>"NotFound",summ[[#This Row],[CHA Hint]],summ[[#This Row],[SrcIDs]]<>"NotFound","SrcID: "&summ[[#This Row],[SrcIDs]],summ[[#This Row],[Core Hint]]<>"NotFound",summ[[#This Row],[Core Hint]]),"")} -> CHA134 | T3: =IF(summ[[#This Row],[Core Hint]]<>"NotFound",_xlfn.TEXTJOIN(" ",,"Disable CORE:",summ[[#This Row],[Core Hint]],"- MCAs:",summ[[#This Row],[Core Mcas]]),"") -> Disable CORE: CORE13 - MCAs: WDTimeout (3 strike) | U3: =IF(summ[[#This Row],[CHA Hint]]<>"NotFound",_xlfn.TEXTJOIN(" ",,"Disable CHA:",summ[[#This Row],[CHA Hint]],"- Signature:",summ[[#This Row],[Top OrigReq]],"-",summ[[#This Row],[Top ISMQ]],":",summ[[#This Row],[Top SAD LocPort]]),IF(summ[[#This Row],[SrcIDs]]<>"NotFound",_xlfn.TEXTJOIN(" ",,"Disable SrcID: ",summ[[#This Row],[SrcIDs]],"- Signature:",summ[[#This Row],[Top OrigReq]],"-",summ[[#This Row],[Top ISMQ]],":",summ[[#This Row],[Top SAD LocPort]]),"")) -> Disable CHA: CHA134 - Signature: WbMtoI - Ismq_Idle : MEM4 | V3: =IF(summ[[#This Row],[LLC Hint]]<>"NotFound",_xlfn.TEXTJOIN(" ",,"Disable LLC:",summ[[#This Row],[LLC Hint]]),"") | W3: =IF(summ[[#This Row],[Other]]<>"",_xlfn.TEXTJOIN(" ",,"Defeature:",summ[[#This Row],[Other]]," -- Check CORE or CHA MCAs for more data."),"") | X3: {=_xlfn.IFS(COUNTIF(summ[[#This Row],[Root Cause]],"CORE*")>0,summ[[#This Row],[Core Next Steps]],COUNTIF(summ[[#This Row],[Root Cause]],"LLC*")>0,summ[[#This Row],[LLC Next Steps]],(COUNTIF(summ[[#This Row],[Root Cause]],"CHA*")+COUNTIF(summ[[#This Row],[Root Cause]],"SrcID*"))>0,summ[[#This Row],[CHA Next Steps]],summ[[#This Row],[Root Cause]]<>"",summ[[#This Row],[Other Next Steps]],summ[[#This Row],[Root Cause]]="","")} -> Disable CHA: CHA134 - Signature: WbMtoI - Ismq_Idle : MEM4 | Y3: =_xlfn.TEXTJOIN(" - ",,IF(summ[[#This Row],[Core Fail Area]]<>"","CORE: "&summ[[#This Row],[Core Fail Area]],""),IF(summ[[#This Row],[CHA Fail Area]]<>"","CHA: "&summ[[#This Row],[CHA Fail Area]],""),IF(summ[[#This Row],[LLC Fail Area]]<>"","LLC: "&summ[[#This Row],[LLC Fail Area]],"")) -> CHA: Compute2 : Row6 : Col2
A4: 74N24C5300241 | B4: =_xlfn.XLOOKUP(summ[[#This Row],[VisualIDs]],ppv[Data.Visual_ID],ppv[Data.Step], "") | C4: =_xlfn.XLOOKUP(summ[[#This Row],[VisualIDs]],ppv[Data.Visual_ID],ppv[Data.Start_WW]) -> #N/A | D4: =_xlfn.XLOOKUP(summ[[#This Row],[VisualIDs]],REV_Units!A:A,REV_Units!F:F) -> 3 | E4: =_xlfn.XLOOKUP(summ[[#This Row],[VisualIDs]],REV_Units!A:A,REV_Units!G:G) -> CORE17 | F4: =_xlfn.XLOOKUP(summ[[#This Row],[VisualIDs]],REV_Units!A:A,REV_Units!H:H) | G4: =_xlfn.XLOOKUP(summ[[#This Row],[VisualIDs]],REV_Units!A:A,REV_Units!I:I) -> CHA9 | H4: =_xlfn.XLOOKUP(summ[[#This Row],[VisualIDs]],REV_Units!A:A,REV_Units!J:J) | I4: =_xlfn.XLOOKUP(summ[[#This Row],[VisualIDs]],REV_Units!A:A,REV_Units!K:K) -> NotFound | J4: =_xlfn.XLOOKUP(summ[[#This Row],[VisualIDs]],REV_Units!A:A,REV_Units!L:L) | K4: =_xlfn.XLOOKUP(summ[[#This Row],[VisualIDs]],REV_Units!A:A,REV_Units!M:M) -> NotFound | L4: =_xlfn.XLOOKUP(summ[[#This Row],[VisualIDs]],REV_Units!A:A,REV_Units!N:N) -> UPI:pcie6 | M4: =_xlfn.XLOOKUP(summ[[#This Row],[VisualIDs]],REV_Units!A:A,REV_Units!O:O) -> DRd | N4: =_xlfn.XLOOKUP(summ[[#This Row],[VisualIDs]],REV_Units!A:A,REV_Units!P:P) -> RspI | O4: =_xlfn.XLOOKUP(summ[[#This Row],[VisualIDs]],REV_Units!A:A,REV_Units!Q:Q) -> Wdata_Wcmp_Split | P4: =_xlfn.XLOOKUP(summ[[#This Row],[VisualIDs]],REV_Units!A:A,REV_Units!R:R) -> HOM | Q4: =_xlfn.XLOOKUP(summ[[#This Row],[VisualIDs]],REV_Units!A:A,REV_Units!S:S) -> MEM0 | R4: =_xlfn.XLOOKUP(summ[[#This Row],[VisualIDs]],REV_Units!A:A,REV_Units!U:U) -> WDTimeout (3 strike), SQDB or IDI (addr / data) parity | S4: {=_xlfn.IFNA(_xlfn.IFS(summ[[#This Row],[LLC Hint]]<>"NotFound",summ[[#This Row],[LLC Hint]],summ[[#This Row],[Other]]<>"",summ[[#This Row],[Other]],AND(summ[[#This Row],[Top OrigReq]]="PortIn",summ[[#This Row],[Core Hint]]<>"NotFound"),summ[[#This Row],[Core Hint]],summ[[#This Row],[CHA Hint]]<>"NotFound",summ[[#This Row],[CHA Hint]],summ[[#This Row],[SrcIDs]]<>"NotFound","SrcID: "&summ[[#This Row],[SrcIDs]],summ[[#This Row],[Core Hint]]<>"NotFound",summ[[#This Row],[Core Hint]]),"")} -> UPI:pcie6 | T4: =IF(summ[[#This Row],[Core Hint]]<>"NotFound",_xlfn.TEXTJOIN(" ",,"Disable CORE:",summ[[#This Row],[Core Hint]],"- MCAs:",summ[[#This Row],[Core Mcas]]),"") -> Disable CORE: CORE17 - MCAs: WDTimeout (3 strike), SQDB or IDI (addr / data) parity | U4: =IF(summ[[#This Row],[CHA Hint]]<>"NotFound",_xlfn.TEXTJOIN(" ",,"Disable CHA:",summ[[#This Row],[CHA Hint]],"- Signature:",summ[[#This Row],[Top OrigReq]],"-",summ[[#This Row],[Top ISMQ]],":",summ[[#This Row],[Top SAD LocPort]]),IF(summ[[#This Row],[SrcIDs]]<>"NotFound",_xlfn.TEXTJOIN(" ",,"Disable SrcID: ",summ[[#This Row],[SrcIDs]],"- Signature:",summ[[#This Row],[Top OrigReq]],"-",summ[[#This Row],[Top ISMQ]],":",summ[[#This Row],[Top SAD LocPort]]),"")) -> Disable CHA: CHA9 - Signature: DRd - Wdata_Wcmp_Split : MEM0 | V4: =IF(summ[[#This Row],[LLC Hint]]<>"NotFound",_xlfn.TEXTJOIN(" ",,"Disable LLC:",summ[[#This Row],[LLC Hint]]),"") | W4: =IF(summ[[#This Row],[Other]]<>"",_xlfn.TEXTJOIN(" ",,"Defeature:",summ[[#This Row],[Other]]," -- Check CORE or CHA MCAs for more data."),"") -> Defeature: UPI:pcie6 -- Check CORE or CHA MCAs for more data. | X4: {=_xlfn.IFS(COUNTIF(summ[[#This Row],[Root Cause]],"CORE*")>0,summ[[#This Row],[Core Next Steps]],COUNTIF(summ[[#This Row],[Root Cause]],"LLC*")>0,summ[[#This Row],[LLC Next Steps]],(COUNTIF(summ[[#This Row],[Root Cause]],"CHA*")+COUNTIF(summ[[#This Row],[Root Cause]],"SrcID*"))>0,summ[[#This Row],[CHA Next Steps]],summ[[#This Row],[Root Cause]]<>"",summ[[#This Row],[Other Next Steps]],summ[[#This Row],[Root Cause]]="","")} -> Defeature: UPI:pcie6 -- Check CORE or CHA MCAs for more data. | Y4: =_xlfn.TEXTJOIN(" - ",,IF(summ[[#This Row],[Core Fail Area]]<>"","CORE: "&summ[[#This Row],[Core Fail Area]],""),IF(summ[[#This Row],[CHA Fail Area]]<>"","CHA: "&summ[[#This Row],[CHA Fail Area]],""),IF(summ[[#This Row],[LLC Fail Area]]<>"","LLC: "&summ[[#This Row],[LLC Fail Area]],""))
A5: 75W67Q6100508 | B5: =_xlfn.XLOOKUP(summ[[#This Row],[VisualIDs]],ppv[Data.Visual_ID],ppv[Data.Step], "") | C5: =_xlfn.XLOOKUP(summ[[#This Row],[VisualIDs]],ppv[Data.Visual_ID],ppv[Data.Start_WW]) -> #N/A | D5: =_xlfn.XLOOKUP(summ[[#This Row],[VisualIDs]],REV_Units!A:A,REV_Units!F:F) -> 1 | E5: =_xlfn.XLOOKUP(summ[[#This Row],[VisualIDs]],REV_Units!A:A,REV_Units!G:G) -> CORE168 | F5: =_xlfn.XLOOKUP(summ[[#This Row],[VisualIDs]],REV_Units!A:A,REV_Units!H:H) | G5: =_xlfn.XLOOKUP(summ[[#This Row],[VisualIDs]],REV_Units!A:A,REV_Units!I:I) -> CHA83 | H5: =_xlfn.XLOOKUP(summ[[#This Row],[VisualIDs]],REV_Units!A:A,REV_Units!J:J) | I5: =_xlfn.XLOOKUP(summ[[#This Row],[VisualIDs]],REV_Units!A:A,REV_Units!K:K) -> NotFound | J5: =_xlfn.XLOOKUP(summ[[#This Row],[VisualIDs]],REV_Units!A:A,REV_Units!L:L) | K5: =_xlfn.XLOOKUP(summ[[#This Row],[VisualIDs]],REV_Units!A:A,REV_Units!M:M) -> 110 | L5: =_xlfn.XLOOKUP(summ[[#This Row],[VisualIDs]],REV_Units!A:A,REV_Units!N:N) | M5: =_xlfn.XLOOKUP(summ[[#This Row],[VisualIDs]],REV_Units!A:A,REV_Units!O:O) -> CLDemote | N5: =_xlfn.XLOOKUP(summ[[#This Row],[VisualIDs]],REV_Units!A:A,REV_Units!P:P) -> CLDemote | O5: =_xlfn.XLOOKUP(summ[[#This Row],[VisualIDs]],REV_Units!A:A,REV_Units!Q:Q) -> Ismq_Idle | P5: =_xlfn.XLOOKUP(summ[[#This Row],[VisualIDs]],REV_Units!A:A,REV_Units!R:R) -> HOM | Q5: =_xlfn.XLOOKUP(summ[[#This Row],[VisualIDs]],REV_Units!A:A,REV_Units!S:S) -> MEM44 | R5: =_xlfn.XLOOKUP(summ[[#This Row],[VisualIDs]],REV_Units!A:A,REV_Units!U:U) -> WDTimeout (3 strike), 51488, 32520 | S5: {=_xlfn.IFNA(_xlfn.IFS(summ[[#This Row],[LLC Hint]]<>"NotFound",summ[[#This Row],[LLC Hint]],summ[[#This Row],[Other]]<>"",summ[[#This Row],[Other]],AND(summ[[#This Row],[Top OrigReq]]="PortIn",summ[[#This Row],[Core Hint]]<>"NotFound"),summ[[#This Row],[Core Hint]],summ[[#This Row],[CHA Hint]]<>"NotFound",summ[[#This Row],[CHA Hint]],summ[[#This Row],[SrcIDs]]<>"NotFound","SrcID: "&summ[[#This Row],[SrcIDs]],summ[[#This Row],[Core Hint]]<>"NotFound",summ[[#This Row],[Core Hint]]),"")} -> CHA83 | T5: =IF(summ[[#This Row],[Core Hint]]<>"NotFound",_xlfn.TEXTJOIN(" ",,"Disable CORE:",summ[[#This Row],[Core Hint]],"- MCAs:",summ[[#This Row],[Core Mcas]]),"") -> Disable CORE: CORE168 - MCAs: WDTimeout (3 strike), 51488, 32520 | U5: =IF(summ[[#This Row],[CHA Hint]]<>"NotFound",_xlfn.TEXTJOIN(" ",,"Disable CHA:",summ[[#This Row],[CHA Hint]],"- Signature:",summ[[#This Row],[Top OrigReq]],"-",summ[[#This Row],[Top ISMQ]],":",summ[[#This Row],[Top SAD LocPort]]),IF(summ[[#This Row],[SrcIDs]]<>"NotFound",_xlfn.TEXTJOIN(" ",,"Disable SrcID: ",summ[[#This Row],[SrcIDs]],"- Signature:",summ[[#This Row],[Top OrigReq]],"-",summ[[#This Row],[Top ISMQ]],":",summ[[#This Row],[Top SAD LocPort]]),"")) -> Disable CHA: CHA83 - Signature: CLDemote - Ismq_Idle : MEM44 | V5: =IF(summ[[#This Row],[LLC Hint]]<>"NotFound",_xlfn.TEXTJOIN(" ",,"Disable LLC:",summ[[#This Row],[LLC Hint]]),"") | W5: =IF(summ[[#This Row],[Other]]<>"",_xlfn.TEXTJOIN(" ",,"Defeature:",summ[[#This Row],[Other]]," -- Check CORE or CHA MCAs for more data."),"") | X5: {=_xlfn.IFS(COUNTIF(summ[[#This Row],[Root Cause]],"CORE*")>0,summ[[#This Row],[Core Next Steps]],COUNTIF(summ[[#This Row],[Root Cause]],"LLC*")>0,summ[[#This Row],[LLC Next Steps]],(COUNTIF(summ[[#This Row],[Root Cause]],"CHA*")+COUNTIF(summ[[#This Row],[Root Cause]],"SrcID*"))>0,summ[[#This Row],[CHA Next Steps]],summ[[#This Row],[Root Cause]]<>"",summ[[#This Row],[Other Next Steps]],summ[[#This Row],[Root Cause]]="","")} -> Disable CHA: CHA83 - Signature: CLDemote - Ismq_Idle : MEM44 | Y5: =_xlfn.TEXTJOIN(" - ",,IF(summ[[#This Row],[Core Fail Area]]<>"","CORE: "&summ[[#This Row],[Core Fail Area]],""),IF(summ[[#This Row],[CHA Fail Area]]<>"","CHA: "&summ[[#This Row],[CHA Fail Area]],""),IF(summ[[#This Row],[LLC Fail Area]]<>"","LLC: "&summ[[#This Row],[LLC Fail Area]],""))
A6: 75DE357100108 | B6: =_xlfn.XLOOKUP(summ[[#This Row],[VisualIDs]],ppv[Data.Visual_ID],ppv[Data.Step], "") | C6: =_xlfn.XLOOKUP(summ[[#This Row],[VisualIDs]],ppv[Data.Visual_ID],ppv[Data.Start_WW]) -> #N/A | D6: =_xlfn.XLOOKUP(summ[[#This Row],[VisualIDs]],REV_Units!A:A,REV_Units!F:F) -> 3 | E6: =_xlfn.XLOOKUP(summ[[#This Row],[VisualIDs]],REV_Units!A:A,REV_Units!G:G) -> NotFound | F6: =_xlfn.XLOOKUP(summ[[#This Row],[VisualIDs]],REV_Units!A:A,REV_Units!H:H) | G6: =_xlfn.XLOOKUP(summ[[#This Row],[VisualIDs]],REV_Units!A:A,REV_Units!I:I) -> NotFound | H6: =_xlfn.XLOOKUP(summ[[#This Row],[VisualIDs]],REV_Units!A:A,REV_Units!J:J) | I6: =_xlfn.XLOOKUP(summ[[#This Row],[VisualIDs]],REV_Units!A:A,REV_Units!K:K) -> NotFound | J6: =_xlfn.XLOOKUP(summ[[#This Row],[VisualIDs]],REV_Units!A:A,REV_Units!L:L) | K6: =_xlfn.XLOOKUP(summ[[#This Row],[VisualIDs]],REV_Units!A:A,REV_Units!M:M) -> 24 | L6: =_xlfn.XLOOKUP(summ[[#This Row],[VisualIDs]],REV_Units!A:A,REV_Units!N:N) -> UPI:pcie7, UPI:pcie4 | M6: =_xlfn.XLOOKUP(summ[[#This Row],[VisualIDs]],REV_Units!A:A,REV_Units!O:O) -> DRd | N6: =_xlfn.XLOOKUP(summ[[#This Row],[VisualIDs]],REV_Units!A:A,REV_Units!P:P) -> RspI | O6: =_xlfn.XLOOKUP(summ[[#This Row],[VisualIDs]],REV_Units!A:A,REV_Units!Q:Q) -> Wdata_Wcmp_Split | P6: =_xlfn.XLOOKUP(summ[[#This Row],[VisualIDs]],REV_Units!A:A,REV_Units!R:R) -> HOM | Q6: =_xlfn.XLOOKUP(summ[[#This Row],[VisualIDs]],REV_Units!A:A,REV_Units!S:S) -> MEM0 | R6: =_xlfn.XLOOKUP(summ[[#This Row],[VisualIDs]],REV_Units!A:A,REV_Units!U:U) -> WDTimeout (3 strike) | S6: {=_xlfn.IFNA(_xlfn.IFS(summ[[#This Row],[LLC Hint]]<>"NotFound",summ[[#This Row],[LLC Hint]],summ[[#This Row],[Other]]<>"",summ[[#This Row],[Other]],AND(summ[[#This Row],[Top OrigReq]]="PortIn",summ[[#This Row],[Core Hint]]<>"NotFound"),summ[[#This Row],[Core Hint]],summ[[#This Row],[CHA Hint]]<>"NotFound",summ[[#This Row],[CHA Hint]],summ[[#This Row],[SrcIDs]]<>"NotFound","SrcID: "&summ[[#This Row],[SrcIDs]],summ[[#This Row],[Core Hint]]<>"NotFound",summ[[#This Row],[Core Hint]]),"")} -> UPI:pcie7, UPI:pcie4 | T6: =IF(summ[[#This Row],[Core Hint]]<>"NotFound",_xlfn.TEXTJOIN(" ",,"Disable CORE:",summ[[#This Row],[Core Hint]],"- MCAs:",summ[[#This Row],[Core Mcas]]),"") | U6: =IF(summ[[#This Row],[CHA Hint]]<>"NotFound",_xlfn.TEXTJOIN(" ",,"Disable CHA:",summ[[#This Row],[CHA Hint]],"- Signature:",summ[[#This Row],[Top OrigReq]],"-",summ[[#This Row],[Top ISMQ]],":",summ[[#This Row],[Top SAD LocPort]]),IF(summ[[#This Row],[SrcIDs]]<>"NotFound",_xlfn.TEXTJOIN(" ",,"Disable SrcID: ",summ[[#This Row],[SrcIDs]],"- Signature:",summ[[#This Row],[Top OrigReq]],"-",summ[[#This Row],[Top ISMQ]],":",summ[[#This Row],[Top SAD LocPort]]),"")) -> Disable SrcID: 24 - Signature: DRd - Wdata_Wcmp_Split : MEM0 | V6: =IF(summ[[#This Row],[LLC Hint]]<>"NotFound",_xlfn.TEXTJOIN(" ",,"Disable LLC:",summ[[#This Row],[LLC Hint]]),"") | W6: =IF(summ[[#This Row],[Other]]<>"",_xlfn.TEXTJOIN(" ",,"Defeature:",summ[[#This Row],[Other]]," -- Check CORE or CHA MCAs for more data."),"") -> Defeature: UPI:pcie7, UPI:pcie4 -- Check CORE or CHA MCAs for more data. | X6: {=_xlfn.IFS(COUNTIF(summ[[#This Row],[Root Cause]],"CORE*")>0,summ[[#This Row],[Core Next Steps]],COUNTIF(summ[[#This Row],[Root Cause]],"LLC*")>0,summ[[#This Row],[LLC Next Steps]],(COUNTIF(summ[[#This Row],[Root Cause]],"CHA*")+COUNTIF(summ[[#This Row],[Root Cause]],"SrcID*"))>0,summ[[#This Row],[CHA Next Steps]],summ[[#This Row],[Root Cause]]<>"",summ[[#This Row],[Other Next Steps]],summ[[#This Row],[Root Cause]]="","")} -> Defeature: UPI:pcie7, UPI:pcie4 -- Check CORE or CHA MCAs for more data. | Y6: =_xlfn.TEXTJOIN(" - ",,IF(summ[[#This Row],[Core Fail Area]]<>"","CORE: "&summ[[#This Row],[Core Fail Area]],""),IF(summ[[#This Row],[CHA Fail Area]]<>"","CHA: "&summ[[#This Row],[CHA Fail Area]],""),IF(summ[[#This Row],[LLC Fail Area]]<>"","LLC: "&summ[[#This Row],[LLC Fail Area]],""))
A7: 759B5H7700068 | B7: =_xlfn.XLOOKUP(summ[[#This Row],[VisualIDs]],ppv[Data.Visual_ID],ppv[Data.Step], "") | C7: =_xlfn.XLOOKUP(summ[[#This Row],[VisualIDs]],ppv[Data.Visual_ID],ppv[Data.Start_WW]) -> #N/A | D7: =_xlfn.XLOOKUP(summ[[#This Row],[VisualIDs]],REV_Units!A:A,REV_Units!F:F) -> 3 | E7: =_xlfn.XLOOKUP(summ[[#This Row],[VisualIDs]],REV_Units!A:A,REV_Units!G:G) -> CORE149 | F7: =_xlfn.XLOOKUP(summ[[#This Row],[VisualIDs]],REV_Units!A:A,REV_Units!H:H) | G7: =_xlfn.XLOOKUP(summ[[#This Row],[VisualIDs]],REV_Units!A:A,REV_Units!I:I) -> CHA149 | H7: =_xlfn.XLOOKUP(summ[[#This Row],[VisualIDs]],REV_Units!A:A,REV_Units!J:J) | I7: =_xlfn.XLOOKUP(summ[[#This Row],[VisualIDs]],REV_Units!A:A,REV_Units!K:K) -> NotFound | J7: =_xlfn.XLOOKUP(summ[[#This Row],[VisualIDs]],REV_Units!A:A,REV_Units!L:L) | K7: =_xlfn.XLOOKUP(summ[[#This Row],[VisualIDs]],REV_Units!A:A,REV_Units!M:M) -> 99 | L7: =_xlfn.XLOOKUP(summ[[#This Row],[VisualIDs]],REV_Units!A:A,REV_Units!N:N) -> UPI:pcie6, UPI:pcie5 | M7: =_xlfn.XLOOKUP(summ[[#This Row],[VisualIDs]],REV_Units!A:A,REV_Units!O:O) -> SplitLock | N7: =_xlfn.XLOOKUP(summ[[#This Row],[VisualIDs]],REV_Units!A:A,REV_Units!P:P) -> RspI | O7: =_xlfn.XLOOKUP(summ[[#This Row],[VisualIDs]],REV_Units!A:A,REV_Units!Q:Q) -> Wcmp | P7: =_xlfn.XLOOKUP(summ[[#This Row],[VisualIDs]],REV_Units!A:A,REV_Units!R:R) -> SPECIAL | Q7: =_xlfn.XLOOKUP(summ[[#This Row],[VisualIDs]],REV_Units!A:A,REV_Units!S:S) -> UBOX | R7: =_xlfn.XLOOKUP(summ[[#This Row],[VisualIDs]],REV_Units!A:A,REV_Units!U:U) -> WDTimeout (3 strike) | S7: {=_xlfn.IFNA(_xlfn.IFS(summ[[#This Row],[LLC Hint]]<>"NotFound",summ[[#This Row],[LLC Hint]],summ[[#This Row],[Other]]<>"",summ[[#This Row],[Other]],AND(summ[[#This Row],[Top OrigReq]]="PortIn",summ[[#This Row],[Core Hint]]<>"NotFound"),summ[[#This Row],[Core Hint]],summ[[#This Row],[CHA Hint]]<>"NotFound",summ[[#This Row],[CHA Hint]],summ[[#This Row],[SrcIDs]]<>"NotFound","SrcID: "&summ[[#This Row],[SrcIDs]],summ[[#This Row],[Core Hint]]<>"NotFound",summ[[#This Row],[Core Hint]]),"")} -> UPI:pcie6, UPI:pcie5 | T7: =IF(summ[[#This Row],[Core Hint]]<>"NotFound",_xlfn.TEXTJOIN(" ",,"Disable CORE:",summ[[#This Row],[Core Hint]],"- MCAs:",summ[[#This Row],[Core Mcas]]),"") -> Disable CORE: CORE149 - MCAs: WDTimeout (3 strike) | U7: =IF(summ[[#This Row],[CHA Hint]]<>"NotFound",_xlfn.TEXTJOIN(" ",,"Disable CHA:",summ[[#This Row],[CHA Hint]],"- Signature:",summ[[#This Row],[Top OrigReq]],"-",summ[[#This Row],[Top ISMQ]],":",summ[[#This Row],[Top SAD LocPort]]),IF(summ[[#This Row],[SrcIDs]]<>"NotFound",_xlfn.TEXTJOIN(" ",,"Disable SrcID: ",summ[[#This Row],[SrcIDs]],"- Signature:",summ[[#This Row],[Top OrigReq]],"-",summ[[#This Row],[Top ISMQ]],":",summ[[#This Row],[Top SAD LocPort]]),"")) -> Disable CHA: CHA149 - Signature: SplitLock - Wcmp : UBOX | V7: =IF(summ[[#This Row],[LLC Hint]]<>"NotFound",_xlfn.TEXTJOIN(" ",,"Disable LLC:",summ[[#This Row],[LLC Hint]]),"") | W7: =IF(summ[[#This Row],[Other]]<>"",_xlfn.TEXTJOIN(" ",,"Defeature:",summ[[#This Row],[Other]]," -- Check CORE or CHA MCAs for more data."),"") -> Defeature: UPI:pcie6, UPI:pcie5 -- Check CORE or CHA MCAs for more data. | X7: {=_xlfn.IFS(COUNTIF(summ[[#This Row],[Root Cause]],"CORE*")>0,summ[[#This Row],[Core Next Steps]],COUNTIF(summ[[#This Row],[Root Cause]],"LLC*")>0,summ[[#This Row],[LLC Next Steps]],(COUNTIF(summ[[#This Row],[Root Cause]],"CHA*")+COUNTIF(summ[[#This Row],[Root Cause]],"SrcID*"))>0,summ[[#This Row],[CHA Next Steps]],summ[[#This Row],[Root Cause]]<>"",summ[[#This Row],[Other Next Steps]],summ[[#This Row],[Root Cause]]="","")} -> Defeature: UPI:pcie6, UPI:pcie5 -- Check CORE or CHA MCAs for more data. | Y7: =_xlfn.TEXTJOIN(" - ",,IF(summ[[#This Row],[Core Fail Area]]<>"","CORE: "&summ[[#This Row],[Core Fail Area]],""),IF(summ[[#This Row],[CHA Fail Area]]<>"","CHA: "&summ[[#This Row],[CHA Fail Area]],""),IF(summ[[#This Row],[LLC Fail Area]]<>"","LLC: "&summ[[#This Row],[LLC Fail Area]],""))
A8: 74SC153000062 | B8: =_xlfn.XLOOKUP(summ[[#This Row],[VisualIDs]],ppv[Data.Visual_ID],ppv[Data.Step], "") | C8: =_xlfn.XLOOKUP(summ[[#This Row],[VisualIDs]],ppv[Data.Visual_ID],ppv[Data.Start_WW]) -> #N/A | D8: =_xlfn.XLOOKUP(summ[[#This Row],[VisualIDs]],REV_Units!A:A,REV_Units!F:F) -> 4 | E8: =_xlfn.XLOOKUP(summ[[#This Row],[VisualIDs]],REV_Units!A:A,REV_Units!G:G) -> NotFound | F8: =_xlfn.XLOOKUP(summ[[#This Row],[VisualIDs]],REV_Units!A:A,REV_Units!H:H) | G8: =_xlfn.XLOOKUP(summ[[#This Row],[VisualIDs]],REV_Units!A:A,REV_Units!I:I) -> NotFound | H8: =_xlfn.XLOOKUP(summ[[#This Row],[VisualIDs]],REV_Units!A:A,REV_Units!J:J) | I8: =_xlfn.XLOOKUP(summ[[#This Row],[VisualIDs]],REV_Units!A:A,REV_Units!K:K) -> NotFound | J8: =_xlfn.XLOOKUP(summ[[#This Row],[VisualIDs]],REV_Units!A:A,REV_Units!L:L) | K8: =_xlfn.XLOOKUP(summ[[#This Row],[VisualIDs]],REV_Units!A:A,REV_Units!M:M) -> 47 | L8: =_xlfn.XLOOKUP(summ[[#This Row],[VisualIDs]],REV_Units!A:A,REV_Units!N:N) | M8: =_xlfn.XLOOKUP(summ[[#This Row],[VisualIDs]],REV_Units!A:A,REV_Units!O:O) -> WbMtoE | N8: =_xlfn.XLOOKUP(summ[[#This Row],[VisualIDs]],REV_Units!A:A,REV_Units!P:P) -> PullData | O8: =_xlfn.XLOOKUP(summ[[#This Row],[VisualIDs]],REV_Units!A:A,REV_Units!Q:Q) -> Ismq_Idle | P8: =_xlfn.XLOOKUP(summ[[#This Row],[VisualIDs]],REV_Units!A:A,REV_Units!R:R) -> HOM | Q8: =_xlfn.XLOOKUP(summ[[#This Row],[VisualIDs]],REV_Units!A:A,REV_Units!S:S) -> MEM2 | R8: =_xlfn.XLOOKUP(summ[[#This Row],[VisualIDs]],REV_Units!A:A,REV_Units!U:U) | S8: {=_xlfn.IFNA(_xlfn.IFS(summ[[#This Row],[LLC Hint]]<>"NotFound",summ[[#This Row],[LLC Hint]],summ[[#This Row],[Other]]<>"",summ[[#This Row],[Other]],AND(summ[[#This Row],[Top OrigReq]]="PortIn",summ[[#This Row],[Core Hint]]<>"NotFound"),summ[[#This Row],[Core Hint]],summ[[#This Row],[CHA Hint]]<>"NotFound",summ[[#This Row],[CHA Hint]],summ[[#This Row],[SrcIDs]]<>"NotFound","SrcID: "&summ[[#This Row],[SrcIDs]],summ[[#This Row],[Core Hint]]<>"NotFound",summ[[#This Row],[Core Hint]]),"")} -> SrcID: 47 | T8: =IF(summ[[#This Row],[Core Hint]]<>"NotFound",_xlfn.TEXTJOIN(" ",,"Disable CORE:",summ[[#This Row],[Core Hint]],"- MCAs:",summ[[#This Row],[Core Mcas]]),"") | U8: =IF(summ[[#This Row],[CHA Hint]]<>"NotFound",_xlfn.TEXTJOIN(" ",,"Disable CHA:",summ[[#This Row],[CHA Hint]],"- Signature:",summ[[#This Row],[Top OrigReq]],"-",summ[[#This Row],[Top ISMQ]],":",summ[[#This Row],[Top SAD LocPort]]),IF(summ[[#This Row],[SrcIDs]]<>"NotFound",_xlfn.TEXTJOIN(" ",,"Disable SrcID: ",summ[[#This Row],[SrcIDs]],"- Signature:",summ[[#This Row],[Top OrigReq]],"-",summ[[#This Row],[Top ISMQ]],":",summ[[#This Row],[Top SAD LocPort]]),"")) -> Disable SrcID: 47 - Signature: WbMtoE - Ismq_Idle : MEM2 | V8: =IF(summ[[#This Row],[LLC Hint]]<>"NotFound",_xlfn.TEXTJOIN(" ",,"Disable LLC:",summ[[#This Row],[LLC Hint]]),"") | W8: =IF(summ[[#This Row],[Other]]<>"",_xlfn.TEXTJOIN(" ",,"Defeature:",summ[[#This Row],[Other]]," -- Check CORE or CHA MCAs for more data."),"") | X8: {=_xlfn.IFS(COUNTIF(summ[[#This Row],[Root Cause]],"CORE*")>0,summ[[#This Row],[Core Next Steps]],COUNTIF(summ[[#This Row],[Root Cause]],"LLC*")>0,summ[[#This Row],[LLC Next Steps]],(COUNTIF(summ[[#This Row],[Root Cause]],"CHA*")+COUNTIF(summ[[#This Row],[Root Cause]],"SrcID*"))>0,summ[[#This Row],[CHA Next Steps]],summ[[#This Row],[Root Cause]]<>"",summ[[#This Row],[Other Next Steps]],summ[[#This Row],[Root Cause]]="","")} -> Disable SrcID: 47 - Signature: WbMtoE - Ismq_Idle : MEM2 | Y8: =_xlfn.TEXTJOIN(" - ",,IF(summ[[#This Row],[Core Fail Area]]<>"","CORE: "&summ[[#This Row],[Core Fail Area]],""),IF(summ[[#This Row],[CHA Fail Area]]<>"","CHA: "&summ[[#This Row],[CHA Fail Area]],""),IF(summ[[#This Row],[LLC Fail Area]]<>"","LLC: "&summ[[#This Row],[LLC Fail Area]],""))

Sheet CHA_MCAS
A2: Visual ID | B2: Run | C2: Operation | D2: CHA_MCNAME | E2: Compute | F2: CHA | G2: MC_STATUS | H2: MC_DECODE | I2: MC_ADDR | J2: MC_MISC | K2: MC_MISC3 | L2: Orig Req | M2: Opcode | N2: cachestate | O2: TorID | P2: TorFSM | Q2: SrcID | R2: ISMQ | S2: Attribute | T2: Result | U2: Local Port
A3: 74JU522300112 | B3: 7-1 | C3: 7682 | D3: DPMB_SOCKET1__COMPUTE0__UNCORE__CHA__CHA51__UTIL__MC_STATUS | E3: 0 | F3: CHA51 | G3: 0XFE000000000C110A | H3: TOR_TIMEOUT | I3: 0X40 | J3: 0X1700EE7800100086 | K3: 0X1106C22F01000C0 | L3: PortIn | M3: RspI | N3: LLC_I | O3: 30 | P3: 0 | Q3: 23 | R3: Wdata_Wcmp | S3: MMCFG | T3: IO | U3: PCIE0
A4: 74JU522300112 | B4: 10-1 | C4: 7682 | D4: DPMB_SOCKET1__COMPUTE1__UNCORE__CHA__CHA83__UTIL__MC_STATUS | E4: 1 | F4: CHA83 | G4: 0XFE000000000C110A | H4: TOR_TIMEOUT | I4: 0X40 | J4: 0X2B00EE7800100086 | K4: 0X1106C25701200C0 | L4: PortIn | M4: RspI | N4: LLC_I | O4: 30 | P4: 0 | Q4: 43 | R4: Wdata_Wcmp | S4: MMCFG | T4: IO | U4: PCIE0
A5: 759Y5U8800863 | B5: 5-1 | C5: 8748 | D5: DPMB_SOCKET0__COMPUTE2__UNCORE__CHA__CHA134__UTIL__MC_STATUS | E5: 2 | F5: CHA134 | G5: 0XBE000000000B017A | H5: CORE_WB_MISS_LLC | I5: 0X1FB2A7C180 | J5: 0X5D08C23802164086 | K5: 0X142140007600 | L5: WbMtoI | M5: PullData | N5: LLC_M | O5: 14 | P5: 2 | Q5: 10 | R5: Ismq_Idle | S5: DRAM | T5: HOM | U5: MEM4
A6: 74N24C5300241 | B6: 2-1 | C6: 7681 | D6: DPMB_SOCKET0__COMPUTE0__UNCORE__CHA__CHA0__UTIL__MC_STATUS | E6: 0 | F6: CHA0 | G6: 0XFE000000000C1136 | H6: TOR_TIMEOUT | I6: 0X61C296B740 | J6: 0X1C802C00100886 | K6: 0X1C00C2D00430000 | L6: RFO | M6: RspI | N6: LLC_I | O6: 11 | P6: 7 | Q6: 104 | R6: Wdata_Wcmp_Split | S6: DRAM | T6: HOM | U6: MEM0
A7: 74N24C5300241 | B7: 2-1 | C7: 7681 | D7: DPMB_SOCKET0__COMPUTE0__UNCORE__CHA__CHA13__UTIL__MC_STATUS | E7: 0 | F7: CHA13 | G7: 0XFE000000000C1136 | H7: TOR_TIMEOUT | I7: 0X7C71423340 | J7: 0XA3C811000100886 | K7: 0X1C00C21A042E007 | L7: DRd | M7: RspI | N7: LLC_I | O7: 4 | P7: 15 | Q7: 13 | R7: Wdata_Wcmp_Split | S7: DRAM | T7: HOM | U7: MEM0
A8: 74N24C5300241 | B8: 2-1 | C8: 7681 | D8: DPMB_SOCKET0__COMPUTE0__UNCORE__CHA__CHA14__UTIL__MC_STATUS | E8: 0 | F8: CHA14 | G8: 0XFE000000000C1136 | H8: TOR_TIMEOUT | I8: 0X37BC73900 | J8: 0XE1C801800100886 | K8: 0X1C0102840024006 | L8: RFO | M8: RspI | N8: LLC_I | O8: 6 | P8: 7 | Q8: 66 | R8: Wdata_Wcmp_Split | S8: DRAM | T8: HOM | U8: MEM2
A9: 74N24C5300241 | B9: 2-1 | C9: 7681 | D9: DPMB_SOCKET0__COMPUTE0__UNCORE__CHA__CHA15__UTIL__MC_STATUS | E9: 0 | F9: CHA15 | G9: 0XFE000000000C1136 | H9: TOR_TIMEOUT | I9: 0X6D14B7F040 | J9: 0X113C817800100886 | K9: 0X1C00C2C40402000 | L9: DRd | M9: RspI | N9: LLC_I | O9: 30 | P9: 15 | Q9: 98 | R9: Wdata_Wcmp_Split | S9: DRAM | T9: HOM | U9: MEM0
A10: 74N24C5300241 | B10: 2-1 | C10: 7681 | D10: DPMB_SOCKET0__COMPUTE0__UNCORE__CHA__CHA16__UTIL__MC_STATUS | E10: 0 | F10: CHA16 | G10: 0XFE000000000C1136 | H10: TOR_TIMEOUT | I10: 0X6F856A2B40 | J10: 0X33C810400100886 | K10: 0X1C00C2420426002 | L10: DRd | M10: RspI | N10: LLC_I | O10: 1 | P10: 15 | Q10: 33 | R10: Wdata_Wcmp_Split | S10: DRAM | T10: HOM | U10: MEM0
A11: 74N24C5300241 | B11: 2-1 | C11: 7681 | D11: DPMB_SOCKET0__COMPUTE0__UNCORE__CHA__CHA17__UTIL__MC_STATUS | E11: 0 | F11: CHA17 | G11: 0XFE000000000C1136 | H11: TOR_TIMEOUT | I11: 0X7BC51C6C40 | J11: 0X73C811400100886 | K11: 0X1C00C2740406006 | L11: DRd | M11: RspI | N11: LLC_I | O11: 5 | P11: 15 | Q11: 58 | R11: Wdata_Wcmp_Split | S11: DRAM | T11: HOM | U11: MEM0
A12: 74N24C5300241 | B12: 2-1 | C12: 7681 | D12: DPMB_SOCKET0__COMPUTE0__UNCORE__CHA__CHA1__UTIL__MC_STATUS | E12: 0 | F12: CHA1 | G12: 0XFE000000000C1136 | H12: TOR_TIMEOUT | I12: 0X77B410B5C0 | J12: 0X53C811800100886 | K12: 0X1C00C2900426000 | L12: DRd | M12: RspI | N12: LLC_I | O12: 6 | P12: 15 | Q12: 72 | R12: Wdata_Wcmp_Split | S12: DRAM | T12: HOM | U12: MEM0
A13: 74N24C5300241 | B13: 2-1 | C13: 7681 | D13: DPMB_SOCKET0__COMPUTE0__UNCORE__CHA__CHA20__UTIL__MC_STATUS | E13: 0 | F13: CHA20 | G13: 0XFE000000000C017A | H13: TOR_TIMEOUT | I13: 0X6CC76EB740 | J13: 0XB00C20800160086 | K13: 0X800C2BA0430885 | L13: WbMtoI | M13: RspI | N13: LLC_M | O13: 2 | P13: 0 | Q13: 93 | R13: Wcmp | S13: DRAM | T13: HOM | U13: MEM0
A14: 74N24C5300241 | B14: 2-1 | C14: 7681 | D14: DPMB_SOCKET0__COMPUTE0__UNCORE__CHA__CHA21__UTIL__MC_STATUS | E14: 0 | F14: CHA21 | G14: 0XFE000000000C1136 | H14: TOR_TIMEOUT | I14: 0X7682878B40 | J14: 0XF3C811000100886 | K14: 0X1C00C218040A004 | L14: DRd | M14: RspI | N14: LLC_I | O14: 4 | P14: 15 | Q14: 12 | R14: Wdata_Wcmp_Split | S14: DRAM | T14: HOM | U14: MEM0
... A921: 75W67Q6100508 | B921: 5-1 | C921: 8748 | D921: DPMB_SOCKET0__COMPUTE1__UNCORE__CHA__CHA83__UTIL__MC_STATUS | E921: 1 | F921: CHA83 | G921: 0XBE000000001F0405 | H921: ADDR_PARITY_ERROR | I921: 0X3F90E0B0DF40 | J921: 0X2C00C078C0100486 | K921: 0X6C2DDC108000 | L921: CLDemote | M921: CLDemote | N921: LLC_I | O921: 30 | P921: 0 | Q921: 110 | R921: Ismq_Idle | S921: MMCFG | T921: ABORT | U921: PCIE0

Sheet LLC
A1: VisualID | B1: Run | C1: Operation | D1: LLC_MC | E1: Compute | F1: LLC | G1: MC_STATUS | H1: MC DECODE | I1: MC_ADDR | J1: MC_MISC | K1: MiscV | L1: RSF | M1: LSF | N1: LLC_misc

Sheet CORE
A1: VisualID | B1: Run | C1: Operation | D1: CORE_MC | E1: Compute | F1: CORE | G1: ErrorType | H1: MC_STATUS | I1: MCACOD (ErrDecode) | J1: MSCOD | K1: MC_ADDR | L1: MC_MISC
A2: 759Y5U8800863 | B2: 4-1 | C2: 8749 | D2: DPMB_SOCKET0__COMPUTE0__CPU__CORE10__ML2_CR_MC3_STATUS | E2: 0 | F2: CORE10 | G2: ML2 | H2: 0XFE000000E1CC0400 | I2: WDTimeout (3 strike) | J2: TimeOutThread:0,ActiveThreads:3,XQ Empty:1,LQ Empty:1,SnpQ Empty:1,No U2C Req Credit:0,No C2U Credits:0,ExtCmpCntIsZero:1,FBVCntIsZero:1,VirtLLC Prefetch:1, | K2: 0XAC7E | L2: 0XAC7E
A3: 759Y5U8800863 | B3: 4-1 | C3: 8749 | D3: DPMB_SOCKET0__COMPUTE0__CPU__CORE13__ML2_CR_MC3_STATUS | E3: 0 | F3: CORE13 | G3: ML2 | H3: 0XBE000000E1CD0400 | I3: WDTimeout (3 strike) | J3: TimeOutThread:1,ActiveThreads:3,XQ Empty:1,LQ Empty:1,SnpQ Empty:1,No U2C Req Credit:0,No C2U Credits:0,ExtCmpCntIsZero:1,FBVCntIsZero:1,VirtLLC Prefetch:1, | K3: 0XFFFFBA984281E9FF | L3: 0XFFFFBA984281E9FF
A4: 759Y5U8800863 | B4: 4-1 | C4: 8749 | D4: DPMB_SOCKET0__COMPUTE0__CPU__CORE14__ML2_CR_MC3_STATUS | E4: 0 | F4: CORE14 | G4: ML2 | H4: 0XFE000000E1CC0400 | I4: WDTimeout (3 strike) | J4: TimeOutThread:0,ActiveThreads:3,XQ Empty:1,LQ Empty:1,SnpQ Empty:1,No U2C Req Credit:0,No C2U Credits:0,ExtCmpCntIsZero:1,FBVCntIsZero:1,VirtLLC Prefetch:1, | K4: 0XAC7E | L4: 0XAC7E
A5: 759Y5U8800863 | B5: 4-1 | C5: 8749 | D5: DPMB_SOCKET0__COMPUTE0__CPU__CORE15__ML2_CR_MC3_STATUS | E5: 0 | F5: CORE15 | G5: ML2 | H5: 0XFE000000E1CC0400 | I5: WDTimeout (3 strike) | J5: TimeOutThread:0,ActiveThreads:3,XQ Empty:1,LQ Empty:1,SnpQ Empty:1,No U2C Req Credit:0,No C2U Credits:0,ExtCmpCntIsZero:1,FBVCntIsZero:1,VirtLLC Prefetch:1, | K5: 0XAC7E | L5: 0XAC7E
A6: 759Y5U8800863 | B6: 4-1 | C6: 8749 | D6: DPMB_SOCKET0__COMPUTE0__CPU__CORE17__ML2_CR_MC3_STATUS | E6: 0 | F6: CORE17 | G6: ML2 | H6: 0XFE000000E1CC0400 | I6: WDTimeout (3 strike) | J6: TimeOutThread:0,ActiveThreads:3,XQ Empty:1,LQ Empty:1,SnpQ Empty:1,No U2C Req Credit:0,No C2U Credits:0,ExtCmpCntIsZero:1,FBVCntIsZero:1,VirtLLC Prefetch:1, | K6: 0XAC7E | L6: 0XAC7E
A7: 759Y5U8800863 | B7: 4-1 | C7: 8749 | D7: DPMB_SOCKET0__COMPUTE0__CPU__CORE1__ML2_CR_MC3_STATUS | E7: 0 | F7: CORE1 | G7: ML2 | H7: 0XFE000000E1CC0400 | I7: WDTimeout (3 strike) | J7: TimeOutThread:0,ActiveThreads:3,XQ Empty:1,LQ Empty:1,SnpQ Empty:1,No U2C Req Credit:0,No C2U Credits:0,ExtCmpCntIsZero:1,FBVCntIsZero:1,VirtLLC Prefetch:1, | K7: 0XAC7E | L7: 0XAC7E
A8: 759Y5U8800863 | B8: 4-1 | C8: 8749 | D8: DPMB_SOCKET0__COMPUTE0__CPU__CORE21__ML2_CR_MC3_STATUS | E8: 0 | F8: CORE21 | G8: ML2 | H8: 0XFE000000E1CC0400 | I8: WDTimeout (3 strike) | J8: TimeOutThread:0,ActiveThreads:3,XQ Empty:1,LQ Empty:1,SnpQ Empty:1,No U2C Req Credit:0,No C2U Credits:0,ExtCmpCntIsZero:1,FBVCntIsZero:1,VirtLLC Prefetch:1, | K8: 0XAC7E | L8: 0XAC7E
A9: 759Y5U8800863 | B9: 4-1 | C9: 8749 | D9: DPMB_SOCKET0__COMPUTE0__CPU__CORE22__ML2_CR_MC3_STATUS | E9: 0 | F9: CORE22 | G9: ML2 | H9: 0XFE000000E1CC0400 | I9: WDTimeout (3 strike) | J9: TimeOutThread:0,ActiveThreads:3,XQ Empty:1,LQ Empty:1,SnpQ Empty:1,No U2C Req Credit:0,No C2U Credits:0,ExtCmpCntIsZero:1,FBVCntIsZero:1,VirtLLC Prefetch:1, | K9: 0XAC7E | L9: 0XAC7E
A10: 759Y5U8800863 | B10: 4-1 | C10: 8749 | D10: DPMB_SOCKET0__COMPUTE0__CPU__CORE23__ML2_CR_MC3_STATUS | E10: 0 | F10: CORE23 | G10: ML2 | H10: 0XFE000000E1CC0400 | I10: WDTimeout (3 strike) | J10: TimeOutThread:0,ActiveThreads:3,XQ Empty:1,LQ Empty:1,SnpQ Empty:1,No U2C Req Credit:0,No C2U Credits:0,ExtCmpCntIsZero:1,FBVCntIsZero:1,VirtLLC Prefetch:1, | K10: 0XAC7E | L10: 0XAC7E
A11: 759Y5U8800863 | B11: 4-1 | C11: 8749 | D11: DPMB_SOCKET0__COMPUTE0__CPU__CORE24__ML2_CR_MC3_STATUS | E11: 0 | F11: CORE24 | G11: ML2 | H11: 0XFE000000E1CC0400 | I11: WDTimeout (3 strike) | J11: TimeOutThread:0,ActiveThreads:3,XQ Empty:1,LQ Empty:1,SnpQ Empty:1,No U2C Req Credit:0,No C2U Credits:0,ExtCmpCntIsZero:1,FBVCntIsZero:1,VirtLLC Prefetch:1, | K11: 0XAC7E | L11: 0XAC7E
A12: 759Y5U8800863 | B12: 4-1 | C12: 8749 | D12: DPMB_SOCKET0__COMPUTE0__CPU__CORE27__ML2_CR_MC3_STATUS | E12: 0 | F12: CORE27 | G12: ML2 | H12: 0XFE000000E1CC0400 | I12: WDTimeout (3 strike) | J12: TimeOutThread:0,ActiveThreads:3,XQ Empty:1,LQ Empty:1,SnpQ Empty:1,No U2C Req Credit:0,No C2U Credits:0,ExtCmpCntIsZero:1,FBVCntIsZero:1,VirtLLC Prefetch:1, | K12: 0XAC7E | L12: 0XAC7E
... A98: 759Y5U8800863 | B98: 3-1 | C98: 8749 | D98: DPMB_SOCKET0__COMPUTE0__CPU__CORE10__ML2_CR_MC3_STATUS | E98: 0 | F98: CORE10 | G98: ML2 | H98: 0XFE000000E1CC0400 | I98: WDTimeout (3 strike) | J98: TimeOutThread:0,ActiveThreads:3,XQ Empty:1,LQ Empty:1,SnpQ Empty:1,No U2C Req Credit:0,No C2U Credits:0,ExtCmpCntIsZero:1,FBVCntIsZero:1,VirtLLC Prefetch:1, | K98: 0XAC7E | L98: 0XAC7E
A99: 759Y5U8800863 | B99: 3-1 | C99: 8749 | D99: DPMB_SOCKET0__COMPUTE0__CPU__CORE13__ML2_CR_MC3_STATUS | E99: 0 | F99: CORE13 | G99: ML2 | H99: 0XF2000000E1CD0400 | I99: WDTimeout (3 strike) | J99: TimeOutThread:1,ActiveThreads:3,XQ Empty:1,LQ Empty:1,SnpQ Empty:1,No U2C Req Credit:0,No C2U Credits:0,ExtCmpCntIsZero:1,FBVCntIsZero:1,VirtLLC Prefetch:1,
A100: 759Y5U8800863 | B100: 3-1 | C100: 8749 | D100: DPMB_SOCKET0__COMPUTE0__CPU__CORE14__ML2_CR_MC3_STATUS | E100: 0 | F100: CORE14 | G100: ML2 | H100: 0XFE000000E1CC0400 | I100: WDTimeout (3 strike) | J100: TimeOutThread:0,ActiveThreads:3,XQ Empty:1,LQ Empty:1,SnpQ Empty:1,No U2C Req Credit:0,No C2U Credits:0,ExtCmpCntIsZero:1,FBVCntIsZero:1,VirtLLC Prefetch:1, | K100: 0XAC7E | L100: 0XAC7E
A101: 759Y5U8800863 | B101: 3-1 | C101: 8749 | D101: DPMB_SOCKET0__COMPUTE0__CPU__CORE15__ML2_CR_MC3_STATUS | E101: 0 | F101: CORE15 | G101: ML2 | H101: 0XFE000000E1CC0400 | I101: WDTimeout (3 strike) | J101: TimeOutThread:0,ActiveThreads:3,XQ Empty:1,LQ Empty:1,SnpQ Empty:1,No U2C Req Credit:0,No C2U Credits:0,ExtCmpCntIsZero:1,FBVCntIsZero:1,VirtLLC Prefetch:1, | K101: 0XAC7E | L101: 0XAC7E
A102: 759Y5U8800863 | B102: 3-1 | C102: 8749 | D102: DPMB_SOCKET0__COMPUTE0__CPU__CORE17__ML2_CR_MC3_STATUS | E102: 0 | F102: CORE17 | G102: ML2 | H102: 0XFE000000E1CC0400 | I102: WDTimeout (3 strike) | J102: TimeOutThread:0,ActiveThreads:3,XQ Empty:1,LQ Empty:1,SnpQ Empty:1,No U2C Req Credit:0,No C2U Credits:0,ExtCmpCntIsZero:1,FBVCntIsZero:1,VirtLLC Prefetch:1, | K102: 0XAC7E | L102: 0XAC7E
A103: 759Y5U8800863 | B103: 3-1 | C103: 8749 | D103: DPMB_SOCKET0__COMPUTE0__CPU__CORE1__ML2_CR_MC3_STATUS | E103: 0 | F103: CORE1 | G103: ML2 | H103: 0XFE000000E1CC0400 | I103: WDTimeout (3 strike) | J103: TimeOutThread:0,ActiveThreads:3,XQ Empty:1,LQ Empty:1,SnpQ Empty:1,No U2C Req Credit:0,No C2U Credits:0,ExtCmpCntIsZero:1,FBVCntIsZero:1,VirtLLC Prefetch:1, | K103: 0XAC7E | L103: 0XAC7E
A104: 759Y5U8800863 | B104: 3-1 | C104: 8749 | D104: DPMB_SOCKET0__COMPUTE0__CPU__CORE21__ML2_CR_MC3_STATUS | E104: 0 | F104: CORE21 | G104: ML2 | H104: 0XFE000000E1CC0400 | I104: WDTimeout (3 strike) | J104: TimeOutThread:0,ActiveThreads:3,XQ Empty:1,LQ Empty:1,SnpQ Empty:1,No U2C Req Credit:0,No C2U Credits:0,ExtCmpCntIsZero:1,FBVCntIsZero:1,VirtLLC Prefetch:1, | K104: 0XAC7E | L104: 0XAC7E
A105: 759Y5U8800863 | B105: 3-1 | C105: 8749 | D105: DPMB_SOCKET0__COMPUTE0__CPU__CORE22__ML2_CR_MC3_STATUS | E105: 0 | F105: CORE22 | G105: ML2 | H105: 0XFE000000E1CD0400 | I105: WDTimeout (3 strike) | J105: TimeOutThread:1,ActiveThreads:3,XQ Empty:1,LQ Empty:1,SnpQ Empty:1,No U2C Req Credit:0,No C2U Credits:0,ExtCmpCntIsZero:1,FBVCntIsZero:1,VirtLLC Prefetch:1, | K105: 0XAC7E | L105: 0XAC7E
A106: 759Y5U8800863 | B106: 3-1 | C106: 8749 | D106: DPMB_SOCKET0__COMPUTE0__CPU__CORE23__ML2_CR_MC3_STATUS | E106: 0 | F106: CORE23 | G106: ML2 | H106: 0XFE000000E1CC0400 | I106: WDTimeout (3 strike) | J106: TimeOutThread:0,ActiveThreads:3,XQ Empty:1,LQ Empty:1,SnpQ Empty:1,No U2C Req Credit:0,No C2U Credits:0,ExtCmpCntIsZero:1,FBVCntIsZero:1,VirtLLC Prefetch:1, | K106: 0XAC7E | L106: 0XAC7E
A107: 759Y5U8800863 | B107: 3-1 | C107: 8749 | D107: DPMB_SOCKET0__COMPUTE0__CPU__CORE24__ML2_CR_MC3_STATUS | E107: 0 | F107: CORE24 | G107: ML2 | H107: 0XFE000000E1CC0400 | I107: WDTimeout (3 strike) | J107: TimeOutThread:0,ActiveThreads:3,XQ Empty:1,LQ Empty:1,SnpQ Empty:1,No U2C Req Credit:0,No C2U Credits:0,ExtCmpCntIsZero:1,FBVCntIsZero:1,VirtLLC Prefetch:1, | K107: 0XAC7E | L107: 0XAC7E
A108: 759Y5U8800863 | B108: 3-1 | C108: 8749 | D108: DPMB_SOCKET0__COMPUTE0__CPU__CORE27__ML2_CR_MC3_STATUS | E108: 0 | F108: CORE27 | G108: ML2 | H108: 0XFE000000E1CC0400 | I108: WDTimeout (3 strike) | J108: TimeOutThread:0,ActiveThreads:3,XQ Empty:1,LQ Empty:1,SnpQ Empty:1,No U2C Req Credit:0,No C2U Credits:0,ExtCmpCntIsZero:1,FBVCntIsZero:1,VirtLLC Prefetch:1, | K108: 0XAC7E | L108: 0XAC7E
A109: 759Y5U8800863 | B109: 3-1 | C109: 8749 | D109: DPMB_SOCKET0__COMPUTE0__CPU__CORE28__ML2_CR_MC3_STATUS | E109: 0 | F109: CORE28 | G109: ML2 | H109: 0XFE000000E1CC0400 | I109: WDTimeout (3 strike) | J109: TimeOutThread:0,ActiveThreads:3,XQ Empty:1,LQ Empty:1,SnpQ Empty:1,No U2C Req Credit:0,No C2U Credits:0,ExtCmpCntIsZero:1,FBVCntIsZero:1,VirtLLC Prefetch:1, | K109: 0XAC7E | L109: 0XAC7E
A110: 759Y5U8800863 | B110: 3-1 | C110: 8749 | D110: DPMB_SOCKET0__COMPUTE0__CPU__CORE29__ML2_CR_MC3_STATUS | E110: 0 | F110: CORE29 | G110: ML2 | H110: 0XFE000000E1CC0400 | I110: WDTimeout (3 strike) | J110: TimeOutThread:0,ActiveThreads:3,XQ Empty:1,LQ Empty:1,SnpQ Empty:1,No U2C Req Credit:0,No C2U Credits:0,ExtCmpCntIsZero:1,FBVCntIsZero:1,VirtLLC Prefetch:1, | K110: 0XAC7E | L110: 0XAC7E
A111: 759Y5U8800863 | B111: 3-1 | C111: 8749 | D111: DPMB_SOCKET0__COMPUTE0__CPU__CORE2__ML2_CR_MC3_STATUS | E111: 0 | F111: CORE2 | G111: ML2 | H111: 0XFE000000E1CC0400 | I111: WDTimeout (3 strike) | J111: TimeOutThread:0,ActiveThreads:3,XQ Empty:1,LQ Empty:1,SnpQ Empty:1,No U2C Req Credit:0,No C2U Credits:0,ExtCmpCntIsZero:1,FBVCntIsZero:1,VirtLLC Prefetch:1, | K111: 0X5F9E2238 | L111: 0X5F9E2238
... A386: 75W67Q6100508 | B386: 5-1 | C386: 8748 | D386: DPMB_SOCKET0__COMPUTE2__CPU__CORE179__ML2_CR_MC3_STATUS | E386: 2 | F386: CORE179 | G386: ML2 | H386: 0XBE000000E1CC0400 | I386: WDTimeout (3 strike) | J386: TimeOutThread:0,ActiveThreads:3,XQ Empty:1,LQ Empty:1,SnpQ Empty:1,No U2C Req Credit:0,No C2U Credits:0,ExtCmpCntIsZero:1,FBVCntIsZero:1,VirtLLC Prefetch:1, | K386: 0XFFFFFFFF8E04C5D2 | L386: 0XFFFFFFFF8E04C5D2
A387: 75W67Q6100508 | B387: 5-1 | C387: 8748 | D387: DPMB_SOCKET0__COMPUTE2__CPU__CORE168__THREAD0__IFU_CR_MC0_STATUS | E387: 2 | F387: CORE168 | G387: IFU | H387: 0X10301D9F6837C920 | I387: 51488 | J387: 55 | L387: 0X8404787DBE48FC3C
A388: 75W67Q6100508 | B388: 5-1 | C388: 8748 | D388: DPMB_SOCKET0__COMPUTE2__CPU__CORE168__THREAD1__IFU_CR_MC0_STATUS | E388: 2 | F388: CORE168 | G388: IFU | H388: 0XE30FFFAFFFF87F08 | I388: 32520 | J388: 248 | L388: 0XF193FFFFF93A7FFF
A389: 74N24C5300241 | B389: 2-1 | C389: 7681 | D389: DPMB_SOCKET0__COMPUTE0__CPU__CORE0__ML2_CR_MC3_STATUS | E389: 0 | F389: CORE0 | G389: ML2 | H389: 0XFE000000F18D0400 | I389: WDTimeout (3 strike) | J389: TimeOutThread:1,ActiveThreads:3,XQ Empty:0,LQ Empty:1,SnpQ Empty:1,No U2C Req Credit:0,No C2U Credits:4,ExtCmpCntIsZero:1,FBVCntIsZero:1,VirtLLC Prefetch:1, | K389: 0XFFFFFF7F12EAEA41 | L389: 0XFFFFFF7F12EAEA41
A390: 74N24C5300241 | B390: 2-1 | C390: 7681 | D390: DPMB_SOCKET0__COMPUTE0__CPU__CORE14__ML2_CR_MC3_STATUS | E390: 0 | F390: CORE14 | G390: ML2 | H390: 0XFE000000F18D0400 | I390: WDTimeout (3 strike) | J390: TimeOutThread:1,ActiveThreads:3,XQ Empty:0,LQ Empty:1,SnpQ Empty:1,No U2C Req Credit:0,No C2U Credits:4,ExtCmpCntIsZero:1,FBVCntIsZero:1,VirtLLC Prefetch:1, | K390: 0XFFFFFFFF4405FDF7 | L390: 0XFFFFFFFF4405FDF7
A391: 74N24C5300241 | B391: 2-1 | C391: 7681 | D391: DPMB_SOCKET0__COMPUTE0__CPU__CORE16__ML2_CR_MC3_STATUS | E391: 0 | F391: CORE16 | G391: ML2 | H391: 0XFE000000E18D0400 | I391: WDTimeout (3 strike) | J391: TimeOutThread:1,ActiveThreads:3,XQ Empty:0,LQ Empty:1,SnpQ Empty:1,No U2C Req Credit:0,No C2U Credits:0,ExtCmpCntIsZero:1,FBVCntIsZero:1,VirtLLC Prefetch:1, | K391: 0XFFFFFFFF12EAEA41 | L391: 0XFFFFFFFF12EAEA41
A392: 74N24C5300241 | B392: 2-1 | C392: 7681 | D392: DPMB_SOCKET0__COMPUTE0__CPU__CORE17__ML2_CR_MC3_STATUS | E392: 0 | F392: CORE17 | G392: ML2 | H392: 0XFE000000F18D0400 | I392: WDTimeout (3 strike) | J392: TimeOutThread:1,ActiveThreads:3,XQ Empty:0,LQ Empty:1,SnpQ Empty:1,No U2C Req Credit:0,No C2U Credits:4,ExtCmpCntIsZero:1,FBVCntIsZero:1,VirtLLC Prefetch:1, | K392: 0XFFFFFFFF12EAE8CA | L392: 0XFFFFFFFF12EAE8CA
A393: 74N24C5300241 | B393: 2-1 | C393: 7681 | D393: DPMB_SOCKET0__COMPUTE0__CPU__CORE1__ML2_CR_MC3_STATUS | E393: 0 | F393: CORE1 | G393: ML2 | H393: 0XF2000000F10D0400 | I393: WDTimeout (3 strike) | J393: TimeOutThread:1,ActiveThreads:3,XQ Empty:0,LQ Empty:0,SnpQ Empty:1,No U2C Req Credit:0,No C2U Credits:4,ExtCmpCntIsZero:1,FBVCntIsZero:1,VirtLLC Prefetch:1,
A394: 74N24C5300241 | B394: 2-1 | C394: 7681 | D394: DPMB_SOCKET0__COMPUTE0__CPU__CORE20__ML2_CR_MC3_STATUS | E394: 0 | F394: CORE20 | G394: ML2 | H394: 0XFE000000F18D0400 | I394: WDTimeout (3 strike) | J394: TimeOutThread:1,ActiveThreads:3,XQ Empty:0,LQ Empty:1,SnpQ Empty:1,No U2C Req Credit:0,No C2U Credits:4,ExtCmpCntIsZero:1,FBVCntIsZero:1,VirtLLC Prefetch:1, | K394: 0XFFFFFF7F4405FFB0 | L394: 0XFFFFFF7F4405FFB0
A395: 74N24C5300241 | B395: 2-1 | C395: 7681 | D395: DPMB_SOCKET0__COMPUTE0__CPU__CORE21__ML2_CR_MC3_STATUS | E395: 0 | F395: CORE21 | G395: ML2 | H395: 0XFE000000F18D0400 | I395: WDTimeout (3 strike) | J395: TimeOutThread:1,ActiveThreads:3,XQ Empty:0,LQ Empty:1,SnpQ Empty:1,No U2C Req Credit:0,No C2U Credits:4,ExtCmpCntIsZero:1,FBVCntIsZero:1,VirtLLC Prefetch:1, | K395: 0XFFFFFF7F12EAEA47 | L395: 0XFFFFFF7F12EAEA47
A396: 74N24C5300241 | B396: 2-1 | C396: 7681 | D396: DPMB_SOCKET0__COMPUTE0__CPU__CORE23__ML2_CR_MC3_STATUS | E396: 0 | F396: CORE23 | G396: ML2 | H396: 0XFE000000F18D0400 | I396: WDTimeout (3 strike) | J396: TimeOutThread:1,ActiveThreads:3,XQ Empty:0,LQ Empty:1,SnpQ Empty:1,No U2C Req Credit:0,No C2U Credits:4,ExtCmpCntIsZero:1,FBVCntIsZero:1,VirtLLC Prefetch:1, | K396: 0XFFFFFFFF4405AA96 | L396: 0XFFFFFFFF4405AA96
A397: 74N24C5300241 | B397: 2-1 | C397: 7681 | D397: DPMB_SOCKET0__COMPUTE0__CPU__CORE24__ML2_CR_MC3_STATUS | E397: 0 | F397: CORE24 | G397: ML2 | H397: 0XF2000000D18D0400 | I397: WDTimeout (3 strike) | J397: TimeOutThread:1,ActiveThreads:3,XQ Empty:0,LQ Empty:1,SnpQ Empty:1,No U2C Req Credit:0,No C2U Credits:4,ExtCmpCntIsZero:0,FBVCntIsZero:1,VirtLLC Prefetch:1, | K397: 0XFFFFFFFF0134E470 | L397: 0XFFFFFFFF0134E470
