Workbook
Name splitchar: ErrorData!$G$1

Sheet CHA
A1: VisualId | B1: Lot | C1: LatoStartWW | D1: LotsSeqKey | E1: UnitTestingSeqKey | F1: TestName | G1: TestValue | H1: Operation | I1: TestNameNumber | J1: TestNameWithoutNumeric | K1: PPVRun_MC

Sheet CORE
A1: VisualId | B1: Lot | C1: LatoStartWW | D1: LotsSeqKey | E1: UnitTestingSeqKey | F1: TestName | G1: TestValue | H1: Operation | I1: TestNameNumber | J1: TestNameWithoutNumeric | K1: PPVRun_MC

Sheet PPV
B3: Final Bucket Data
B4: VisualId | C4: DpmBucket | D4: DecimaSite | E4: DecimaWW | F4: DecimaBucket | G4: DpmBucketAccuracy | H4: ProductConfigurationName | I4: BinDesc | J4: SubBucket | K4: Comments | L4: NextSteps

Sheet MC_Check
B1: Bucket | C1: All | K1: Bin | L1: =_xlfn.XLOOKUP(H2,ppv[VisualId],ppv[BinDesc],"")
B2: Units | C2: PPV | D2: Comments | E2: Next Steps | G2: Unit | H2: D5R858J700147 | AA2: Data Format | AE2: DPMB | AG2: Show Top | AJ2: 10 | AK2: Module Format | AN2: PHY
B3: {=IF(C1="All",_xlfn.UNIQUE(ppv[VisualId]),_xlfn._xlws.FILTER(ppv[VisualId],(ppv[SubBucket]=C1)*(IF(D1<>"",ISNUMBER(SEARCH(D1, ppv[Comments])),TRUE))))} -> 0 | C3: =_xlfn.XLOOKUP(B3,ppv[VisualId],ppv[DpmBucket],"") | G3: Accuracy | H3: =_xlfn.XLOOKUP(H2,ppv[VisualId],ppv[DpmBucketAccuracy],"") | AA3: Other | AC3: MEMORY | AF3: MODULE | AJ3: CBO | AM3: LLC (N/A)
C4: =_xlfn.XLOOKUP(B4,ppv[VisualId],ppv[DpmBucket],"") -> 0 | G4: WW | H4: =_xlfn.XLOOKUP(H2,ppv[VisualId],ppv[DecimaWW],"") | L4: XB: | N4: CrossBar | AA4: Punit | AC4: MEM | AD4: Fail(s) | AF4: Top Failing Core(s) | AG4: Fail(s) | AH4: Type(s) | AJ4: Top Failing CBO(s) | AK4: Fail(s) | AM4: TopFailing LLC | AN4: Fail(s)
C5: =_xlfn.XLOOKUP(B5,ppv[VisualId],ppv[DpmBucket],"") -> 0 | G5: Bucket | H5: =_xlfn.XLOOKUP(H2,ppv[VisualId],ppv[DpmBucket]) -> #N/A | L5: CBB: | N5: Core Building Block | AA5: {=IFERROR(_xlfn._xlws.FILTER(punitmcas[type],punitmcas[Counter]>0),"")} | AC5: {=IFERROR(_xlfn._xlws.FILTER(memss[Name],memss[MEMSS_Hitter_Count]>0),"")} | AD5: {=IFERROR(_xlfn._xlws.FILTER(memss[MEMSS_Hitter_Count],memss[MEMSS_Hitter_Count]>0),"")} | AF5: {=IFERROR("PHY"&_xlfn._xlws.FILTER(misc[location],misc[Core_Hitter_Count]>=MAX(misc[Core_Hitter_Count]-$AJ$2,1)),"")&":"&IFERROR("MODULE"&_xlfn._xlws.FILTER(misc[Module],misc[Core_Hitter_Count]>=MAX(misc[Core_Hitter_Count]-$AJ$2,1)),"")} -> : | AG5: {=IFERROR(_xlfn._xlws.FILTER(misc[Core_Hitter_Count],misc[Core_Hitter_Count]>=MAX(misc[Core_Hitter_Count]-$AJ$2,1)),"")} | AH5: {=IFERROR(_xlfn._xlws.FILTER(misc[Core_FAILS],misc[Core_Hitter_Count]>=MAX(misc[Core_Hitter_Count]-$AJ$2,1)),"")} | AJ5: {=IFERROR("CBO"&_xlfn._xlws.FILTER(misc[location],misc[CHA_Hitter_Count]>=MAX(misc[CHA_Hitter_Count]-$AJ$2,1)),"")} | AK5: {=IFERROR(_xlfn._xlws.FILTER(misc[CHA_Hitter_Count],misc[CHA_Hitter_Count]>=MAX(misc[CHA_Hitter_Count]-$AJ$2,1)),"")} | AM5: {=IFERROR("LLC"&_xlfn._xlws.FILTER(misc[location],misc[LLC_Hitter_Count]>=MAX(misc[LLC_Hitter_Count]-$AJ$2,1)),"")} | AN5: {=IFERROR(_xlfn._xlws.FILTER(misc[LLC_Hitter_Count],misc[LLC_Hitter_Count]>=MAX(misc[LLC_Hitter_Count]-$AJ$2,1)),"")}
C6: =_xlfn.XLOOKUP(B6,ppv[VisualId],ppv[DpmBucket],"") -> 0 | G6: =_xlfn.XLOOKUP(H2,ppv[VisualId],ppv[Comments]) -> #N/A | L6: D2D: | N6: Die-to-Die Interconnect
C7: =_xlfn.XLOOKUP(B7,ppv[VisualId],ppv[DpmBucket],"") -> 0 | G7: Postcodes | L7: Cluster/Module for TOP and Base DIE
C8: =_xlfn.XLOOKUP(B8,ppv[VisualId],ppv[DpmBucket],"") -> 0 | G8: {=_xlfn._xlws.FILTER(cha_mc[PPVRun_MC],((cha_mc[VisualId]=H2)*(ISNUMBER(SEARCH("BIOSNONSTICKYSCRATCHPAD",cha_mc[TestName])))),"")} | H8: {=_xlfn._xlws.FILTER(cha_mc[TestValue],((cha_mc[VisualId]=H2)*(ISNUMBER(SEARCH("BIOSNONSTICKYSCRATCHPAD",cha_mc[TestName])))),"")} | J8: FAILS | L8: CBB | N8: DCM (CORE) | T8: CLUSTER (CBO)
C9: =_xlfn.XLOOKUP(B9,ppv[VisualId],ppv[DpmBucket],"") -> 0 | J9: LLC | L9: 0 | N9: R/C | O9: 0 | P9: 1 | Q9: 2 | R9: 3 | S9: TOP | T9: BASE | U9: 0 | V9: 1 | W9: 2 | X9: 3 | Y9: R/C
C10: =_xlfn.XLOOKUP(B10,ppv[VisualId],ppv[DpmBucket],"") -> 0 | J10: MODULE | L10: COMPUTE | M10: 0 | N10: 0 | O10: =L9*(32)+O9 -> 0 | P10: =L9*(32)+P9 -> 1 | Q10: =L9*(32)+Q9 -> 2 | R10: =L9*(32)+R9 -> 3 | S10: XB | T10: XB | U10: =L9*(32)+U9 -> 0 | V10: =L9*(32)+V9 -> 1 | W10: =L9*(32)+W9 -> 2 | X10: =L9*(32)+X9 -> 3 | Y10: 0
C11: =_xlfn.XLOOKUP(B11,ppv[VisualId],ppv[DpmBucket],"") -> 0 | J11: CHA | N11: 1 | O11: =O10+4 -> 4 | P11: =P10+4 -> 5 | Q11: =Q10+4 -> 6 | R11: =R10+4 -> 7 | S11: XB | T11: XB | U11: =U10+4 -> 4 | V11: =V10+4 -> 5 | W11: =W10+4 -> 6 | X11: =X10+4 -> 7 | Y11: 1 | AA11: S3M
C12: =_xlfn.XLOOKUP(B12,ppv[VisualId],ppv[DpmBucket],"") -> 0 | J12: MEM | M12: 1 | N12: 2 | O12: =O11+4 -> 8 | P12: =P11+4 -> 9 | Q12: =Q11+4 -> 10 | R12: =R11+4 -> 11 | S12: XB | T12: XB | U12: =U11+4 -> 8 | V12: =V11+4 -> 9 | W12: =W11+4 -> 10 | X12: =X11+4 -> 11 | Y12: 2
C13: =_xlfn.XLOOKUP(B13,ppv[VisualId],ppv[DpmBucket],"") -> 0 | N13: 3 | O13: =O12+4 -> 12 | P13: =P12+4 -> 13 | Q13: =Q12+4 -> 14 | R13: =R12+4 -> 15 | S13: XB | T13: XB | U13: =U12+4 -> 12 | V13: =V12+4 -> 13 | W13: =W12+4 -> 14 | X13: =X12+4 -> 15 | Y13: 3
C14: =_xlfn.XLOOKUP(B14,ppv[VisualId],ppv[DpmBucket],"") -> 0 | M14: 2 | N14: 4 | O14: =O13+4 -> 16 | P14: =P13+4 -> 17 | Q14: =Q13+4 -> 18 | R14: =R13+4 -> 19 | S14: XB | T14: XB | U14: =U13+4 -> 16 | V14: =V13+4 -> 17 | W14: =W13+4 -> 18 | X14: =X13+4 -> 19 | Y14: 4
C15: =_xlfn.XLOOKUP(B15,ppv[VisualId],ppv[DpmBucket],"") -> 0 | N15: 5 | O15: =O14+4 -> 20 | P15: =P14+4 -> 21 | Q15: =Q14+4 -> 22 | R15: =R14+4 -> 23 | S15: XB | T15: XB | U15: =U14+4 -> 20 | V15: =V14+4 -> 21 | W15: =W14+4 -> 22 | X15: =X14+4 -> 23 | Y15: 5
C16: =_xlfn.XLOOKUP(B16,ppv[VisualId],ppv[DpmBucket],"") -> 0 | M16: 3 | N16: 6 | O16: =O15+4 -> 24 | P16: =P15+4 -> 25 | Q16: =Q15+4 -> 26 | R16: =R15+4 -> 27 | S16: XB | T16: XB | U16: =U15+4 -> 24 | V16: =V15+4 -> 25 | W16: =W15+4 -> 26 | X16: =X15+4 -> 27 | Y16: 6
C17: =_xlfn.XLOOKUP(B17,ppv[VisualId],ppv[DpmBucket],"") -> 0 | N17: 7 | O17: =O16+4 -> 28 | P17: =P16+4 -> 29 | Q17: =Q16+4 -> 30 | R17: =R16+4 -> 31 | S17: XB | T17: XB | U17: =U16+4 -> 28 | V17: =V16+4 -> 29 | W17: =W16+4 -> 30 | X17: =X16+4 -> 31 | Y17: 7
C18: =_xlfn.XLOOKUP(B18,ppv[VisualId],ppv[DpmBucket],"") -> 0 | U18: UXI SWITCH
C19: =_xlfn.XLOOKUP(B19,ppv[VisualId],ppv[DpmBucket],"") -> 0 | U19: D2D | V19: D2D | W19: D2D | X19: D2D
C20: =_xlfn.XLOOKUP(B20,ppv[VisualId],ppv[DpmBucket],"") -> 0
C21: =_xlfn.XLOOKUP(B21,ppv[VisualId],ppv[DpmBucket],"") -> 0 | J21: FAILS | L21: CBB | N21: DCM (CORE) | T21: CLUSTER (CBO)
C22: =_xlfn.XLOOKUP(B22,ppv[VisualId],ppv[DpmBucket],"") -> 0 | J22: LLC | L22: 1 | N22: R/C | O22: 0 | P22: 1 | Q22: 2 | R22: 3 | S22: TOP | T22: BASE | U22: 0 | V22: 1 | W22: 2 | X22: 3 | Y22: R/C
C23: =_xlfn.XLOOKUP(B23,ppv[VisualId],ppv[DpmBucket],"") -> 0 | J23: MODULE | L23: COMPUTE | M23: 0 | N23: 0 | O23: =L22*(32)+O22 -> 32 | P23: =L22*(32)+P22 -> 33 | Q23: =L22*(32)+Q22 -> 34 | R23: =L22*(32)+R22 -> 35 | S23: XB | T23: XB | U23: =L22*(32)+U22 -> 32 | V23: =L22*(32)+V22 -> 33 | W23: =L22*(32)+W22 -> 34 | X23: =L22*(32)+X22 -> 35 | Y23: 0
C24: =_xlfn.XLOOKUP(B24,ppv[VisualId],ppv[DpmBucket],"") -> 0 | J24: CHA | N24: 1 | O24: =O23+4 -> 36 | P24: =P23+4 -> 37 | Q24: =Q23+4 -> 38 | R24: =R23+4 -> 39 | S24: XB | T24: XB | U24: =U23+4 -> 36 | V24: =V23+4 -> 37 | W24: =W23+4 -> 38 | X24: =X23+4 -> 39 | Y24: 1
C25: =_xlfn.XLOOKUP(B25,ppv[VisualId],ppv[DpmBucket],"") -> 0 | J25: MEM | M25: 1 | N25: 2 | O25: =O24+4 -> 40 | P25: =P24+4 -> 41 | Q25: =Q24+4 -> 42 | R25: =R24+4 -> 43 | S25: XB | T25: XB | U25: =U24+4 -> 40 | V25: =V24+4 -> 41 | W25: =W24+4 -> 42 | X25: =X24+4 -> 43 | Y25: 2
C26: =_xlfn.XLOOKUP(B26,ppv[VisualId],ppv[DpmBucket],"") -> 0 | N26: 3 | O26: =O25+4 -> 44 | P26: =P25+4 -> 45 | Q26: =Q25+4 -> 46 | R26: =R25+4 -> 47 | S26: XB | T26: XB | U26: =U25+4 -> 44 | V26: =V25+4 -> 45 | W26: =W25+4 -> 46 | X26: =X25+4 -> 47 | Y26: 3
C27: =_xlfn.XLOOKUP(B27,ppv[VisualId],ppv[DpmBucket],"") -> 0 | M27: 2 | N27: 4 | O27: =O26+4 -> 48 | P27: =P26+4 -> 49 | Q27: =Q26+4 -> 50 | R27: =R26+4 -> 51 | S27: XB | T27: XB | U27: =U26+4 -> 48 | V27: =V26+4 -> 49 | W27: =W26+4 -> 50 | X27: =X26+4 -> 51 | Y27: 4
C28: =_xlfn.XLOOKUP(B28,ppv[VisualId],ppv[DpmBucket],"") -> 0 | N28: 5 | O28: =O27+4 -> 52 | P28: =P27+4 -> 53 | Q28: =Q27+4 -> 54 | R28: =R27+4 -> 55 | S28: XB | T28: XB | U28: =U27+4 -> 52 | V28: =V27+4 -> 53 | W28: =W27+4 -> 54 | X28: =X27+4 -> 55 | Y28: 5
C29: =_xlfn.XLOOKUP(B29,ppv[VisualId],ppv[DpmBucket],"") -> 0 | M29: 3 | N29: 6 | O29: =O28+4 -> 56 | P29: =P28+4 -> 57 | Q29: =Q28+4 -> 58 | R29: =R28+4 -> 59 | S29: XB | T29: XB | U29: =U28+4 -> 56 | V29: =V28+4 -> 57 | W29: =W28+4 -> 58 | X29: =X28+4 -> 59 | Y29: 6
C30: =_xlfn.XLOOKUP(B30,ppv[VisualId],ppv[DpmBucket],"") -> 0 | N30: 7 | O30: =O29+4 -> 60 | P30: =P29+4 -> 61 | Q30: =Q29+4 -> 62 | R30: =R29+4 -> 63 | S30: XB | T30: XB | U30: =U29+4 -> 60 | V30: =V29+4 -> 61 | W30: =W29+4 -> 62 | X30: =X29+4 -> 63 | Y30: 7
C31: =_xlfn.XLOOKUP(B31,ppv[VisualId],ppv[DpmBucket],"") -> 0 | U31: UXI SWITCH
C32: =_xlfn.XLOOKUP(B32,ppv[VisualId],ppv[DpmBucket],"") -> 0 | U32: D2D | V32: D2D | W32: D2D | X32: D2D
C33: =_xlfn.XLOOKUP(B33,ppv[VisualId],ppv[DpmBucket],"") -> 0
C34: =_xlfn.XLOOKUP(B34,ppv[VisualId],ppv[DpmBucket],"") -> 0 | J34: FAILS | L34: CBB | N34: DCM (CORE) | T34: CLUSTER (CBO)
C35: =_xlfn.XLOOKUP(B35,ppv[VisualId],ppv[DpmBucket],"") -> 0 | J35: LLC | L35: 2 | N35: R/C | O35: 0 | P35: 1 | Q35: 2 | R35: 3 | S35: TOP | T35: BASE | U35: 0 | V35: 1 | W35: 2 | X35: 3 | Y35: R/C
C36: =_xlfn.XLOOKUP(B36,ppv[VisualId],ppv[DpmBucket],"") -> 0 | J36: MODULE | L36: COMPUTE | M36: 0 | N36: 0 | O36: =L35*(32)+O35 -> 64 | P36: =L35*(32)+P35 -> 65 | Q36: =L35*(32)+Q35 -> 66 | R36: =L35*(32)+R35 -> 67 | S36: XB | T36: XB | U36: =L35*(32)+U35 -> 64 | V36: =L35*(32)+V35 -> 65 | W36: =L35*(32)+W35 -> 66 | X36: =L35*(32)+X35 -> 67 | Y36: 0
C37: =_xlfn.XLOOKUP(B37,ppv[VisualId],ppv[DpmBucket],"") -> 0 | J37: CHA | N37: 1 | O37: =O36+4 -> 68 | P37: =P36+4 -> 69 | Q37: =Q36+4 -> 70 | R37: =R36+4 -> 71 | S37: XB | T37: XB | U37: =U36+4 -> 68 | V37: =V36+4 -> 69 | W37: =W36+4 -> 70 | X37: =X36+4 -> 71 | Y37: 1
J38: MEM | M38: 1 | N38: 2 | O38: =O37+4 -> 72 | P38: =P37+4 -> 73 | Q38: =Q37+4 -> 74 | R38: =R37+4 -> 75 | S38: XB | T38: XB | U38: =U37+4 -> 72 | V38: =V37+4 -> 73 | W38: =W37+4 -> 74 | X38: =X37+4 -> 75 | Y38: 2
N39: 3 | O39: =O38+4 -> 76 | P39: =P38+4 -> 77 | Q39: =Q38+4 -> 78 | R39: =R38+4 -> 79 | S39: XB | T39: XB | U39: =U38+4 -> 76 | V39: =V38+4 -> 77 | W39: =W38+4 -> 78 | X39: =X38+4 -> 79 | Y39: 3
M40: 2 | N40: 4 | O40: =O39+4 -> 80 | P40: =P39+4 -> 81 | Q40: =Q39+4 -> 82 | R40: =R39+4 -> 83 | S40: XB | T40: XB | U40: =U39+4 -> 80 | V40: =V39+4 -> 81 | W40: =W39+4 -> 82 | X40: =X39+4 -> 83 | Y40: 4
...

Sheet ErrorData
A1: This Sheet is for miscelanous calculations, avoid modifying it unless necessary as it might end up giving wrong data analysis if not managed carefully. | F1: char | G1: =IF(MC_Check!AE2="DPMB","__",".") -> __ | I1: LOG = PHY | AK1: WIP | AT1: S3M | AX1: PUNIT
A2: Failing_LLC | B2: Failing_CHA | C2: Failing_Core | D2: Formats | F2: CBB | G2: location | H2: Module | I2: Module_log | J2: Compute | K2: ROW | L2: ENV | M2: CBO | N2: corefail | O2: llcfail | P2: chafail | Q2: CBO_MCA_String | R2: CHA_Hitter_Count | S2: IFU_MCA_String | T2: Core_IFU_Count | U2: ROB_MCA_String | V2: Core_ROB_Count | W2: DCU_MCA_String | X2: Core_DCU_Count | Y2: CORE_DTLB_String | Z2: Core_DTLB_Count | AA2: Core_ML2_String | AB2: Core_ML2_Count | AC2: Core_L2_String - SPARE | AD2: Core_L2_Count - SPARE | AE2: Core_Hitter_Count | AF2: Core_FAILS | AG2: LLC_MCA_String - Not Used | AH2: LLC_Hitter_Count | AK2: Compute | AL2: location | AM2: Name | AN2: fail | AO2: MEMMS_MCA_String | AP2: MEMSS_Hitter_Count | AT2: type | AU2: MCA_String | AV2: Counter | AX2: type | AY2: MCA_String | AZ2: Counter
A3: {=IFERROR(SUBSTITUTE(_xlfn._xlws.FILTER(_xlfn.UNIQUE(cha_mc[VisualId]&cha_mc[TestName]),ISNUMBER(SEARCH(MC_Check!H2 & "*LLC*__MCI_STATUS*", _xlfn.UNIQUE(cha_mc[VisualId]&cha_mc[TestName])))),MC_Check!H2,""),"No LLC Data Found")} -> No LLC Data Found | B3: {=IFERROR(SUBSTITUTE(_xlfn._xlws.FILTER(_xlfn.UNIQUE(cha_mc[VisualId]&cha_mc[TestName]),ISNUMBER(SEARCH(MC_Check!H2 & "*CBREGS*__MC_STATUS*", _xlfn.UNIQUE(cha_mc[VisualId]&cha_mc[TestName])))),MC_Check!H2,""), "No CHA Data Found")} -> No CHA Data Found | C3: {=IFERROR(SUBSTITUTE(_xlfn._xlws.FILTER(_xlfn.UNIQUE(core_mc[VisualId]&core_mc[TestName]),ISNUMBER(SEARCH(MC_Check!H2 & "**CR_MC3_STATUS*", _xlfn.UNIQUE(core_mc[VisualId]&core_mc[TestName])))),MC_Check!H2,""), "No CORE Data Found")} -> No CORE Data Found | D3: DPMB | F3: 0 | G3: 0 | H3: =IF(MC_Check!$AN$2="PHY",misc[[#This Row],[location]],misc[[#This Row],[Module_log]]) -> 0 | I3: =misc[[#This Row],[Module]] -> 0 | J3: 0 | K3: 0 | L3: 0 | M3: =_xlfn.TEXTJOIN("",,misc[[#This Row],[ROW]],misc[[#This Row],[ROW]]) -> 00 | N3: =misc[[#This Row],[Core_Hitter_Count]]>0 -> FALSE | O3: =misc[[#This Row],[LLC_Hitter_Count]]>0 -> FALSE | P3: =misc[[#This Row],[CHA_Hitter_Count]]>0 -> FALSE | Q3: =_xlfn.TEXTJOIN("",,"*SOCKET0**CBB",misc[[#This Row],[CBB]],"**BASE**I_CCF_ENV",misc[[#This Row],[ENV]],splitchar,"CBREGS_ALL",misc[[#This Row],[CBO]],splitchar,"MC_STATUS*") -> *SOCKET0**CBB0**BASE**I_CCF_ENV0__CBREGS_ALL00__MC_STATUS* | R3: =COUNTIFS(cha_mc[TestName],misc[[#This Row],[CBO_MCA_String]],cha_mc[VisualId],MC_Check!$H$2) -> 0 | S3: =_xlfn.TEXTJOIN("",,"*SOCKET0**CBB",misc[[#This Row],[CBB]],"**COMPUTE",misc[[#This Row],[Compute]],"**MODULE",misc[[#This Row],[Module]],splitchar,"**CORE**IFU*CR*MC0*STATUS**") -> *SOCKET0**CBB0**COMPUTE0**MODULE0__**CORE**IFU*CR*MC0*STATUS** | T3: =COUNTIFS(core_mc[TestName],misc[[#This Row],[IFU_MCA_String]],core_mc[VisualId],MC_Check!$H$2) -> 0 | U3: =_xlfn.TEXTJOIN("",,"*SOCKET0**CBB",misc[[#This Row],[CBB]],"**COMPUTE",misc[[#This Row],[Compute]],"**MODULE",misc[[#This Row],[Module]],splitchar,"**CORE**ROB1*CR*MC*STATUS**") -> *SOCKET0**CBB0**COMPUTE0**MODULE0__**CORE**ROB1*CR*MC*STATUS** | V3: =COUNTIFS(core_mc[TestName],misc[[#This Row],[ROB_MCA_String]],core_mc[VisualId],MC_Check!$H$2) -> 0 | W3: =_xlfn.TEXTJOIN("",,"*SOCKET0**CBB",misc[[#This Row],[CBB]],"**COMPUTE",misc[[#This Row],[Compute]],"**MODULE",misc[[#This Row],[Module]],splitchar,"**CORE**DCU*CR*MC1*STATUS**") -> *SOCKET0**CBB0**COMPUTE0**MODULE0__**CORE**DCU*CR*MC1*STATUS** | X3: =COUNTIFS(core_mc[TestName],misc[[#This Row],[DCU_MCA_String]],core_mc[VisualId],MC_Check!$H$2) -> 0 | Y3: =_xlfn.TEXTJOIN("",,"*SOCKET0**CBB",misc[[#This Row],[CBB]],"**COMPUTE",misc[[#This Row],[Compute]],"**MODULE",misc[[#This Row],[Module]],splitchar,"**CORE**DTLB*CR*MC2*STATUS**") -> *SOCKET0**CBB0**COMPUTE0**MODULE0__**CORE**DTLB*CR*MC2*STATUS** | Z3: =COUNTIFS(core_mc[TestName],misc[[#This Row],[CORE_DTLB_String]],core_mc[VisualId],MC_Check!$H$2) -> 0 | AA3: =_xlfn.TEXTJOIN("",,"*SOCKET0**CBB",misc[[#This Row],[CBB]],"**COMPUTE",misc[[#This Row],[Compute]],"**MODULE",misc[[#This Row],[Module]],splitchar,"**ML2*CR*MC3*STATUS**") -> *SOCKET0**CBB0**COMPUTE0**MODULE0__**ML2*CR*MC3*STATUS** | AB3: =COUNTIFS(core_mc[TestName],misc[[#This Row],[Core_ML2_String]],core_mc[VisualId],MC_Check!$H$2) -> 0 | AC3: =_xlfn.TEXTJOIN("",,"*SOCKET0**CBB",misc[[#This Row],[CBB]],"**COMPUTE",misc[[#This Row],[Compute]],"**MODULE",misc[[#This Row],[Module]],splitchar,"SPARE") -> *SOCKET0**CBB0**COMPUTE0**MODULE0__SPARE | AD3: =COUNTIFS(core_mc[TestName],misc[[#This Row],[Core_L2_String - SPARE]],core_mc[VisualId],MC_Check!$H$2) -> 0 | AE3: =misc[[#This Row],[Core_DTLB_Count]]+misc[[#This Row],[Core_DCU_Count]]+misc[[#This Row],[Core_IFU_Count]]+misc[[#This Row],[Core_ROB_Count]]+misc[[#This Row],[Core_L2_Count - SPARE]]+misc[[#This Row],[Core_ML2_Count]] -> 0 | AF3: =_xlfn.TEXTJOIN(", ",,IF(misc[[#This Row],[Core_IFU_Count]]>0,"IFU",""),IF(misc[[#This Row],[Core_DCU_Count]]>0,"DCU",""),IF(misc[[#This Row],[Core_DTLB_Count]]>0,"DTLB",""),IF(misc[[#This Row],[Core_ROB_Count]]>0,"ROB",""),IF(misc[[#This Row],[Core_ML2_Count]]>0,"ML2",""),IF(misc[[#This Row],[Core_L2_Count - SPARE]]>0,"L2","")) | AG3: =_xlfn.TEXTJOIN("",,"*SOCKET0**CBB",misc[[#This Row],[CBB]],"**BASE**I_CCF**ENV",misc[[#This Row],[ENV]],splitchar,"CBREGS_ALL",misc[[#This Row],[CBO]],splitchar,"SPARE") -> *SOCKET0**CBB0**BASE**I_CCF**ENV0__CBREGS_ALL00__SPARE | AH3: =COUNTIFS(cha_mc[TestName],misc[[#This Row],[LLC_MCA_String - Not Used]],cha_mc[VisualId],MC_Check!$H$2) -> 0 | AK3: 1 | AL3: 0 | AM3: ="CH"&memss[[#This Row],[location]] -> CH0 | AN3: =memss[[#This Row],[MEMSS_Hitter_Count]]>0 -> FALSE | AO3: =_xlfn.TEXTJOIN("",,"*SOCKET0**SOC**MEMSS**B2CMI",memss[[#This Row],[location]],splitchar,"MCI*STATUS*SHADOW*") -> *SOCKET0**SOC**MEMSS**B2CMI0__MCI*STATUS*SHADOW* | AP3: =COUNTIFS(cha_mc[TestName],memss[[#This Row],[MEMMS_MCA_String]],cha_mc[VisualId],MC_Check!$H$2) -> 0 | AT3: io0 | AU3: ="*SOCKET0**IO0**TAPS**IOW*GLBW*IS3M*IBL*TOP110"&splitchar&"TAP*S3M*ERR*STS*" -> *SOCKET0**IO0**TAPS**IOW*GLBW*IS3M*IBL*TOP110__TAP*S3M*ERR*STS* | AV3: =COUNTIFS(cha_mc[TestName],s3errors[[#This Row],[MCA_String]],cha_mc[VisualId],MC_Check!$H$2) -> 0 | AX3: io0 | AY3: ="*SOCKET0**IO0**UNCORE**PUNIT**PTPCFSMS**PTPCFSMS"&splitchar&"MC*STATUS*" -> *SOCKET0**IO0**UNCORE**PUNIT**PTPCFSMS**PTPCFSMS__MC*STATUS* | AZ3: =COUNTIFS(cha_mc[TestName],punitmcas[[#This Row],[MCA_String]],cha_mc[VisualId],MC_Check!$H$2) -> 0
D4: REGISTERS | F4: 0 | G4: 1 | H4: =IF(MC_Check!$AN$2="PHY",misc[[#This Row],[location]],misc[[#This Row],[Module_log]]) -> 1 | I4: =misc[[#This Row],[Module]] -> 1 | J4: 0 | K4: 0 | L4: 1 | M4: =_xlfn.TEXTJOIN("",,misc[[#This Row],[ROW]],misc[[#This Row],[ROW]]) -> 00 | N4: =misc[[#This Row],[Core_Hitter_Count]]>0 -> FALSE | O4: =misc[[#This Row],[LLC_Hitter_Count]]>0 -> FALSE | P4: =misc[[#This Row],[CHA_Hitter_Count]]>0 -> FALSE | Q4: =_xlfn.TEXTJOIN("",,"*SOCKET0**CBB",misc[[#This Row],[CBB]],"**BASE**I_CCF_ENV",misc[[#This Row],[ENV]],splitchar,"CBREGS_ALL",misc[[#This Row],[CBO]],splitchar,"MC_STATUS*") -> *SOCKET0**CBB0**BASE**I_CCF_ENV1__CBREGS_ALL00__MC_STATUS* | R4: =COUNTIFS(cha_mc[TestName],misc[[#This Row],[CBO_MCA_String]],cha_mc[VisualId],MC_Check!$H$2) -> 0 | S4: =_xlfn.TEXTJOIN("",,"*SOCKET0**CBB",misc[[#This Row],[CBB]],"**COMPUTE",misc[[#This Row],[Compute]],"**MODULE",misc[[#This Row],[Module]],splitchar,"**CORE**IFU*CR*MC0*STATUS**") -> *SOCKET0**CBB0**COMPUTE0**MODULE1__**CORE**IFU*CR*MC0*STATUS** | T4: =COUNTIFS(core_mc[TestName],misc[[#This Row],[IFU_MCA_String]],core_mc[VisualId],MC_Check!$H$2) -> 0 | U4: =_xlfn.TEXTJOIN("",,"*SOCKET0**CBB",misc[[#This Row],[CBB]],"**COMPUTE",misc[[#This Row],[Compute]],"**MODULE",misc[[#This Row],[Module]],splitchar,"**CORE**ROB1*CR*MC*STATUS**") -> *SOCKET0**CBB0**COMPUTE0**MODULE1__**CORE**ROB1*CR*MC*STATUS** | V4: =COUNTIFS(core_mc[TestName],misc[[#This Row],[ROB_MCA_String]],core_mc[VisualId],MC_Check!$H$2) -> 0 | W4: =_xlfn.TEXTJOIN("",,"*SOCKET0**CBB",misc[[#This Row],[CBB]],"**COMPUTE",misc[[#This Row],[Compute]],"**MODULE",misc[[#This Row],[Module]],splitchar,"**CORE**DCU*CR*MC1*STATUS**") -> *SOCKET0**CBB0**COMPUTE0**MODULE1__**CORE**DCU*CR*MC1*STATUS** | X4: =COUNTIFS(core_mc[TestName],misc[[#This Row],[DCU_MCA_String]],core_mc[VisualId],MC_Check!$H$2) -> 0 | Y4: =_xlfn.TEXTJOIN("",,"*SOCKET0**CBB",misc[[#This Row],[CBB]],"**COMPUTE",misc[[#This Row],[Compute]],"**MODULE",misc[[#This Row],[Module]],splitchar,"**CORE**DTLB*CR*MC2*STATUS**") -> *SOCKET0**CBB0**COMPUTE0**MODULE1__**CORE**DTLB*CR*MC2*STATUS** | Z4: =COUNTIFS(core_mc[TestName],misc[[#This Row],[CORE_DTLB_String]],core_mc[VisualId],MC_Check!$H$2) -> 0 | AA4: =_xlfn.TEXTJOIN("",,"*SOCKET0**CBB",misc[[#This Row],[CBB]],"**COMPUTE",misc[[#This Row],[Compute]],"**MODULE",misc[[#This Row],[Module]],splitchar,"**ML2*CR*MC3*STATUS**") -> *SOCKET0**CBB0**COMPUTE0**MODULE1__**ML2*CR*MC3*STATUS** | AB4: =COUNTIFS(core_mc[TestName],misc[[#This Row],[Core_ML2_String]],core_mc[VisualId],MC_Check!$H$2) -> 0 | AC4: =_xlfn.TEXTJOIN("",,"*SOCKET0**CBB",misc[[#This Row],[CBB]],"**COMPUTE",misc[[#This Row],[Compute]],"**MODULE",misc[[#This Row],[Module]],splitchar,"SPARE") -> *SOCKET0**CBB0**COMPUTE0**MODULE1__SPARE | AD4: =COUNTIFS(core_mc[TestName],misc[[#This Row],[Core_L2_String - SPARE]],core_mc[VisualId],MC_Check!$H$2) -> 0 | AE4: =misc[[#This Row],[Core_DTLB_Count]]+misc[[#This Row],[Core_DCU_Count]]+misc[[#This Row],[Core_IFU_Count]]+misc[[#This Row],[Core_ROB_Count]]+misc[[#This Row],[Core_L2_Count - SPARE]]+misc[[#This Row],[Core_ML2_Count]] -> 0 | AF4: =_xlfn.TEXTJOIN(", ",,IF(misc[[#This Row],[Core_IFU_Count]]>0,"IFU",""),IF(misc[[#This Row],[Core_DCU_Count]]>0,"DCU",""),IF(misc[[#This Row],[Core_DTLB_Count]]>0,"DTLB",""),IF(misc[[#This Row],[Core_ROB_Count]]>0,"ROB",""),IF(misc[[#This Row],[Core_ML2_Count]]>0,"ML2",""),IF(misc[[#This Row],[Core_L2_Count - SPARE]]>0,"L2","")) | AG4: =_xlfn.TEXTJOIN("",,"*SOCKET0**CBB",misc[[#This Row],[CBB]],"**BASE**I_CCF**ENV",misc[[#This Row],[ENV]],splitchar,"CBREGS_ALL",misc[[#This Row],[CBO]],splitchar,"SPARE") -> *SOCKET0**CBB0**BASE**I_CCF**ENV1__CBREGS_ALL00__SPARE | AH4: =COUNTIFS(cha_mc[TestName],misc[[#This Row],[LLC_MCA_String - Not Used]],cha_mc[VisualId],MC_Check!$H$2) -> 0 | AK4: 1 | AL4: 1 | AM4: ="CH"&memss[[#This Row],[location]] -> CH1 | AN4: =memss[[#This Row],[MEMSS_Hitter_Count]]>0 -> FALSE | AO4: =_xlfn.TEXTJOIN("",,"*SOCKET0**SOC**MEMSS**B2CMI",memss[[#This Row],[location]],splitchar,"MCI*STATUS*SHADOW*") -> *SOCKET0**SOC**MEMSS**B2CMI1__MCI*STATUS*SHADOW* | AP4: =COUNTIFS(cha_mc[TestName],memss[[#This Row],[MEMMS_MCA_String]],cha_mc[VisualId],MC_Check!$H$2) -> 0 | AT4: io1 | AU4: ="*SOCKET0**IO1**TAPS**IOW*GLBW*IS3M*IBL*TOP110"&splitchar&"TAP*S3M*ERR*STS**" -> *SOCKET0**IO1**TAPS**IOW*GLBW*IS3M*IBL*TOP110__TAP*S3M*ERR*STS** | AV4: =COUNTIFS(cha_mc[TestName],s3errors[[#This Row],[MCA_String]],cha_mc[VisualId],MC_Check!$H$2) -> 0 | AX4: io1 | AY4: ="*SOCKET0**IO1**UNCORE**PUNIT**PTPCFSMS**PTPCFSMS"&splitchar&"MC*STATUS*" -> *SOCKET0**IO1**UNCORE**PUNIT**PTPCFSMS**PTPCFSMS__MC*STATUS* | AZ4: =COUNTIFS(cha_mc[TestName],punitmcas[[#This Row],[MCA_String]],cha_mc[VisualId],MC_Check!$H$2) -> 0
F5: 0 | G5: 2 | H5: =IF(MC_Check!$AN$2="PHY",misc[[#This Row],[location]],misc[[#This Row],[Module_log]]) -> 2 | I5: =misc[[#This Row],[Module]] -> 2 | J5: 0 | K5: 0 | L5: 2 | M5: =_xlfn.TEXTJOIN("",,misc[[#This Row],[ROW]],misc[[#This Row],[ROW]]) -> 00 | N5: =misc[[#This Row],[Core_Hitter_Count]]>0 -> FALSE | O5: =misc[[#This Row],[LLC_Hitter_Count]]>0 -> FALSE | P5: =misc[[#This Row],[CHA_Hitter_Count]]>0 -> FALSE | Q5: =_xlfn.TEXTJOIN("",,"*SOCKET0**CBB",misc[[#This Row],[CBB]],"**BASE**I_CCF_ENV",misc[[#This Row],[ENV]],splitchar,"CBREGS_ALL",misc[[#This Row],[CBO]],splitchar,"MC_STATUS*") -> *SOCKET0**CBB0**BASE**I_CCF_ENV2__CBREGS_ALL00__MC_STATUS* | R5: =COUNTIFS(cha_mc[TestName],misc[[#This Row],[CBO_MCA_String]],cha_mc[VisualId],MC_Check!$H$2) -> 0 | S5: =_xlfn.TEXTJOIN("",,"*SOCKET0**CBB",misc[[#This Row],[CBB]],"**COMPUTE",misc[[#This Row],[Compute]],"**MODULE",misc[[#This Row],[Module]],splitchar,"**CORE**IFU*CR*MC0*STATUS**") -> *SOCKET0**CBB0**COMPUTE0**MODULE2__**CORE**IFU*CR*MC0*STATUS** | T5: =COUNTIFS(core_mc[TestName],misc[[#This Row],[IFU_MCA_String]],core_mc[VisualId],MC_Check!$H$2) -> 0 | U5: =_xlfn.TEXTJOIN("",,"*SOCKET0**CBB",misc[[#This Row],[CBB]],"**COMPUTE",misc[[#This Row],[Compute]],"**MODULE",misc[[#This Row],[Module]],splitchar,"**CORE**ROB1*CR*MC*STATUS**") -> *SOCKET0**CBB0**COMPUTE0**MODULE2__**CORE**ROB1*CR*MC*STATUS** | V5: =COUNTIFS(core_mc[TestName],misc[[#This Row],[ROB_MCA_String]],core_mc[VisualId],MC_Check!$H$2) -> 0 | W5: =_xlfn.TEXTJOIN("",,"*SOCKET0**CBB",misc[[#This Row],[CBB]],"**COMPUTE",misc[[#This Row],[Compute]],"**MODULE",misc[[#This Row],[Module]],splitchar,"**CORE**DCU*CR*MC1*STATUS**") -> *SOCKET0**CBB0**COMPUTE0**MODULE2__**CORE**DCU*CR*MC1*STATUS** | X5: =COUNTIFS(core_mc[TestName],misc[[#This Row],[DCU_MCA_String]],core_mc[VisualId],MC_Check!$H$2) -> 0 | Y5: =_xlfn.TEXTJOIN("",,"*SOCKET0**CBB",misc[[#This Row],[CBB]],"**COMPUTE",misc[[#This Row],[Compute]],"**MODULE",misc[[#This Row],[Module]],splitchar,"**CORE**DTLB*CR*MC2*STATUS**") -> *SOCKET0**CBB0**COMPUTE0**MODULE2__**CORE**DTLB*CR*MC2*STATUS** | Z5: =COUNTIFS(core_mc[TestName],misc[[#This Row],[CORE_DTLB_String]],core_mc[VisualId],MC_Check!$H$2) -> 0 | AA5: =_xlfn.TEXTJOIN("",,"*SOCKET0**CBB",misc[[#This Row],[CBB]],"**COMPUTE",misc[[#This Row],[Compute]],"**MODULE",misc[[#This Row],[Module]],splitchar,"**ML2*CR*MC3*STATUS**") -> *SOCKET0**CBB0**COMPUTE0**MODULE2__**ML2*CR*MC3*STATUS** | AB5: =COUNTIFS(core_mc[TestName],misc[[#This Row],[Core_ML2_String]],core_mc[VisualId],MC_Check!$H$2) -> 0 | AC5: =_xlfn.TEXTJOIN("",,"*SOCKET0**CBB",misc[[#This Row],[CBB]],"**COMPUTE",misc[[#This Row],[Compute]],"**MODULE",misc[[#This Row],[Module]],splitchar,"SPARE") -> *SOCKET0**CBB0**COMPUTE0**MODULE2__SPARE | AD5: =COUNTIFS(core_mc[TestName],misc[[#This Row],[Core_L2_String - SPARE]],core_mc[VisualId],MC_Check!$H$2) -> 0 | AE5: =misc[[#This Row],[Core_DTLB_Count]]+misc[[#This Row],[Core_DCU_Count]]+misc[[#This Row],[Core_IFU_Count]]+misc[[#This Row],[Core_ROB_Count]]+misc[[#This Row],[Core_L2_Count - SPARE]]+misc[[#This Row],[Core_ML2_Count]] -> 0 | AF5: =_xlfn.TEXTJOIN(", ",,IF(misc[[#This Row],[Core_IFU_Count]]>0,"IFU",""),IF(misc[[#This Row],[Core_DCU_Count]]>0,"DCU",""),IF(misc[[#This Row],[Core_DTLB_Count]]>0,"DTLB",""),IF(misc[[#This Row],[Core_ROB_Count]]>0,"ROB",""),IF(misc[[#This Row],[Core_ML2_Count]]>0,"ML2",""),IF(misc[[#This Row],[Core_L2_Count - SPARE]]>0,"L2","")) | AG5: =_xlfn.TEXTJOIN("",,"*SOCKET0**CBB",misc[[#This Row],[CBB]],"**BASE**I_CCF**ENV",misc[[#This Row],[ENV]],splitchar,"CBREGS_ALL",misc[[#This Row],[CBO]],splitchar,"SPARE") -> *SOCKET0**CBB0**BASE**I_CCF**ENV2__CBREGS_ALL00__SPARE | AH5: =COUNTIFS(cha_mc[TestName],misc[[#This Row],[LLC_MCA_String - Not Used]],cha_mc[VisualId],MC_Check!$H$2) -> 0 | AK5: 0 | AL5: 2 | AM5: ="CH"&memss[[#This Row],[location]] -> CH2 | AN5: =memss[[#This Row],[MEMSS_Hitter_Count]]>0 -> FALSE | AO5: =_xlfn.TEXTJOIN("",,"*SOCKET0**SOC**MEMSS**B2CMI",memss[[#This Row],[location]],splitchar,"MCI*STATUS*SHADOW*") -> *SOCKET0**SOC**MEMSS**B2CMI2__MCI*STATUS*SHADOW* | AP5: =COUNTIFS(cha_mc[TestName],memss[[#This Row],[MEMMS_MCA_String]],cha_mc[VisualId],MC_Check!$H$2) -> 0 | AT5: cdie0 | AU5: ="*SOCKET0**COMPUTE0**TAPS**IOW*GLBW*IS3M*IBL*TOP110"&splitchar&"TAP*S3M*ERR*STS**" -> *SOCKET0**COMPUTE0**TAPS**IOW*GLBW*IS3M*IBL*TOP110__TAP*S3M*ERR*STS** | AV5: =COUNTIFS(cha_mc[TestName],s3errors[[#This Row],[MCA_String]],cha_mc[VisualId],MC_Check!$H$2) -> 0 | AX5: cdie0 | AY5: ="*SOCKET0**COMPUTE0**UNCORE**PUNIT**PTPCFSMS**PTPCFSMS"&splitchar&"MC*STATUS*" -> *SOCKET0**COMPUTE0**UNCORE**PUNIT**PTPCFSMS**PTPCFSMS__MC*STATUS* | AZ5: =COUNTIFS(cha_mc[TestName],punitmcas[[#This Row],[MCA_String]],cha_mc[VisualId],MC_Check!$H$2) -> 0
F6: 0 | G6: 3 | H6: =IF(MC_Check!$AN$2="PHY",misc[[#This Row],[location]],misc[[#This Row],[Module_log]]) -> 3 | I6: =misc[[#This Row],[Module]] -> 3 | J6: 0 | K6: 0 | L6: 3 | M6: =_xlfn.TEXTJOIN("",,misc[[#This Row],[ROW]],misc[[#This Row],[ROW]]) -> 00 | N6: =misc[[#This Row],[Core_Hitter_Count]]>0 -> FALSE | O6: =misc[[#This Row],[LLC_Hitter_Count]]>0 -> FALSE | P6: =misc[[#This Row],[CHA_Hitter_Count]]>0 -> FALSE | Q6: =_xlfn.TEXTJOIN("",,"*SOCKET0**CBB",misc[[#This Row],[CBB]],"**BASE**I_CCF_ENV",misc[[#This Row],[ENV]],splitchar,"CBREGS_ALL",misc[[#This Row],[CBO]],splitchar,"MC_STATUS*") -> *SOCKET0**CBB0**BASE**I_CCF_ENV3__CBREGS_ALL00__MC_STATUS* | R6: =COUNTIFS(cha_mc[TestName],misc[[#This Row],[CBO_MCA_String]],cha_mc[VisualId],MC_Check!$H$2) -> 0 | S6: =_xlfn.TEXTJOIN("",,"*SOCKET0**CBB",misc[[#This Row],[CBB]],"**COMPUTE",misc[[#This Row],[Compute]],"**MODULE",misc[[#This Row],[Module]],splitchar,"**CORE**IFU*CR*MC0*STATUS**") -> *SOCKET0**CBB0**COMPUTE0**MODULE3__**CORE**IFU*CR*MC0*STATUS** | T6: =COUNTIFS(core_mc[TestName],misc[[#This Row],[IFU_MCA_String]],core_mc[VisualId],MC_Check!$H$2) -> 0 | U6: =_xlfn.TEXTJOIN("",,"*SOCKET0**CBB",misc[[#This Row],[CBB]],"**COMPUTE",misc[[#This Row],[Compute]],"**MODULE",misc[[#This Row],[Module]],splitchar,"**CORE**ROB1*CR*MC*STATUS**") -> *SOCKET0**CBB0**COMPUTE0**MODULE3__**CORE**ROB1*CR*MC*STATUS** | V6: =COUNTIFS(core_mc[TestName],misc[[#This Row],[ROB_MCA_String]],core_mc[VisualId],MC_Check!$H$2) -> 0 | W6: =_xlfn.TEXTJOIN("",,"*SOCKET0**CBB",misc[[#This Row],[CBB]],"**COMPUTE",misc[[#This Row],[Compute]],"**MODULE",misc[[#This Row],[Module]],splitchar,"**CORE**DCU*CR*MC1*STATUS**") -> *SOCKET0**CBB0**COMPUTE0**MODULE3__**CORE**DCU*CR*MC1*STATUS** | X6: =COUNTIFS(core_mc[TestName],misc[[#This Row],[DCU_MCA_String]],core_mc[VisualId],MC_Check!$H$2) -> 0 | Y6: =_xlfn.TEXTJOIN("",,"*SOCKET0**CBB",misc[[#This Row],[CBB]],"**COMPUTE",misc[[#This Row],[Compute]],"**MODULE",misc[[#This Row],[Module]],splitchar,"**CORE**DTLB*CR*MC2*STATUS**") -> *SOCKET0**CBB0**COMPUTE0**MODULE3__**CORE**DTLB*CR*MC2*STATUS** | Z6: =COUNTIFS(core_mc[TestName],misc[[#This Row],[CORE_DTLB_String]],core_mc[VisualId],MC_Check!$H$2) -> 0 | AA6: =_xlfn.TEXTJOIN("",,"*SOCKET0**CBB",misc[[#This Row],[CBB]],"**COMPUTE",misc[[#This Row],[Compute]],"**MODULE",misc[[#This Row],[Module]],splitchar,"**ML2*CR*MC3*STATUS**") -> *SOCKET0**CBB0**COMPUTE0**MODULE3__**ML2*CR*MC3*STATUS** | AB6: =COUNTIFS(core_mc[TestName],misc[[#This Row],[Core_ML2_String]],core_mc[VisualId],MC_Check!$H$2) -> 0 | AC6: =_xlfn.TEXTJOIN("",,"*SOCKET0**CBB",misc[[#This Row],[CBB]],"**COMPUTE",misc[[#This Row],[Compute]],"**MODULE",misc[[#This Row],[Module]],splitchar,"SPARE") -> *SOCKET0**CBB0**COMPUTE0**MODULE3__SPARE | AD6: =COUNTIFS(core_mc[TestName],misc[[#This Row],[Core_L2_String - SPARE]],core_mc[VisualId],MC_Check!$H$2) -> 0 | AE6: =misc[[#This Row],[Core_DTLB_Count]]+misc[[#This Row],[Core_DCU_Count]]+misc[[#This Row],[Core_IFU_Count]]+misc[[#This Row],[Core_ROB_Count]]+misc[[#This Row],[Core_L2_Count - SPARE]]+misc[[#This Row],[Core_ML2_Count]] -> 0 | AF6: =_xlfn.TEXTJOIN(", ",,IF(misc[[#This Row],[Core_IFU_Count]]>0,"IFU",""),IF(misc[[#This Row],[Core_DCU_Count]]>0,"DCU",""),IF(misc[[#This Row],[Core_DTLB_Count]]>0,"DTLB",""),IF(misc[[#This Row],[Core_ROB_Count]]>0,"ROB",""),IF(misc[[#This Row],[Core_ML2_Count]]>0,"ML2",""),IF(misc[[#This Row],[Core_L2_Count - SPARE]]>0,"L2","")) | AG6: =_xlfn.TEXTJOIN("",,"*SOCKET0**CBB",misc[[#This Row],[CBB]],"**BASE**I_CCF**ENV",misc[[#This Row],[ENV]],splitchar,"CBREGS_ALL",misc[[#This Row],[CBO]],splitchar,"SPARE") -> *SOCKET0**CBB0**BASE**I_CCF**ENV3__CBREGS_ALL00__SPARE | AH6: =COUNTIFS(cha_mc[TestName],misc[[#This Row],[LLC_MCA_String - Not Used]],cha_mc[VisualId],MC_Check!$H$2) -> 0 | AK6: 0 | AL6: 3 | AM6: ="CH"&memss[[#This Row],[location]] -> CH3 | AN6: =memss[[#This Row],[MEMSS_Hitter_Count]]>0 -> FALSE | AO6: =_xlfn.TEXTJOIN("",,"*SOCKET0**SOC**MEMSS**B2CMI",memss[[#This Row],[location]],splitchar,"MCI*STATUS*SHADOW*") -> *SOCKET0**SOC**MEMSS**B2CMI3__MCI*STATUS*SHADOW* | AP6: =COUNTIFS(cha_mc[TestName],memss[[#This Row],[MEMMS_MCA_String]],cha_mc[VisualId],MC_Check!$H$2) -> 0 | AT6: cdie1 | AU6: ="*SOCKET0**COMPUTE1**TAPS**IOW*GLBW*IS3M*IBL*TOP110"&splitchar&"TAP*S3M*ERR*STS**" -> *SOCKET0**COMPUTE1**TAPS**IOW*GLBW*IS3M*IBL*TOP110__TAP*S3M*ERR*STS** | AV6: =COUNTIFS(cha_mc[TestName],s3errors[[#This Row],[MCA_String]],cha_mc[VisualId],MC_Check!$H$2) -> 0 | AX6: cdie1 | AY6: ="*SOCKET0**COMPUTE0**UNCORE**PUNIT**PTPCFSMS**PTPCFSMS"&splitchar&"MC*STATUS*" -> *SOCKET0**COMPUTE0**UNCORE**PUNIT**PTPCFSMS**PTPCFSMS__MC*STATUS* | AZ6: =COUNTIFS(cha_mc[TestName],punitmcas[[#This Row],[MCA_String]],cha_mc[VisualId],MC_Check!$H$2) -> 0
D7: ShowTop | F7: 0 | G7: 4 | H7: =IF(MC_Check!$AN$2="PHY",misc[[#This Row],[location]],misc[[#This Row],[Module_log]]) -> 4 | I7: =misc[[#This Row],[Module]] -> 4 | J7: 0 | K7: =K3+1 -> 1 | L7: 0 | M7: =_xlfn.TEXTJOIN("",,misc[[#This Row],[ROW]],misc[[#This Row],[ROW]]) -> 11 | N7: =misc[[#This Row],[Core_Hitter_Count]]>0 -> FALSE | O7: =misc[[#This Row],[LLC_Hitter_Count]]>0 -> FALSE | P7: =misc[[#This Row],[CHA_Hitter_Count]]>0 -> FALSE | Q7: =_xlfn.TEXTJOIN("",,"*SOCKET0**CBB",misc[[#This Row],[CBB]],"**BASE**I_CCF_ENV",misc[[#This Row],[ENV]],splitchar,"CBREGS_ALL",misc[[#This Row],[CBO]],splitchar,"MC_STATUS*") -> *SOCKET0**CBB0**BASE**I_CCF_ENV0__CBREGS_ALL11__MC_STATUS* | R7: =COUNTIFS(cha_mc[TestName],misc[[#This Row],[CBO_MCA_String]],cha_mc[VisualId],MC_Check!$H$2) -> 0 | S7: =_xlfn.TEXTJOIN("",,"*SOCKET0**CBB",misc[[#This Row],[CBB]],"**COMPUTE",misc[[#This Row],[Compute]],"**MODULE",misc[[#This Row],[Module]],splitchar,"**CORE**IFU*CR*MC0*STATUS**") -> *SOCKET0**CBB0**COMPUTE0**MODULE4__**CORE**IFU*CR*MC0*STATUS** | T7: =COUNTIFS(core_mc[TestName],misc[[#This Row],[IFU_MCA_String]],core_mc[VisualId],MC_Check!$H$2) -> 0 | U7: =_xlfn.TEXTJOIN("",,"*SOCKET0**CBB",misc[[#This Row],[CBB]],"**COMPUTE",misc[[#This Row],[Compute]],"**MODULE",misc[[#This Row],[Module]],splitchar,"**CORE**ROB1*CR*MC*STATUS**") -> *SOCKET0**CBB0**COMPUTE0**MODULE4__**CORE**ROB1*CR*MC*STATUS** | V7: =COUNTIFS(core_mc[TestName],misc[[#This Row],[ROB_MCA_String]],core_mc[VisualId],MC_Check!$H$2) -> 0 | W7: =_xlfn.TEXTJOIN("",,"*SOCKET0**CBB",misc[[#This Row],[CBB]],"**COMPUTE",misc[[#This Row],[Compute]],"**MODULE",misc[[#This Row],[Module]],splitchar,"**CORE**DCU*CR*MC1*STATUS**") -> *SOCKET0**CBB0**COMPUTE0**MODULE4__**CORE**DCU*CR*MC1*STATUS** | X7: =COUNTIFS(core_mc[TestName],misc[[#This Row],[DCU_MCA_String]],core_mc[VisualId],MC_Check!$H$2) -> 0 | Y7: =_xlfn.TEXTJOIN("",,"*SOCKET0**CBB",misc[[#This Row],[CBB]],"**COMPUTE",misc[[#This Row],[Compute]],"**MODULE",misc[[#This Row],[Module]],splitchar,"**CORE**DTLB*CR*MC2*STATUS**") -> *SOCKET0**CBB0**COMPUTE0**MODULE4__**CORE**DTLB*CR*MC2*STATUS** | Z7: =COUNTIFS(core_mc[TestName],misc[[#This Row],[CORE_DTLB_String]],core_mc[VisualId],MC_Check!$H$2) -> 0 | AA7: =_xlfn.TEXTJOIN("",,"*SOCKET0**CBB",misc[[#This Row],[CBB]],"**COMPUTE",misc[[#This Row],[Compute]],"**MODULE",misc[[#This Row],[Module]],splitchar,"**ML2*CR*MC3*STATUS**") -> *SOCKET0**CBB0**COMPUTE0**MODULE4__**ML2*CR*MC3*STATUS** | AB7: =COUNTIFS(core_mc[TestName],misc[[#This Row],[Core_ML2_String]],core_mc[VisualId],MC_Check!$H$2) -> 0 | AC7: =_xlfn.TEXTJOIN("",,"*SOCKET0**CBB",misc[[#This Row],[CBB]],"**COMPUTE",misc[[#This Row],[Compute]],"**MODULE",misc[[#This Row],[Module]],splitchar,"SPARE") -> *SOCKET0**CBB0**COMPUTE0**MODULE4__SPARE | AD7: =COUNTIFS(core_mc[TestName],misc[[#This Row],[Core_L2_String - SPARE]],core_mc[VisualId],MC_Check!$H$2) -> 0 | AE7: =misc[[#This Row],[Core_DTLB_Count]]+misc[[#This Row],[Core_DCU_Count]]+misc[[#This Row],[Core_IFU_Count]]+misc[[#This Row],[Core_ROB_Count]]+misc[[#This Row],[Core_L2_Count - SPARE]]+misc[[#This Row],[Core_ML2_Count]] -> 0 | AF7: =_xlfn.TEXTJOIN(", ",,IF(misc[[#This Row],[Core_IFU_Count]]>0,"IFU",""),IF(misc[[#This Row],[Core_DCU_Count]]>0,"DCU",""),IF(misc[[#This Row],[Core_DTLB_Count]]>0,"DTLB",""),IF(misc[[#This Row],[Core_ROB_Count]]>0,"ROB",""),IF(misc[[#This Row],[Core_ML2_Count]]>0,"ML2",""),IF(misc[[#This Row],[Core_L2_Count - SPARE]]>0,"L2","")) | AG7: =_xlfn.TEXTJOIN("",,"*SOCKET0**CBB",misc[[#This Row],[CBB]],"**BASE**I_CCF**ENV",misc[[#This Row],[ENV]],splitchar,"CBREGS_ALL",misc[[#This Row],[CBO]],splitchar,"SPARE") -> *SOCKET0**CBB0**BASE**I_CCF**ENV0__CBREGS_ALL11__SPARE | AH7: =COUNTIFS(cha_mc[TestName],misc[[#This Row],[LLC_MCA_String - Not Used]],cha_mc[VisualId],MC_Check!$H$2) -> 0 | AK7: 2 | AL7: 4 | AM7: ="CH"&memss[[#This Row],[location]] -> CH4 | AN7: =memss[[#This Row],[MEMSS_Hitter_Count]]>0 -> FALSE | AO7: =_xlfn.TEXTJOIN("",,"*SOCKET0**SOC**MEMSS**B2CMI",memss[[#This Row],[location]],splitchar,"MCI*STATUS*SHADOW*") -> *SOCKET0**SOC**MEMSS**B2CMI4__MCI*STATUS*SHADOW* | AP7: =COUNTIFS(cha_mc[TestName],memss[[#This Row],[MEMMS_MCA_String]],cha_mc[VisualId],MC_Check!$H$2) -> 0 | AT7: cdie2 | AU7: ="*SOCKET0**COMPUTE2**TAPS**IOW*GLBW*IS3M*IBL*TOP110"&splitchar&"TAP*S3M*ERR*STS**" -> *SOCKET0**COMPUTE2**TAPS**IOW*GLBW*IS3M*IBL*TOP110__TAP*S3M*ERR*STS** | AV7: =COUNTIFS(cha_mc[TestName],s3errors[[#This Row],[MCA_String]],cha_mc[VisualId],MC_Check!$H$2) -> 0 | AX7: cdie2 | AY7: ="*SOCKET0**COMPUTE0**UNCORE**PUNIT**PTPCFSMS**PTPCFSMS"&splitchar&"MC*STATUS*" -> *SOCKET0**COMPUTE0**UNCORE**PUNIT**PTPCFSMS**PTPCFSMS__MC*STATUS* | AZ7: =COUNTIFS(cha_mc[TestName],punitmcas[[#This Row],[MCA_String]],cha_mc[VisualId],MC_Check!$H$2) -> 0
D8: 1 | F8: 0 | G8: 5 | H8: =IF(MC_Check!$AN$2="PHY",misc[[#This Row],[location]],misc[[#This Row],[Module_log]]) -> 5 | I8: =misc[[#This Row],[Module]] -> 5 | J8: 0 | K8: =K4+1 -> 1 | L8: 1 | M8: =_xlfn.TEXTJOIN("",,misc[[#This Row],[ROW]],misc[[#This Row],[ROW]]) -> 11 | N8: =misc[[#This Row],[Core_Hitter_Count]]>0 -> FALSE | O8: =misc[[#This Row],[LLC_Hitter_Count]]>0 -> FALSE | P8: =misc[[#This Row],[CHA_Hitter_Count]]>0 -> FALSE | Q8: =_xlfn.TEXTJOIN("",,"*SOCKET0**CBB",misc[[#This Row],[CBB]],"**BASE**I_CCF_ENV",misc[[#This Row],[ENV]],splitchar,"CBREGS_ALL",misc[[#This Row],[CBO]],splitchar,"MC_STATUS*") -> *SOCKET0**CBB0**BASE**I_CCF_ENV1__CBREGS_ALL11__MC_STATUS* | R8: =COUNTIFS(cha_mc[TestName],misc[[#This Row],[CBO_MCA_String]],cha_mc[VisualId],MC_Check!$H$2) -> 0 | S8: =_xlfn.TEXTJOIN("",,"*SOCKET0**CBB",misc[[#This Row],[CBB]],"**COMPUTE",misc[[#This Row],[Compute]],"**MODULE",misc[[#This Row],[Module]],splitchar,"**CORE**IFU*CR*MC0*STATUS**") -> *SOCKET0**CBB0**COMPUTE0**MODULE5__**CORE**IFU*CR*MC0*STATUS** | T8: =COUNTIFS(core_mc[TestName],misc[[#This Row],[IFU_MCA_String]],core_mc[VisualId],MC_Check!$H$2) -> 0 | U8: =_xlfn.TEXTJOIN("",,"*SOCKET0**CBB",misc[[#This Row],[CBB]],"**COMPUTE",misc[[#This Row],[Compute]],"**MODULE",misc[[#This Row],[Module]],splitchar,"**CORE**ROB1*CR*MC*STATUS**") -> *SOCKET0**CBB0**COMPUTE0**MODULE5__**CORE**ROB1*CR*MC*STATUS** | V8: =COUNTIFS(core_mc[TestName],misc[[#This Row],[ROB_MCA_String]],core_mc[VisualId],MC_Check!$H$2) -> 0 | W8: =_xlfn.TEXTJOIN("",,"*SOCKET0**CBB",misc[[#This Row],[CBB]],"**COMPUTE",misc[[#This Row],[Compute]],"**MODULE",misc[[#This Row],[Module]],splitchar,"**CORE**DCU*CR*MC1*STATUS**") -> *SOCKET0**CBB0**COMPUTE0**MODULE5__**CORE**DCU*CR*MC1*STATUS** | X8: =COUNTIFS(core_mc[TestName],misc[[#This Row],[DCU_MCA_String]],core_mc[VisualId],MC_Check!$H$2) -> 0 | Y8: =_xlfn.TEXTJOIN("",,"*SOCKET0**CBB",misc[[#This Row],[CBB]],"**COMPUTE",misc[[#This Row],[Compute]],"**MODULE",misc[[#This Row],[Module]],splitchar,"**CORE**DTLB*CR*MC2*STATUS**") -> *SOCKET0**CBB0**COMPUTE0**MODULE5__**CORE**DTLB*CR*MC2*STATUS** | Z8: =COUNTIFS(core_mc[TestName],misc[[#This Row],[CORE_DTLB_String]],core_mc[VisualId],MC_Check!$H$2) -> 0 | AA8: =_xlfn.TEXTJOIN("",,"*SOCKET0**CBB",misc[[#This Row],[CBB]],"**COMPUTE",misc[[#This Row],[Compute]],"**MODULE",misc[[#This Row],[Module]],splitchar,"**ML2*CR*MC3*STATUS**") -> *SOCKET0**CBB0**COMPUTE0**MODULE5__**ML2*CR*MC3*STATUS** | AB8: =COUNTIFS(core_mc[TestName],misc[[#This Row],[Core_ML2_String]],core_mc[VisualId],MC_Check!$H$2) -> 0 | AC8: =_xlfn.TEXTJOIN("",,"*SOCKET0**CBB",misc[[#This Row],[CBB]],"**COMPUTE",misc[[#This Row],[Compute]],"**MODULE",misc[[#This Row],[Module]],splitchar,"SPARE") -> *SOCKET0**CBB0**COMPUTE0**MODULE5__SPARE | AD8: =COUNTIFS(core_mc[TestName],misc[[#This Row],[Core_L2_String - SPARE]],core_mc[VisualId],MC_Check!$H$2) -> 0 | AE8: =misc[[#This Row],[Core_DTLB_Count]]+misc[[#This Row],[Core_DCU_Count]]+misc[[#This Row],[Core_IFU_Count]]+misc[[#This Row],[Core_ROB_Count]]+misc[[#This Row],[Core_L2_Count - SPARE]]+misc[[#This Row],[Core_ML2_Count]] -> 0 | AF8: =_xlfn.TEXTJOIN(", ",,IF(misc[[#This Row],[Core_IFU_Count]]>0,"IFU",""),IF(misc[[#This Row],[Core_DCU_Count]]>0,"DCU",""),IF(misc[[#This Row],[Core_DTLB_Count]]>0,"DTLB",""),IF(misc[[#This Row],[Core_ROB_Count]]>0,"ROB",""),IF(misc[[#This Row],[Core_ML2_Count]]>0,"ML2",""),IF(misc[[#This Row],[Core_L2_Count - SPARE]]>0,"L2","")) | AG8: =_xlfn.TEXTJOIN("",,"*SOCKET0**CBB",misc[[#This Row],[CBB]],"**BASE**I_CCF**ENV",misc[[#This Row],[ENV]],splitchar,"CBREGS_ALL",misc[[#This Row],[CBO]],splitchar,"SPARE") -> *SOCKET0**CBB0**BASE**I_CCF**ENV1__CBREGS_ALL11__SPARE | AH8: =COUNTIFS(cha_mc[TestName],misc[[#This Row],[LLC_MCA_String - Not Used]],cha_mc[VisualId],MC_Check!$H$2) -> 0 | AK8: 2 | AL8: 5 | AM8: ="CH"&memss[[#This Row],[location]] -> CH5 | AN8: =memss[[#This Row],[MEMSS_Hitter_Count]]>0 -> FALSE | AO8: =_xlfn.TEXTJOIN("",,"*SOCKET0**SOC**MEMSS**B2CMI",memss[[#This Row],[location]],splitchar,"MCI*STATUS*SHADOW*") -> *SOCKET0**SOC**MEMSS**B2CMI5__MCI*STATUS*SHADOW* | AP8: =COUNTIFS(cha_mc[TestName],memss[[#This Row],[MEMMS_MCA_String]],cha_mc[VisualId],MC_Check!$H$2) -> 0
D9: 2 | F9: 0 | G9: 6 | H9: =IF(MC_Check!$AN$2="PHY",misc[[#This Row],[location]],misc[[#This Row],[Module_log]]) -> 6 | I9: =misc[[#This Row],[Module]] -> 6 | J9: 0 | K9: =K5+1 -> 1 | L9: 2 | M9: =_xlfn.TEXTJOIN("",,misc[[#This Row],[ROW]],misc[[#This Row],[ROW]]) -> 11 | N9: =misc[[#This Row],[Core_Hitter_Count]]>0 -> FALSE | O9: =misc[[#This Row],[LLC_Hitter_Count]]>0 -> FALSE | P9: =misc[[#This Row],[CHA_Hitter_Count]]>0 -> FALSE | Q9: =_xlfn.TEXTJOIN("",,"*SOCKET0**CBB",misc[[#This Row],[CBB]],"**BASE**I_CCF_ENV",misc[[#This Row],[ENV]],splitchar,"CBREGS_ALL",misc[[#This Row],[CBO]],splitchar,"MC_STATUS*") -> *SOCKET0**CBB0**BASE**I_CCF_ENV2__CBREGS_ALL11__MC_STATUS* | R9: =COUNTIFS(cha_mc[TestName],misc[[#This Row],[CBO_MCA_String]],cha_mc[VisualId],MC_Check!$H$2) -> 0 | S9: =_xlfn.TEXTJOIN("",,"*SOCKET0**CBB",misc[[#This Row],[CBB]],"**COMPUTE",misc[[#This Row],[Compute]],"**MODULE",misc[[#This Row],[Module]],splitchar,"**CORE**IFU*CR*MC0*STATUS**") -> *SOCKET0**CBB0**COMPUTE0**MODULE6__**CORE**IFU*CR*MC0*STATUS** | T9: =COUNTIFS(core_mc[TestName],misc[[#This Row],[IFU_MCA_String]],core_mc[VisualId],MC_Check!$H$2) -> 0 | U9: =_xlfn.TEXTJOIN("",,"*SOCKET0**CBB",misc[[#This Row],[CBB]],"**COMPUTE",misc[[#This Row],[Compute]],"**MODULE",misc[[#This Row],[Module]],splitchar,"**CORE**ROB1*CR*MC*STATUS**") -> *SOCKET0**CBB0**COMPUTE0**MODULE6__**CORE**ROB1*CR*MC*STATUS** | V9: =COUNTIFS(core_mc[TestName],misc[[#This Row],[ROB_MCA_String]],core_mc[VisualId],MC_Check!$H$2) -> 0 | W9: =_xlfn.TEXTJOIN("",,"*SOCKET0**CBB",misc[[#This Row],[CBB]],"**COMPUTE",misc[[#This Row],[Compute]],"**MODULE",misc[[#This Row],[Module]],splitchar,"**CORE**DCU*CR*MC1*STATUS**") -> *SOCKET0**CBB0**COMPUTE0**MODULE6__**CORE**DCU*CR*MC1*STATUS** | X9: =COUNTIFS(core_mc[TestName],misc[[#This Row],[DCU_MCA_String]],core_mc[VisualId],MC_Check!$H$2) -> 0 | Y9: =_xlfn.TEXTJOIN("",,"*SOCKET0**CBB",misc[[#This Row],[CBB]],"**COMPUTE",misc[[#This Row],[Compute]],"**MODULE",misc[[#This Row],[Module]],splitchar,"**CORE**DTLB*CR*MC2*STATUS**") -> *SOCKET0**CBB0**COMPUTE0**MODULE6__**CORE**DTLB*CR*MC2*STATUS** | Z9: =COUNTIFS(core_mc[TestName],misc[[#This Row],[CORE_DTLB_String]],core_mc[VisualId],MC_Check!$H$2) -> 0 | AA9: =_xlfn.TEXTJOIN("",,"*SOCKET0**CBB",misc[[#This Row],[CBB]],"**COMPUTE",misc[[#This Row],[Compute]],"**MODULE",misc[[#This Row],[Module]],splitchar,"**ML2*CR*MC3*STATUS**") -> *SOCKET0**CBB0**COMPUTE0**MODULE6__**ML2*CR*MC3*STATUS** | AB9: =COUNTIFS(core_mc[TestName],misc[[#This Row],[Core_ML2_String]],core_mc[VisualId],MC_Check!$H$2) -> 0 | AC9: =_xlfn.TEXTJOIN("",,"*SOCKET0**CBB",misc[[#This Row],[CBB]],"**COMPUTE",misc[[#This Row],[Compute]],"**MODULE",misc[[#This Row],[Module]],splitchar,"SPARE") -> *SOCKET0**CBB0**COMPUTE0**MODULE6__SPARE | AD9: =COUNTIFS(core_mc[TestName],misc[[#This Row],[Core_L2_String - SPARE]],core_mc[VisualId],MC_Check!$H$2) -> 0 | AE9: =misc[[#This Row],[Core_DTLB_Count]]+misc[[#This Row],[Core_DCU_Count]]+misc[[#This Row],[Core_IFU_Count]]+misc[[#This Row],[Core_ROB_Count]]+misc[[#This Row],[Core_L2_Count - SPARE]]+misc[[#This Row],[Core_ML2_Count]] -> 0 | AF9: =_xlfn.TEXTJOIN(", ",,IF(misc[[#This Row],[Core_IFU_Count]]>0,"IFU",""),IF(misc[[#This Row],[Core_DCU_Count]]>0,"DCU",""),IF(misc[[#This Row],[Core_DTLB_Count]]>0,"DTLB",""),IF(misc[[#This Row],[Core_ROB_Count]]>0,"ROB",""),IF(misc[[#This Row],[Core_ML2_Count]]>0,"ML2",""),IF(misc[[#This Row],[Core_L2_Count - SPARE]]>0,"L2","")) | AG9: =_xlfn.TEXTJOIN("",,"*SOCKET0**CBB",misc[[#This Row],[CBB]],"**BASE**I_CCF**ENV",misc[[#This Row],[ENV]],splitchar,"CBREGS_ALL",misc[[#This Row],[CBO]],splitchar,"SPARE") -> *SOCKET0**CBB0**BASE**I_CCF**ENV2__CBREGS_ALL11__SPARE | AH9: =COUNTIFS(cha_mc[TestName],misc[[#This Row],[LLC_MCA_String - Not Used]],cha_mc[VisualId],MC_Check!$H$2) -> 0 | AK9: 1 | AL9: 6 | AM9: ="CH"&memss[[#This Row],[location]] -> CH6 | AN9: =memss[[#This Row],[MEMSS_Hitter_Count]]>0 -> FALSE | AO9: =_xlfn.TEXTJOIN("",,"*SOCKET0**SOC**MEMSS**B2CMI",memss[[#This Row],[location]],splitchar,"MCI*STATUS*SHADOW*") -> *SOCKET0**SOC**MEMSS**B2CMI6__MCI*STATUS*SHADOW* | AP9: =COUNTIFS(cha_mc[TestName],memss[[#This Row],[MEMMS_MCA_String]],cha_mc[VisualId],MC_Check!$H$2) -> 0
D10: 3 | F10: 0 | G10: 7 | H10: =IF(MC_Check!$AN$2="PHY",misc[[#This Row],[location]],misc[[#This Row],[Module_log]]) -> 7 | I10: =misc[[#This Row],[Module]] -> 7 | J10: 0 | K10: =K6+1 -> 1 | L10: 3 | M10: =_xlfn.TEXTJOIN("",,misc[[#This Row],[ROW]],misc[[#This Row],[ROW]]) -> 11 | N10: =misc[[#This Row],[Core_Hitter_Count]]>0 -> FALSE | O10: =misc[[#This Row],[LLC_Hitter_Count]]>0 -> FALSE | P10: =misc[[#This Row],[CHA_Hitter_Count]]>0 -> FALSE | Q10: =_xlfn.TEXTJOIN("",,"*SOCKET0**CBB",misc[[#This Row],[CBB]],"**BASE**I_CCF_ENV",misc[[#This Row],[ENV]],splitchar,"CBREGS_ALL",misc[[#This Row],[CBO]],splitchar,"MC_STATUS*") -> *SOCKET0**CBB0**BASE**I_CCF_ENV3__CBREGS_ALL11__MC_STATUS* | R10: =COUNTIFS(cha_mc[TestName],misc[[#This Row],[CBO_MCA_String]],cha_mc[VisualId],MC_Check!$H$2) -> 0 | S10: =_xlfn.TEXTJOIN("",,"*SOCKET0**CBB",misc[[#This Row],[CBB]],"**COMPUTE",misc[[#This Row],[Compute]],"**MODULE",misc[[#This Row],[Module]],splitchar,"**CORE**IFU*CR*MC0*STATUS**") -> *SOCKET0**CBB0**COMPUTE0**MODULE7__**CORE**IFU*CR*MC0*STATUS** | T10: =COUNTIFS(core_mc[TestName],misc[[#This Row],[IFU_MCA_String]],core_mc[VisualId],MC_Check!$H$2) -> 0 | U10: =_xlfn.TEXTJOIN("",,"*SOCKET0**CBB",misc[[#This Row],[CBB]],"**COMPUTE",misc[[#This Row],[Compute]],"**MODULE",misc[[#This Row],[Module]],splitchar,"**CORE**ROB1*CR*MC*STATUS**") -> *SOCKET0**CBB0**COMPUTE0**MODULE7__**CORE**ROB1*CR*MC*STATUS** | V10: =COUNTIFS(core_mc[TestName],misc[[#This Row],[ROB_MCA_String]],core_mc[VisualId],MC_Check!$H$2) -> 0 | W10: =_xlfn.TEXTJOIN("",,"*SOCKET0**CBB",misc[[#This Row],[CBB]],"**COMPUTE",misc[[#This Row],[Compute]],"**MODULE",misc[[#This Row],[Module]],splitchar,"**CORE**DCU*CR*MC1*STATUS**") -> *SOCKET0**CBB0**COMPUTE0**MODULE7__**CORE**DCU*CR*MC1*STATUS** | X10: =COUNTIFS(core_mc[TestName],misc[[#This Row],[DCU_MCA_String]],core_mc[VisualId],MC_Check!$H$2) -> 0 | Y10: =_xlfn.TEXTJOIN("",,"*SOCKET0**CBB",misc[[#This Row],[CBB]],"**COMPUTE",misc[[#This Row],[Compute]],"**MODULE",misc[[#This Row],[Module]],splitchar,"**CORE**DTLB*CR*MC2*STATUS**") -> *SOCKET0**CBB0**COMPUTE0**MODULE7__**CORE**DTLB*CR*MC2*STATUS** | Z10: =COUNTIFS(core_mc[TestName],misc[[#This Row],[CORE_DTLB_String]],core_mc[VisualId],MC_Check!$H$2) -> 0 | AA10: =_xlfn.TEXTJOIN("",,"*SOCKET0**CBB",misc[[#This Row],[CBB]],"**COMPUTE",misc[[#This Row],[Compute]],"**MODULE",misc[[#This Row],[Module]],splitchar,"**ML2*CR*MC3*STATUS**") -> *SOCKET0**CBB0**COMPUTE0**MODULE7__**ML2*CR*MC3*STATUS** | AB10: =COUNTIFS(core_mc[TestName],misc[[#This Row],[Core_ML2_String]],core_mc[VisualId],MC_Check!$H$2) -> 0 | AC10: =_xlfn.TEXTJOIN("",,"*SOCKET0**CBB",misc[[#This Row],[CBB]],"**COMPUTE",misc[[#This Row],[Compute]],"**MODULE",misc[[#This Row],[Module]],splitchar,"SPARE") -> *SOCKET0**CBB0**COMPUTE0**MODULE7__SPARE | AD10: =COUNTIFS(core_mc[TestName],misc[[#This Row],[Core_L2_String - SPARE]],core_mc[VisualId],MC_Check!$H$2) -> 0 | AE10: =misc[[#This Row],[Core_DTLB_Count]]+misc[[#This Row],[Core_DCU_Count]]+misc[[#This Row],[Core_IFU_Count]]+misc[[#This Row],[Core_ROB_Count]]+misc[[#This Row],[Core_L2_Count - SPARE]]+misc[[#This Row],[Core_ML2_Count]] -> 0 | AF10: =_xlfn.TEXTJOIN(", ",,IF(misc[[#This Row],[Core_IFU_Count]]>0,"IFU",""),IF(misc[[#This Row],[Core_DCU_Count]]>0,"DCU",""),IF(misc[[#This Row],[Core_DTLB_Count]]>0,"DTLB",""),IF(misc[[#This Row],[Core_ROB_Count]]>0,"ROB",""),IF(misc[[#This Row],[Core_ML2_Count]]>0,"ML2",""),IF(misc[[#This Row],[Core_L2_Count - SPARE]]>0,"L2","")) | AG10: =_xlfn.TEXTJOIN("",,"*SOCKET0**CBB",misc[[#This Row],[CBB]],"**BASE**I_CCF**ENV",misc[[#This Row],[ENV]],splitchar,"CBREGS_ALL",misc[[#This Row],[CBO]],splitchar,"SPARE") -> *SOCKET0**CBB0**BASE**I_CCF**ENV3__CBREGS_ALL11__SPARE | AH10: =COUNTIFS(cha_mc[TestName],misc[[#This Row],[LLC_MCA_String - Not Used]],cha_mc[VisualId],MC_Check!$H$2) -> 0 | AK10: 1 | AL10: 7 | AM10: ="CH"&memss[[#This Row],[location]] -> CH7 | AN10: =memss[[#This Row],[MEMSS_Hitter_Count]]>0 -> FALSE | AO10: =_xlfn.TEXTJOIN("",,"*SOCKET0**SOC**MEMSS**B2CMI",memss[[#This Row],[location]],splitchar,"MCI*STATUS*SHADOW*") -> *SOCKET0**SOC**MEMSS**B2CMI7__MCI*STATUS*SHADOW* | AP10: =COUNTIFS(cha_mc[TestName],memss[[#This Row],[MEMMS_MCA_String]],cha_mc[VisualId],MC_Check!$H$2) -> 0
D11: 10 | F11: 0 | G11: 8 | H11: =IF(MC_Check!$AN$2="PHY",misc[[#This Row],[location]],misc[[#This Row],[Module_log]]) -> 8 | I11: =misc[[#This Row],[Module]] -> 8 | J11: =J3+1 -> 1 | K11: =K7+1 -> 2 | L11: 0 | M11: =_xlfn.TEXTJOIN("",,misc[[#This Row],[ROW]],misc[[#This Row],[ROW]]) -> 22 | N11: =misc[[#This Row],[Core_Hitter_Count]]>0 -> FALSE | O11: =misc[[#This Row],[LLC_Hitter_Count]]>0 -> FALSE | P11: =misc[[#This Row],[CHA_Hitter_Count]]>0 -> FALSE | Q11: =_xlfn.TEXTJOIN("",,"*SOCKET0**CBB",misc[[#This Row],[CBB]],"**BASE**I_CCF_ENV",misc[[#This Row],[ENV]],splitchar,"CBREGS_ALL",misc[[#This Row],[CBO]],splitchar,"MC_STATUS*") -> *SOCKET0**CBB0**BASE**I_CCF_ENV0__CBREGS_ALL22__MC_STATUS* | R11: =COUNTIFS(cha_mc[TestName],misc[[#This Row],[CBO_MCA_String]],cha_mc[VisualId],MC_Check!$H$2) -> 0 | S11: =_xlfn.TEXTJOIN("",,"*SOCKET0**CBB",misc[[#This Row],[CBB]],"**COMPUTE",misc[[#This Row],[Compute]],"**MODULE",misc[[#This Row],[Module]],splitchar,"**CORE**IFU*CR*MC0*STATUS**") -> *SOCKET0**CBB0**COMPUTE1**MODULE8__**CORE**IFU*CR*MC0*STATUS** | T11: =COUNTIFS(core_mc[TestName],misc[[#This Row],[IFU_MCA_String]],core_mc[VisualId],MC_Check!$H$2) -> 0 | U11: =_xlfn.TEXTJOIN("",,"*SOCKET0**CBB",misc[[#This Row],[CBB]],"**COMPUTE",misc[[#This Row],[Compute]],"**MODULE",misc[[#This Row],[Module]],splitchar,"**CORE**ROB1*CR*MC*STATUS**") -> *SOCKET0**CBB0**COMPUTE1**MODULE8__**CORE**ROB1*CR*MC*STATUS** | V11: =COUNTIFS(core_mc[TestName],misc[[#This Row],[ROB_MCA_String]],core_mc[VisualId],MC_Check!$H$2) -> 0 | W11: =_xlfn.TEXTJOIN("",,"*SOCKET0**CBB",misc[[#This Row],[CBB]],"**COMPUTE",misc[[#This Row],[Compute]],"**MODULE",misc[[#This Row],[Module]],splitchar,"**CORE**DCU*CR*MC1*STATUS**") -> *SOCKET0**CBB0**COMPUTE1**MODULE8__**CORE**DCU*CR*MC1*STATUS** | X11: =COUNTIFS(core_mc[TestName],misc[[#This Row],[DCU_MCA_String]],core_mc[VisualId],MC_Check!$H$2) -> 0 | Y11: =_xlfn.TEXTJOIN("",,"*SOCKET0**CBB",misc[[#This Row],[CBB]],"**COMPUTE",misc[[#This Row],[Compute]],"**MODULE",misc[[#This Row],[Module]],splitchar,"**CORE**DTLB*CR*MC2*STATUS**") -> *SOCKET0**CBB0**COMPUTE1**MODULE8__**CORE**DTLB*CR*MC2*STATUS** | Z11: =COUNTIFS(core_mc[TestName],misc[[#This Row],[CORE_DTLB_String]],core_mc[VisualId],MC_Check!$H$2) -> 0 | AA11: =_xlfn.TEXTJOIN("",,"*SOCKET0**CBB",misc[[#This Row],[CBB]],"**COMPUTE",misc[[#This Row],[Compute]],"**MODULE",misc[[#This Row],[Module]],splitchar,"**ML2*CR*MC3*STATUS**") -> *SOCKET0**CBB0**COMPUTE1**MODULE8__**ML2*CR*MC3*STATUS** | AB11: =COUNTIFS(core_mc[TestName],misc[[#This Row],[Core_ML2_String]],core_mc[VisualId],MC_Check!$H$2) -> 0 | AC11: =_xlfn.TEXTJOIN("",,"*SOCKET0**CBB",misc[[#This Row],[CBB]],"**COMPUTE",misc[[#This Row],[Compute]],"**MODULE",misc[[#This Row],[Module]],splitchar,"SPARE") -> *SOCKET0**CBB0**COMPUTE1**MODULE8__SPARE | AD11: =COUNTIFS(core_mc[TestName],misc[[#This Row],[Core_L2_String - SPARE]],core_mc[VisualId],MC_Check!$H$2) -> 0 | AE11: =misc[[#This Row],[Core_DTLB_Count]]+misc[[#This Row],[Core_DCU_Count]]+misc[[#This Row],[Core_IFU_Count]]+misc[[#This Row],[Core_ROB_Count]]+misc[[#This Row],[Core_L2_Count - SPARE]]+misc[[#This Row],[Core_ML2_Count]] -> 0 | AF11: =_xlfn.TEXTJOIN(", ",,IF(misc[[#This Row],[Core_IFU_Count]]>0,"IFU",""),IF(misc[[#This Row],[Core_DCU_Count]]>0,"DCU",""),IF(misc[[#This Row],[Core_DTLB_Count]]>0,"DTLB",""),IF(misc[[#This Row],[Core_ROB_Count]]>0,"ROB",""),IF(misc[[#This Row],[Core_ML2_Count]]>0,"ML2",""),IF(misc[[#This Row],[Core_L2_Count - SPARE]]>0,"L2","")) | AG11: =_xlfn.TEXTJOIN("",,"*SOCKET0**CBB",misc[[#This Row],[CBB]],"**BASE**I_CCF**ENV",misc[[#This Row],[ENV]],splitchar,"CBREGS_ALL",misc[[#This Row],[CBO]],splitchar,"SPARE") -> *SOCKET0**CBB0**BASE**I_CCF**ENV0__CBREGS_ALL22__SPARE | AH11: =COUNTIFS(cha_mc[TestName],misc[[#This Row],[LLC_MCA_String - Not Used]],cha_mc[VisualId],MC_Check!$H$2) -> 0 | AK11: 0 | AL11: 8 | AM11: ="CH"&memss[[#This Row],[location]] -> CH8 | AN11: =memss[[#This Row],[MEMSS_Hitter_Count]]>0 -> FALSE | AO11: =_xlfn.TEXTJOIN("",,"*SOCKET0**SOC**MEMSS**B2CMI",memss[[#This Row],[location]],splitchar,"MCI*STATUS*SHADOW*") -> *SOCKET0**SOC**MEMSS**B2CMI8__MCI*STATUS*SHADOW* | AP11: =COUNTIFS(cha_mc[TestName],memss[[#This Row],[MEMMS_MCA_String]],cha_mc[VisualId],MC_Check!$H$2) -> 0
F12: 0 | G12: 9 | H12: =IF(MC_Check!$AN$2="PHY",misc[[#This Row],[location]],misc[[#This Row],[Module_log]]) -> 9 | I12: =misc[[#This Row],[Module]] -> 9 | J12: =J4+1 -> 1 | K12: =K8+1 -> 2 | L12: 1 | M12: =_xlfn.TEXTJOIN("",,misc[[#This Row],[ROW]],misc[[#This Row],[ROW]]) -> 22 | N12: =misc[[#This Row],[Core_Hitter_Count]]>0 -> FALSE | O12: =misc[[#This Row],[LLC_Hitter_Count]]>0 -> FALSE | P12: =misc[[#This Row],[CHA_Hitter_Count]]>0 -> FALSE | Q12: =_xlfn.TEXTJOIN("",,"*SOCKET0**CBB",misc[[#This Row],[CBB]],"**BASE**I_CCF_ENV",misc[[#This Row],[ENV]],splitchar,"CBREGS_ALL",misc[[#This Row],[CBO]],splitchar,"MC_STATUS*") -> *SOCKET0**CBB0**BASE**I_CCF_ENV1__CBREGS_ALL22__MC_STATUS* | R12: =COUNTIFS(cha_mc[TestName],misc[[#This Row],[CBO_MCA_String]],cha_mc[VisualId],MC_Check!$H$2) -> 0 | S12: =_xlfn.TEXTJOIN("",,"*SOCKET0**CBB",misc[[#This Row],[CBB]],"**COMPUTE",misc[[#This Row],[Compute]],"**MODULE",misc[[#This Row],[Module]],splitchar,"**CORE**IFU*CR*MC0*STATUS**") -> *SOCKET0**CBB0**COMPUTE1**MODULE9__**CORE**IFU*CR*MC0*STATUS** | T12: =COUNTIFS(core_mc[TestName],misc[[#This Row],[IFU_MCA_String]],core_mc[VisualId],MC_Check!$H$2) -> 0 | U12: =_xlfn.TEXTJOIN("",,"*SOCKET0**CBB",misc[[#This Row],[CBB]],"**COMPUTE",misc[[#This Row],[Compute]],"**MODULE",misc[[#This Row],[Module]],splitchar,"**CORE**ROB1*CR*MC*STATUS**") -> *SOCKET0**CBB0**COMPUTE1**MODULE9__**CORE**ROB1*CR*MC*STATUS** | V12: =COUNTIFS(core_mc[TestName],misc[[#This Row],[ROB_MCA_String]],core_mc[VisualId],MC_Check!$H$2) -> 0 | W12: =_xlfn.TEXTJOIN("",,"*SOCKET0**CBB",misc[[#This Row],[CBB]],"**COMPUTE",misc[[#This Row],[Compute]],"**MODULE",misc[[#This Row],[Module]],splitchar,"**CORE**DCU*CR*MC1*STATUS**") -> *SOCKET0**CBB0**COMPUTE1**MODULE9__**CORE**DCU*CR*MC1*STATUS** | X12: =COUNTIFS(core_mc[TestName],misc[[#This Row],[DCU_MCA_String]],core_mc[VisualId],MC_Check!$H$2) -> 0 | Y12: =_xlfn.TEXTJOIN("",,"*SOCKET0**CBB",misc[[#This Row],[CBB]],"**COMPUTE",misc[[#This Row],[Compute]],"**MODULE",misc[[#This Row],[Module]],splitchar,"**CORE**DTLB*CR*MC2*STATUS**") -> *SOCKET0**CBB0**COMPUTE1**MODULE9__**CORE**DTLB*CR*MC2*STATUS** | Z12: =COUNTIFS(core_mc[TestName],misc[[#This Row],[CORE_DTLB_String]],core_mc[VisualId],MC_Check!$H$2) -> 0 | AA12: =_xlfn.TEXTJOIN("",,"*SOCKET0**CBB",misc[[#This Row],[CBB]],"**COMPUTE",misc[[#This Row],[Compute]],"**MODULE",misc[[#This Row],[Module]],splitchar,"**ML2*CR*MC3*STATUS**") -> *SOCKET0**CBB0**COMPUTE1**MODULE9__**ML2*CR*MC3*STATUS** | AB12: =COUNTIFS(core_mc[TestName],misc[[#This Row],[Core_ML2_String]],core_mc[VisualId],MC_Check!$H$2) -> 0 | AC12: =_xlfn.TEXTJOIN("",,"*SOCKET0**CBB",misc[[#This Row],[CBB]],"**COMPUTE",misc[[#This Row],[Compute]],"**MODULE",misc[[#This Row],[Module]],splitchar,"SPARE") -> *SOCKET0**CBB0**COMPUTE1**MODULE9__SPARE | AD12: =COUNTIFS(core_mc[TestName],misc[[#This Row],[Core_L2_String - SPARE]],core_mc[VisualId],MC_Check!$H$2) -> 0 | AE12: =misc[[#This Row],[Core_DTLB_Count]]+misc[[#This Row],[Core_DCU_Count]]+misc[[#This Row],[Core_IFU_Count]]+misc[[#This Row],[Core_ROB_Count]]+misc[[#This Row],[Core_L2_Count - SPARE]]+misc[[#This Row],[Core_ML2_Count]] -> 0 | AF12: =_xlfn.TEXTJOIN(", ",,IF(misc[[#This Row],[Core_IFU_Count]]>0,"IFU",""),IF(misc[[#This Row],[Core_DCU_Count]]>0,"DCU",""),IF(misc[[#This Row],[Core_DTLB_Count]]>0,"DTLB",""),IF(misc[[#This Row],[Core_ROB_Count]]>0,"ROB",""),IF(misc[[#This Row],[Core_ML2_Count]]>0,"ML2",""),IF(misc[[#This Row],[Core_L2_Count - SPARE]]>0,"L2","")) | AG12: =_xlfn.TEXTJOIN("",,"*SOCKET0**CBB",misc[[#This Row],[CBB]],"**BASE**I_CCF**ENV",misc[[#This Row],[ENV]],splitchar,"CBREGS_ALL",misc[[#This Row],[CBO]],splitchar,"SPARE") -> *SOCKET0**CBB0**BASE**I_CCF**ENV1__CBREGS_ALL22__SPARE | AH12: =COUNTIFS(cha_mc[TestName],misc[[#This Row],[LLC_MCA_String - Not Used]],cha_mc[VisualId],MC_Check!$H$2) -> 0 | AK12: 0 | AL12: 9 | AM12: ="CH"&memss[[#This Row],[location]] -> CH9 | AN12: =memss[[#This Row],[MEMSS_Hitter_Count]]>0 -> FALSE | AO12: =_xlfn.TEXTJOIN("",,"*SOCKET0**SOC**MEMSS**B2CMI",memss[[#This Row],[location]],splitchar,"MCI*STATUS*SHADOW*") -> *SOCKET0**SOC**MEMSS**B2CMI9__MCI*STATUS*SHADOW* | AP12: =COUNTIFS(cha_mc[TestName],memss[[#This Row],[MEMMS_MCA_String]],cha_mc[VisualId],MC_Check!$H$2) -> 0
